Workbook

Sheet Cover
A1: BMS2.0控制器通信矩阵 项目名称： 编 制： 校 对： 审 核： 批 准： 2024年08月

Sheet Revision
A1: 版本管理
A3: 版本 | B3: 日期 | C3: 作者 | D3: 审核 | E3: 修改说明
A4: V1.0.0 | B4: 2024/8/12 | C4: yiwang | E4: 二、三级板数据协议首版
A5: V1.0.1 | B5: 2024/8/13 | C5: xuc01 | E5: 1.combine array, such as CellV/CellT/Fault 2.delete reserved signals 3.delete RBMS_FDUSt1-8/RBMS_FCUSt/RBMS_FireSt 4.signal order change 5.add review comment 6.add formula to caculate Byte/StartBit
A6: V1.0.2 | B6: 2024/8/14 | C6: zl | E6: 1.change cell and temp send periodic from 5000(ms) to 1000(ms); 2.change cell balancing state send periodic from 10000(ms) to 1000(ms); 3.change cell self-discharge send periodic from 30000(ms) to 1000(ms);
A7: V1.0.3 | B7: 2024/9/4 | C7: xuc01 | E7: 1.Sheet“Legend”更新字节序与位序 2.Sheet“StationID”地址问题 3.Sheet“Comm Matrix”删除列“SPN可疑参数编号”，删除详细数据报文发送周期列 4. start bit/byte 列重新计算 5. Unit列重新核对 6. 数据包整合 7. 信号中英文描述补充完整 8. 信号名称与上位机显示匹配 9. 补充信号值描述 10.补充cmdGroup，cmdid等信息 11.修改RBMS_ConFail的信号值描述 luof03 12.添加RBMS_CellTMUXFaiIDNbr的信号值描述 luof03
A8: V1.0.4 | B8: 2024/9/10 | C8: xuc01 | E8: BBMS_SumInfo中信号startbit修正
A9: V1.0.5 | B9: 2024/10/14 | C9: xuc01 | E9: 删除数据帧：RBMS_VendorVersionInfo 与 BBMS_VendorVersionInfo，这两帧信息在底层输出，不在通讯协议中体现
A10: V1.0.6 | B10: 2024/11/06 | C10: xuc01 | E10: add: TMS与参数阈值数据帧
A11: V1.0.7 | B11: 2024/11/12 | C11: zhangyf03 | E11: Sheet "Comm Matrix"： 1. 删除：数据帧BBMS_RTCInfo（底层已实现）、风扇控制信号HMI_CtrlBoxFanManualCtrl（MIC预制舱暂无风扇功能），列 Mapping Signal； 2. 新增列（用于自动化mapping）：Tx Mapping Signal(RBMS/BBMS)、Rx Mapping Signal(RBMS)、Rx Mapping Signal(BBMS)； 3. 新增数据帧（从已有数据帧中拆分得到）：HMI_TMSCtrlWord、HMI_BankDOCtrl、HMI_RackDOCtrl； 4. 修改错误名称 Falut -> Fault； Sheet "Message ID"： 1. 新增列：请求payload、BBMS-A； 2. BBMS_CtrlWord的HMI：Rx -> /；HMI_TMSCtrlWord/HMI_BankDOCtrl的RBMS：Rx -> /； 3. 根据新的BMS2.0协议重定义了cmdGroup、cmdid、请求payload、响应payload信息；
A12: V1.0.8 | B12: 2024/12/24 | C12: zhangyf03 | E12: Sheet "Comm Matrix": 1. 帧 TMS_Info：重命名为TMS_SumInfo，并与CANFD通信矩阵中TMS_SumInfo信号保持一致；补充mapping name； 2. 帧 ParaThr_TMS：修改信号 CcTHMC_EntCoolMaxTemUpLimtC 名称；修改数据类型为 fixdt(0, 16, 2^-6, -40)；删除目前未实现信号的mapping name； 3. 信号 RBMS_SumInfo/RBMS_DFCLPointTimeDay 的增益：0->1； 4. 分辨率修改： RBMS_LstChEkWh、RBMS_LstDchEkWh：0.0078125->0.1； BBMS_LstChEkWh、BBMS_LstDchEkWh：0.25->1； RBMS_IsoR、RBMS_IsoRPos、RBMS_IsoRNeg、BBMS_IsoRPos、BBMS_IsoRNeg：2->1； 5. mapping信号以及数据类型信号修改： RBMS_A: ScEMCT_RBMS_A -> ScSGPC_BatIA_dbug (fixdt(0, 32, 0.001, -2000)); RBMS_ModTmpMax: ScEMCT_RBMS_ModTmpMax -> ScCLTH_MaxCellTDegC (fixdt(0, 16, 2^-6, -40)); RBMS_ModTmpMin: ScEMCT_RBMS_ModTmpMin -> ScCLTH_MinCellTDegC (fixdt(0, 16, 2^-6, -40)); RBMS_ModTmpAvg: ScEMCT_RBMS_ModTmpAvg -> ScCLTH_AvgCellTDegC (fixdt(0, 16, 2^-6, -40)); RBMS_MaxPoleTDegC: ScEMCT_MaxPoleTDegC -> ScCLTH_MaxPoleTDegC (fixdt(0, 16, 2^-6, -40)); RBMS_MinPoleTDegC: ScEMCT_MinPoleTDegC -> ScCLTH_MinPoleTDegC (fixdt(0, 16, 2^-6, -40)); RBMS_AvgPoleTDegC: ScEMCT_AvgPoleTDegC -> ScCLTH_AvgPoleTDegC (fixdt(0, 16, 2^-6, -40)); RBMS_ModTmp: SaEMCT_RBMS_ModTmp -> SaCLTS_CellTDegC (fixdt(0, 16, 2^-6, -40)); RBMS_PoleTDegC: SaCLTS_CellTDegC (fixdt(0, 16, 2^-6, -40)); RBMS_MaxCellVMdulTDegC: ScCLTH_MaxCellVMdulTDegC (fixdt(0, 16, 2^-6, -40)); RBMS_MinCellVMdulTDegC: ScCLTH_MinCellVMdulTDegC (fixdt(0, 16, 2^-6, -40)); 6. 删除帧 BBMS_Forward，在底层实现； Sheet "Message ID"：TMS_Info -> TMS_SumInfo; 删除帧 BBMS_Forward；
A13: V1.0.9 | B13: 2024/12/27 | C13: zhangyf03 | E13: Sheet "Comm Matrix"：帧 ParaThr_CellV、ParaThr_RackI、ParaThr_ModuleT、ParaThr_SOX、ParaThr_AUX更新mapping信号名，并更新信号名与mapping信号名一致；； Sheet "Message ID"：更新各数据帧的接收/发送方； Sheet "Station ID"：修改IP Address；
A14: V1.0.10 | B14: 2025/01/06 | C14: zhangyf03 | E14: Sheet "Comm Matrix" & Sheet "Message ID"： 1. 新增帧 RBMS_PCBBdTemp，增加PCB板温及有效性数据； 2. 删除帧 ParaThd_TMS 中以 B/C 结尾的信号； 3. 帧 RBMS_Fault 只发给 BBMS_A，不再发给 BBMS_M；
A15: V1.0.11 | B15: 2025/01/13 | C15: zhangyf03 | E15: Sheet "Comm Matrix" & Sheet "Message ID"： 1. 帧 ParaThr_TMS：修改数据类型为 fixdt(0, 16, 2^-6, -40) -> fixdt(0, 8, 1, -40)； 2. 帧 RBMS_PCBBdTemp：接收方增加 HMI（但暂时无需HMI显示），便于与 BBMS_A 组播； 3. 帧 RBMS_SumInfo 中信号 RBMS_AccuDischrgAh、RBMS_AccuChrgAh：修改数据类型为 fixdt(0, 64, 0.001, 0) -> fixdt(0, 32, 1, 0)； 4. 上位机 DIDO 控制需求： a）本地/远程控制、使能控制、连接控制、故障清除、使能绝缘检测 已在原 HMI_CtlWord 帧实现；RBMS继电器强控 已在原 HMI_RackDOCtrl 中等效实现，重命名为 HMI_RBMSRlyCtrl； b）新增帧 HMI_RBMSDOCtrl、HMI_BBMSDOCtrl； c）DIDO状态显示已在底层实现；
... A18: V1.0.14 | B18: 2025/02/19 | C18: zhangyf03 | E18: Sheet "Comm Matrix"： 信号 RBMS_TMSFltLevel 的 Tx Mapping Signal：ScTMCR_TMSFltLevel→ScTMCR_TMSFltLevelState
A19: V1.0.15 | B19: 45713 | C19: zhangyf03 | E19: Sheet "Comm Matrix"： 帧 ParaThr_AUX 中删除信号 CcSOCA_FullChJudgeCellVmV、CcSOPC_FullDischCutVmV
A20: V1.0.16 | B20: 45727 | C20: zhangyf03 | E20: Sheet "Message ID": 1. 帧 RBMS_SumInfo 的 BBMS_M 列 "/" -> "Rx"； 2. 新增帧 RBMS_AFEVolt； Sheet "Comm Matrix"： 1. 根据 CANFD 通讯矩阵添加信号； 2. 新增帧 RBMS_AFEVolt； 3. 帧 RBMS_SumInfo： a）补充、修改"Rx Mapping Signal"列信号； b）对于涉及不同精度的电流、温度等信号，发给A核的信号名添加后缀"2"，对应的 Mapping 信号名称后添加后缀 "_A"；
A21: V1.0.17 | B21: 45737 | C21: zhangyf03 | E21: Sheet "Message ID": 1. 新增帧 HMI_RackFaultCali、HMI_BankFaultCali 相关命令，用于NVM批量标定故障次数； Sheet "Comm Matrix"： 1. 新增帧 HMI_RackFaultCali、HMI_BankFaultCali，用于NVM批量标定故障次数； 2. 帧 BBMS_SumInfo：信号 BBMS_ConFail 修改描述与 CANFD 中一致，删除信号 BBMS_CycleTimes； 3. 帧 RBMS_SumInfo：信号 RBMS_CellTMUXFaiIDNbr 变更，删除信号 RBMS_PoleTAllVldFlg； 4. SOX调试数据帧信号修改； 5. 帧 ParaThr_AUX：修改满充满放电压阈值信号；
A22: V1.0.18 | B22: 45744 | C22: zhangyf03 | E22: Sheet "Message ID": 1. 删除帧 HMI_RackFaultCali、HMI_BankFaultCali 的读取命令； Sheet "Comm Matrix"： 1. 帧 RBMS_SumInfo：删除信号 RBMS_CellOvTiNbr、RBMS_CellOvTempTiNbr、RBMS_FltProtnTiNbr；新增信号 RBMS_FltOvTiNbr，用于发送故障数组越限次数； 2. 帧 BBMS_SumInfo：新增信号 BBMS_FltOvTiNbr，用于发送故障数组越限次数；
A23: V1.0.19 | B23: 45748 | C23: zhangyf03 | E23: Sheet "Message ID": 新增帧 RBMS_PoleTemp； Sheet "Comm Matrix"：新增帧 RBMS_PoleTemp（从帧 RBMS_CellTemp 中将极柱温度单独拆分成一帧 ）；
A24: V1.0.20 | B24: 45754 | C24: zhangyf03 | E24: Sheet "Comm Matrix"：帧 RBMS_PCBBdTemp：修改有效性信号Byte数、温度信号offset为-40；
A25: V1.0.21 | B25: 45763 | C25: zhangyf03 | E25: Sheet "Comm Matrix"： 1. 帧 RBMS_SumInfo：添加Reserved信号避免解析错位；删除RBMS_CellVIdxMdulNbr、RBMS_TMdulIdxNbr；增加Rack最大、最小电压/温度电芯所在模组以及模组内位置信号；RBMS_ConSt信号bit10改为急停状态； 2. 帧 BBMS_SumInfo：修改Bank最大、最小电压/温度电芯所在Rack、模组、模组内位置Tx mapping信号（将BKPC信号替换原EMCT信号）； 3. 帧 RBMS_AFEVolt：补充Tx mapping信号；
A26: V1.0.22 | B26: 45776 | C26: zhangyf03 | E26: Sheet "Comm Matrix"： 帧 ParaThr_AUX：CbSGPC_BalFordCmdFlg->CbCBCC_BalFordCmdFlg；
A27: V1.0.23 | B27: 45789 | C27: zhangyf03 | E27: Sheet "Message ID": 新增帧 RBMS_PackPosNegConnTemp，Pack正负极连接件温度及其有效性； Sheet "Comm Matrix"： 1. 新增帧 RBMS_PackPosNegConnTemp； 2. 帧 RBMS_SumInfo：新增AFE菊花链主、副链节点数信号 RBMS_DaisyChain1LastNode、RBMS_DaisyChain2LastNode，；
A28: V1.0.24 | B28: 45791 | C28: zhangyf03 | E28: Sheet "Message ID"：删除帧 HMI_BroadcastSig； Sheet "Comm Matrix"： 1. 删除帧 HMI_BroadcastSig； 2. 帧 ParaThr_AUX：删除4个信号CcCSPC_FullDischSumV、FULL_DISCHARGE_CELLV、CcCSPC_FullChSumV、FULL_CHARGE_CELLV； 3. 帧 ParaThr_CellV：信号CcCLVH_MaxCellVOvLvl2FltVmV->FULL_CHARGE_CELLV、CcCLVH_MinCellVUvLvl2FltVmV->FULL_DISCHARGE_CELLV； 4. 修改信号描述：帧 BBMS_SumInfo/信号BBMS_ConFail、帧 ParaThr_CellV、帧 ParaThr_RackV；
A29: V1.0.25 | B29: 45798 | C29: zhangyf03 | E29: Sheet "Comm Matrix"：帧 RBMS_SumInfo：修改高压盒温度相关信号名称、描述、Mapping信号；
A30: V1.0.26 | B30: 45807 | C30: zhangyf03 | E30: Sheet "Message ID"： 1. 增加帧 HMI_FltOvTiNbr，用于标定RBMS/BBMS_M故障越限次数； 2. 增加列 Rx_cmdType，以区分接收命令类型； 3. 增加列 BBMS_A Store，以识别A核需要保存的数据； 4. 合并电压、温度数据帧： a. 帧 RBMS_CellV、RBMS_AFEVolt 合并至同一帧 RBMS_Volt； b. 帧 RBMS_CellTemp、RBMS_PoleTemp、RBMS_PackPosNegConnTemp、RBMS_PCBBdTemp 合并至同一帧 RBMS_Temp； Sheet "Comm Matrix"： 1. 帧 RBMS_SumInfo/RBMS_FltOvTiNbr[200] 与 帧BBMS_SumInfo/BBMS_FltOvTiNbr[200] 移至帧 HMI_FltOvTiNbr； 2. 将5s/10s/30s发送的EMCT模型输出更新为前置模块的输出变量； 3. 帧 RBMS_SumInfo 中删除部分无逻辑信号，与CAN保持一致； 4. 涉及维度信号优化： a. 删除有效性信号 RBMS_ModTmpVldFlg、RBMS_PoleTVldFlg、RBMS_PackPosNegConnTVldFlg（温度为-40时即为无效）； b. 电压、温度合并后数据帧 RBMS_Volt、RBMS_Temp：固定结构体维度，可变维度定义在Map信号中； 新增 Sheet "Device ID"：记录设备类型以及节点号；
... A48: V1.0.44 | B48: 46027 | C48: zhangyf03 | E48: Sheet "Message ID"：HMI_CtlWord 命令列"BBMS_A"由 / -> Rx； Sheet "Comm Matrix"：HMI_CtlWord：信号 HMI_AlmRst 增加 BBMS_A 的 Rx 信号，支持A核故障清除功能；

Sheet Legend
A1: Legend 矩阵说明 | D1: Requset 通信要求
A2: Property 属性 | B2: Description 描述 | D2: Property 属性 | E2: Description 描述
A3: Message Name 报文名称 | B3: 例：RBMS_CellV表示RBMS发送的CellV报文 | D3: Byte/Bit Order 排列格式 | E3: Intel Little Endian/LSB
A4: Message Send Type 报文发送类型 | B4: Periodic:固定周期发送; Event:事件未触发时不发送，事件触发时按快速周期发送N次，快速发送周期默认50ms，发送次数默认3次; IfActive:1.未触发时固定周期发送，触发后以较快周期发送；2.未触发时不发送，触发后以固定周期发送; PE:事件未触发时按固定周期发送，事件触发时按快速周期发送N次，快速发送周期默认50ms，发送次数默认3次; On Request:接收到请求后触发; | D4: Data Type 数据类型 | E4: Unsigned integer
A5: Message Periodic Time (ms) 报文周期时间 | B5: 单位：毫秒（ms） | D5: 说明： Big Endian 大端：一个数值的最高有效字节存放在最低的内存地址上 LSB (Least Significant Bit): 最低有效位, 最右边的一位, 从右到左发送
A6: Signal Name 信号名称 | B6: 例：RBMS_Life表示RACK BMS发送的生命值信号
A7: Signal Description 信号描述
A8: Byte 字节 | B8: 1-1500Byte
A9: Bit 位 | B9: 8-1Bit
A10: Signal Send Type 信号发送类型 | B10: Periodic OnChange OnChangeWithRepetition IfActive
A11: Bit Length (Bit) 信号长度
A12: Resolution 精度 | B12: Used to Transform the Hex Value to Physical Value or in Reverse Direction. [Physical Value] = ( [Hex Value] * [Resolution] ) + [Offset] 用于十六进制和物理值间的相互转换。 [物理值] = ( [十六进制值] * [精度] ) + [偏移量]
A13: Offset 偏移量 | B13: Offset Value of the Signal. 信号的偏移量。
A14: Signal Min. Value (phys) 物理最小值 | B14: Physical Minimum Value of the Signal in Physical Value 信号的物理最小值
A15: Signal Max. Value(phys) 物理最大值 | B15: Physical maximum Value of the signal in physical Value 信号的物理最大值
A16: Signal Max. Value(Raw) 原始最大值 | B16: Raw maximum Value of the signal in physical Value 信号的原始最大值
A17: Initial Value(Hex) 初始值 | B17: Predefined Value If no valid signal is Available after Network Startup. 网络启动后没有可用的有效值而预定义的值
A18: Unit 单位 | B18: Unit of the signal physical Value 信号物理值的单位
A19: Signal Value Description 信号值描述 | B19: Hex-Physics Representation of the Signal Value 信号十六进制值所代表的物理值
A20: Message Periodic Time Fast(ms) 报文的快速发送周期(ms) | B20: The Fast Periodic Time of Message if the Send Type is not Periodic. 若报文非周期发送而定义的快速发送周期。
A21: Message Nr. Of Reption 报文的快速发送次数 | B21: The Repetition Number of Message if the Send Type is not Periodic 若报文非周期发送而定义的快速发送次数。
A22: Message Delay Time(ms) 报文延时时间(ms) | B22: The Min Time between the Same Message if the Send Type is not Periodic 若报文非周期发送，相同报文间的最小时间间隔。

Sheet Station ID
B2: BMS No. | C2: IP Address
B3: Bank BMS | C3: 192.168.1.136
B4: Rack BMS #1 | C4: 192.168.1.137
B5: Rack BMS #2 | C5: 192.168.1.138
B6: Rack BMS #3 | C6: 192.168.1.139
B7: Rack BMS #4 | C7: 192.168.1.140
B8: Rack BMS #5 | C8: 192.168.1.141
B9: Rack BMS #6 | C9: 192.168.1.142
B10: Rack BMS #7 | C10: 192.168.1.143
B11: Rack BMS #8 | C11: 192.168.1.144
B12: Rack BMS #9 | C12: 192.168.1.145
B13: Rack BMS #10 | C13: 192.168.1.146
... B16: HMI | C16: 192.168.1.149

Sheet Message ID
A1: Message Name | B1: Description | C1: Send Type | D1: Periodic Time (ms) | E1: cmdGroup | F1: cmdid | G1: 命令类型 0x01:不需要回应的报文； 0x02:需要回应的报文； 0x03:回应的报文 | H1: 请求payload | I1: 响应payload | J1: HMI | K1: BBMS_A | L1: BBMS_M | M1: RBMS | N1: Rx_cmdType (RBMS/BBMS_M/BBMS_A) | O1: BBMS_A Store | P1: HMI Store | Q1: cmdNUm
A2: RBMS_SumInfo | B2: Rack 概要数据(系统状态、高压状态、接插件温度、消防干接点、TMS、FCU、温湿度、水浸传感器；SOX、持续和瞬时功率、电压温度概要、故障和心跳信号；可充/放容量电量) | C2: Periodic | D2: 1000 | E2: 0x03 | F2: 1 | G2: 0x01 | H2: struct RBMS_SumInfo | I2: / | J2: Rx | K2: Rx | L2: Rx | M2: Tx | N2: Set | O2: 1 | P2: 1 | Q2: =COUNTIF(A:A,A2) -> 1
A3: RBMS_Volt | B3: 电芯电压及其有效性、各AFE总压 | C3: Periodic | D3: 1000 | E3: 0x03 | F3: 2 | G3: 0x01 | H3: struct RBMS_Volt | I3: / | J3: Rx | K3: Rx | L3: / | M3: Tx | N3: Set | O3: 1 | P3: 1 | Q3: =COUNTIF(A:A,A3) -> 1
A4: RBMS_Temp | B4: 电芯温度、极柱温度、Pack正负极连接件温度、PCB板温及其有效性 | C4: Periodic | D4: 1000 | E4: 0x03 | F4: 3 | G4: 0x01 | H4: struct RBMS_Temp | I4: / | J4: Rx | K4: Rx | L4: / | M4: Tx | N4: Set | O4: 1 | P4: 1 | Q4: =COUNTIF(A:A,A4) -> 1
A5: RBMS_CellBalSt | B5: Cell Balancing State 电芯均衡状态 | C5: Periodic | D5: 10000 | E5: 0x03 | F5: 4 | G5: 0x01 | H5: struct RBMS_CellBalSt | I5: / | J5: Rx | K5: Rx | L5: / | M5: Tx | N5: Set | O5: 1 | P5: 1 | Q5: =COUNTIF(A:A,A5) -> 1
A6: RBMS_CellSdr | B6: 单体电芯自放电率 | C6: Periodic | D6: 30000 | E6: 0x03 | F6: 5 | G6: 0x01 | H6: struct RBMS_CellSdr | I6: / | J6: Rx | K6: Rx | L6: / | M6: Tx | N6: Set | O6: 0 | P6: 1 | Q6: =COUNTIF(A:A,A6) -> 1
A7: RBMS_Fault | B7: RBMS故障列表 | C7: Periodic | D7: 1000 | E7: 0x04 | F7: 1 | G7: 0x01 | H7: struct FaultFlags | I7: / | J7: Rx | K7: Rx | L7: / | M7: Tx | N7: Set | O7: 1 | P7: 1 | Q7: =COUNTIF(A:A,A7) -> 1
A8: BBMS_SumInfo | B8: Bank 概要数据 | C8: Periodic | D8: 1000 | E8: 0x02 | F8: 1 | G8: 0x01 | H8: struct BBMS_SumInfo | I8: / | J8: Rx | K8: Rx | L8: Tx | M8: / | N8: Set | O8: 1 | P8: 1 | Q8: =COUNTIF(A:A,A8) -> 1
A9: BBMS_Fault | B9: BMS故障列表 | C9: Periodic | D9: 1000 | E9: 0x04 | F9: 1 | G9: 0x01 | H9: struct FaultFlags | I9: / | J9: Rx | K9: Rx | L9: Tx | M9: / | N9: Set | O9: 1 | P9: 1 | Q9: =COUNTIF(A:A,A9) -> 1
A10: BBMS_CtlWord | B10: BBMS Control BBMS控制指令 | C10: Periodic | D10: 1000 | E10: 0x03 | F10: 7 | G10: 0x02 | H10: struct BBMS_CtlWord | I10: struct state{ uint8_t state; //00：写入成功，01：写入失败 } | J10: / | K10: / | L10: Tx | M10: Rx | N10: Set | O10: 0 | P10: 0 | Q10: =COUNTIF(A:A,A10) -> 2
A11: BBMS_CtlWord | B11: 存储所有Rack的BBMS控制命令 | C11: Periodic | D11: 1000 | E11: 0x02 | F11: 12 | G11: 0x01 | H11: struct BBMS_CtlWordAllRack | I11: / | J11: Rx | K11: Rx | L11: Tx | M11: / | N11: Set | O11: 1 | P11: 1 | Q11: =COUNTIF(A:A,A11) -> 2
A12: HMI_CtlWord | B12: HMI Control HMI 控制指令 | C12: OnChange | D12: / | E12: 0x04 | F12: 4 | G12: 0x02 | H12: struct HMI_CtlWord | I12: struct state{ uint8_t state; //00：写入成功，01：写入失败 } | J12: Tx | K12: Rx | L12: Rx | M12: Rx | N12: Set | O12: 0 | P12: 0 | Q12: =COUNTIF(A:A,A12) -> 1
A13: HMI_TMSCtrlWord | B13: HMI TMS控制指令(BBMS) | C13: OnChange | D13: / | E13: 0x02 | F13: 3 | G13: 0x02 | H13: struct HMI_TMSCtrlWord | I13: struct state{ uint8_t state; //00：写入成功，01：写入失败 } | J13: Tx | K13: / | L13: Rx | M13: / | N13: Set | O13: 0 | P13: 0 | Q13: =COUNTIF(A:A,A13) -> 2
A14: HMI_TMSCtrlWord | B14: HMI TMS控制指令(RBMS) | C14: OnChange | D14: / | E14: 0x03 | F14: 37 | G14: 0x02 | H14: struct HMI_TMSCtrlWord | I14: struct state{ uint8_t state; //00：写入成功，01：写入失败 } | J14: Tx | K14: / | L14: / | M14: Rx | N14: Set | O14: 0 | P14: 0 | Q14: =COUNTIF(A:A,A14) -> 2
A15: HMI_BankDOCtrl | B15: HMI三级板DO控制指令（灯） | C15: OnChange | D15: / | E15: 0x02 | F15: 4 | G15: 0x02 | H15: struct HMI_BankDOCtrl | I15: struct state{ uint8_t state; //00：写入成功，01：写入失败 } | J15: Tx | K15: / | L15: Rx | M15: / | N15: Set | O15: 0 | P15: 0 | Q15: =COUNTIF(A:A,A15) -> 1
A16: HMI_RackCaliCtrl | B16: Rack标定与控制 | C16: OnChange | D16: / | E16: 0x03 | F16: 8 | G16: 0x02 | H16: struct HMI_RackCaliCtrl | I16: struct state{ uint8_t state; //00：写入成功，01：写入失败 } | J16: Tx | K16: / | L16: / | M16: Rx | N16: Set | O16: 0 | P16: 0 | Q16: =COUNTIF(A:A,A16) -> 1
A17: HMI_RBMSRlyCtrl | B17: HMI二级板继电器强控指令 | C17: OnChange | D17: / | E17: 0x03 | F17: 9 | G17: 0x02 | H17: struct HMI_RBMSRlyCtrl | I17: struct state{ uint8_t state; //00：写入成功，01：写入失败 } | J17: Tx | K17: / | L17: / | M17: Rx | N17: Set | O17: 0 | P17: 0 | Q17: =COUNTIF(A:A,A17) -> 1
A18: TMS_SumInfo | B18: 热管理信息(BBMS) | C18: Periodic | D18: 1000 | E18: 0x02 | F18: 2 | G18: 0x01 | H18: struct TMS_SumInfo | I18: / | J18: Rx | K18: Rx | L18: Tx | M18: / | N18: Set | O18: 1 | P18: 1 | Q18: =COUNTIF(A:A,A18) -> 2
A19: TMS_SumInfo | B19: 热管理信息(RBMS) | C19: Periodic | D19: 1000 | E19: 0x03 | F19: 38 | G19: 0x01 | H19: struct TMS_SumInfo | I19: / | J19: Rx | K19: Rx | L19: / | M19: Tx | N19: Set | O19: 1 | P19: 1 | Q19: =COUNTIF(A:A,A19) -> 2
A20: ParaThr_CellV | B20: 读取-电压阈值参数 | C20: OnChange | D20: / | E20: 0x03 | F20: 10 | G20: 0x02 | H20: / | I20: struct ParaThr_CellV | J20: Tx | K20: / | L20: / | M20: Rx | N20: Get | O20: 0 | P20: 0 | Q20: =COUNTIF(A:A,A20) -> 2
A21: ParaThr_CellV | B21: 写入-电压阈值参数 | C21: OnChange | D21: / | E21: 0x03 | F21: 11 | G21: 0x02 | H21: struct ParaThr_CellV | I21: struct state{ uint8_t state; //00：写入成功，01：写入失败 } | J21: Tx | K21: / | L21: / | M21: Rx | N21: Set | O21: 0 | P21: 0 | Q21: =COUNTIF(A:A,A21) -> 2
A22: ParaThr_RackV | B22: 读取-簇电压阈值参数 | C22: OnChange | D22: / | E22: 0x03 | F22: 12 | G22: 0x02 | H22: / | I22: struct ParaThr_RackV | J22: Tx | K22: / | L22: / | M22: Rx | N22: Get | O22: 0 | P22: 0 | Q22: =COUNTIF(A:A,A22) -> 2
A23: ParaThr_RackV | B23: 写入-簇电压阈值参数 | C23: OnChange | D23: / | E23: 0x03 | F23: 13 | G23: 0x02 | H23: struct ParaThr_RackV | I23: struct state{ uint8_t state; //00：写入成功，01：写入失败 } | J23: Tx | K23: / | L23: / | M23: Rx | N23: Set | O23: 0 | P23: 0 | Q23: =COUNTIF(A:A,A23) -> 2
A24: ParaThr_RackI | B24: 读取-簇电流阈值参数 | C24: OnChange | D24: / | E24: 0x03 | F24: 14 | G24: 0x02 | H24: / | I24: struct ParaThr_RackI | J24: Tx | K24: / | L24: / | M24: Rx | N24: Get | O24: 0 | P24: 0 | Q24: =COUNTIF(A:A,A24) -> 2
A25: ParaThr_RackI | B25: 写入-簇电流阈值参数 | C25: OnChange | D25: / | E25: 0x03 | F25: 15 | G25: 0x02 | H25: struct ParaThr_RackI | I25: struct state{ uint8_t state; //00：写入成功，01：写入失败 } | J25: Tx | K25: / | L25: / | M25: Rx | N25: Set | O25: 0 | P25: 0 | Q25: =COUNTIF(A:A,A25) -> 2
A26: ParaThr_ModuleT | B26: 读取-温度阈值参数 | C26: OnChange | D26: / | E26: 0x03 | F26: 16 | G26: 0x02 | H26: / | I26: struct ParaThr_ModuleT | J26: Tx | K26: / | L26: / | M26: Rx | N26: Get | O26: 0 | P26: 0 | Q26: =COUNTIF(A:A,A26) -> 2
A27: ParaThr_ModuleT | B27: 写入-温度阈值参数 | C27: OnChange | D27: / | E27: 0x03 | F27: 17 | G27: 0x02 | H27: struct ParaThr_ModuleT | I27: struct state{ uint8_t state; //00：写入成功，01：写入失败 } | J27: Tx | K27: / | L27: / | M27: Rx | N27: Set | O27: 0 | P27: 0 | Q27: =COUNTIF(A:A,A27) -> 2
A28: ParaThr_SOX | B28: 读取-SOX阈值参数 | C28: OnChange | D28: / | E28: 0x03 | F28: 18 | G28: 0x02 | H28: / | I28: struct ParaThr_SOX | J28: Tx | K28: / | L28: / | M28: Rx | N28: Get | O28: 0 | P28: 0 | Q28: =COUNTIF(A:A,A28) -> 2
A29: ParaThr_SOX | B29: 写入-SOX阈值参数 | C29: OnChange | D29: / | E29: 0x03 | F29: 19 | G29: 0x02 | H29: struct ParaThr_SOX | I29: struct state{ uint8_t state; //00：写入成功，01：写入失败 } | J29: Tx | K29: / | L29: / | M29: Rx | N29: Set | O29: 0 | P29: 0 | Q29: =COUNTIF(A:A,A29) -> 2
A30: ParaThr_AUX | B30: 读取-AUX阈值参数 | C30: OnChange | D30: / | E30: 0x03 | F30: 20 | G30: 0x02 | H30: / | I30: struct ParaThr_AUX | J30: Tx | K30: / | L30: / | M30: Rx | N30: Get | O30: 0 | P30: 0 | Q30: =COUNTIF(A:A,A30) -> 2
A31: ParaThr_AUX | B31: 写入-AUX阈值参数 | C31: OnChange | D31: / | E31: 0x03 | F31: 21 | G31: 0x02 | H31: struct ParaThr_AUX | I31: struct state{ uint8_t state; //00：写入成功，01：写入失败 } | J31: Tx | K31: / | L31: / | M31: Rx | N31: Set | O31: 0 | P31: 0 | Q31: =COUNTIF(A:A,A31) -> 2
... A37: HMI_BBMSDOCtrl | B37: HMI三级板DO控制命令 | C37: OnChange | D37: / | E37: 0x02 | F37: 10 | G37: 0x02 | H37: struct HMI_BBMSDOCtrl | I37: struct state{ uint8_t state; //00：写入成功，01：写入失败 } | J37: Tx | K37: / | L37: Rx | M37: / | N37: Set | O37: 0 | P37: 0 | Q37: =COUNTIF(A:A,A37) -> 1
A38: RBMS_SOXdebugData1 | B38: SOX算法调试的输入数据，包含电流、电压、温度等 | C38: Periodic | D38: 1000 | E38: 0x03 | F38: 25 | G38: 0x01 | H38: struct RBMS_SOXdebugData1 | I38: / | J38: Rx | K38: Rx | L38: / | M38: Tx | N38: Set | O38: 1 | P38: 1 | Q38: =COUNTIF(A:A,A38) -> 1
A39: RBMS_SOXdebugData2 | B39: SOX算法调试的输出数据，包含SOC、SOHC、容量等 | C39: Periodic | D39: 1000 | E39: 0x03 | F39: 26 | G39: 0x01 | H39: struct RBMS_SOXdebugData2 | I39: / | J39: Rx | K39: Rx | L39: / | M39: Tx | N39: Set | O39: 1 | P39: 1 | Q39: =COUNTIF(A:A,A39) -> 1
A40: HMI_RackFaultCali | B40: 写入-Rack故障累积次数标定 | C40: OnChange | D40: / | E40: 0x03 | F40: 28 | G40: 0x02 | H40: struct HMI_RackFaultCali | I40: struct state{ uint8_t state; //00：写入成功，01：写入失败 } | J40: Tx | K40: / | L40: / | M40: Rx | N40: Set | O40: 0 | P40: 0 | Q40: =COUNTIF(A:A,A40) -> 1
A41: HMI_BankFaultCali | B41: 写入-Bank故障累积次数标定 | C41: OnChange | D41: / | E41: 0x02 | F41: 11 | G41: 0x02 | H41: struct HMI_BankFaultCali | I41: struct state{ uint8_t state; //00：写入成功，01：写入失败 } | J41: Tx | K41: / | L41: Rx | M41: / | N41: Set | O41: 0 | P41: 0 | Q41: =COUNTIF(A:A,A41) -> 1
A42: HMI_FltOvTiNbr | B42: 读取-RBMS/BBMS故障越限次数 | C42: OnChange | D42: / | E42: 0x04 | F42: 5 | G42: 0x02 | H42: / | I42: struct HMI_FltOvTiNbr | J42: Tx | K42: / | L42: Rx | M42: Rx | N42: Get | O42: 0 | P42: 0 | Q42: =COUNTIF(A:A,A42) -> 1
A43: RBMS_Debug | B43: 模型调试信息 | C43: Periodic | D43: 1000 | E43: 0x03 | F43: 23 | G43: 0x01 | H43: struct RBMS_Debug | I43: / | J43: Rx | K43: Rx | L43: / | M43: Tx | N43: Set | O43: 1 | P43: 1 | Q43: =COUNTIF(A:A,A43) -> 1
A44: BBMS_A_SOCInfo | B44: 单芯计算的SOC以及各簇SOC结果 | C44: Periodic | D44: 1000 | E44: 0x01 | F44: 7 | G44: 0x01 | H44: struct BBMS_A_SOCInfo | I44: / | J44: Rx | K44: Tx | L44: / | M44: / | N44: / | O44: 1 | P44: 1 | Q44: =COUNTIF(A:A,A44) -> 1
A45: BBMS_A_SOHInfo | B45: 单芯计算的SOH以及各簇SOH结果 | C45: Periodic | D45: 1000 | E45: 0x01 | F45: 8 | G45: 0x01 | H45: struct BBMS_A_SOHInfo | I45: / | J45: Rx | K45: Tx | L45: / | M45: / | N45: / | O45: 1 | P45: 1 | Q45: =COUNTIF(A:A,A45) -> 1
...

Sheet Comm Matrix
A1: Message Name | B1: Description | C1: Signal Name | D1: Signal Description | E1: Byte | F1: Start Bit | G1: Bit Length (Bit) | H1: Resolution | I1: offset | J1: Signal Min. Value (Valid) | K1: Signal Max. Value (Valid) | L1: Initial Value | M1: Unit | N1: CSV Store Length(Byte) | O1: Signal Value Description | P1: Upper Computer Display | Q1: remark | R1: Tx Mapping Signal (RBMS/BBMS_M/BBMS_A) | S1: Rx Mapping Signal (BBMS_A) | T1: Rx Mapping Signal (BBMS_M) | U1: Rx Mapping Signal (RBMS)
A2: RBMS_SumInfo | B2: =VLOOKUP(A2,'Message ID'!A:M,2,FALSE) -> Rack 概要数据(系统状态、高压状态、接插件温度、消防干接点、TMS、FCU、温湿度、水浸传感器；SOX、持续和瞬时功率、电压温度概要、故障和心跳信号；可充/放容量电量) | E2: 310 | N2: =SUM(N3:N131) -> 805
C3: RBMS_St | D3: Battery String Status 电池串工作状态 | E3: =IF(INT((F3+G3-1)/8)+1=INT(F3/8)+1,INT(F3/8)+1,INT(F3/8)+1&"-"&INT((F3+G3-1)/8)+1) -> 1 | F3: 0 | G3: 8 | H3: 1 | I3: 0 | J3: 0 | K3: =(POWER(2,G3)-1)*H3+I3 -> 255 | L3: 0 | M3: / | N3: =LEN(K3) -> 3 | O3: Bit0[1]: Rack Enable Status;Rack使能状态 Signal; 0X0-Disabled; 0X1-Enabled; Bit1[1]: Rack Online Status;Rack在线状态 Signal; 0X0-Offline; 0X1-Online; Bit2[1]: Rack Control Mode Status;Rack控制模式 Signal; 0X0-BMS Control; 0X1-Debug; Bit3[1]: Overall Balancing Status;均衡状态 Signal; 0X0-Stop; 0X1-Ongoing; Bit4[0]: Fault Hardline Status;故障路线状态 Signal; 0X0- Activitied; 0X1- Disactivitied; Bit5[1]: Green Light Status;绿灯状态 Signal; 0X0-Off; 0X1-On; Bit6[1]: Yellow Light Status;黄灯状态 Signal; 0X0-Off; 0X1-On; Bit7[1]: Red Light Status;红灯状态 Signal; 0X0-Off; 0X1-On; | P3: Rack状态,Rack Status[1,4] | R3: ScEMCT_RBMS_St | S3: BSWSRackSt | T3: BSWSRackSt | U3: /
C4: RBMS_ChaSt | D4: Rack Charging Status Rack充放电状态 | E4: =IF(INT((F4+G4-1)/8)+1=INT(F4/8)+1,INT(F4/8)+1,INT(F4/8)+1&"-"&INT((F4+G4-1)/8)+1) -> 2 | F4: =F3+G3 -> 8 | G4: 8 | H4: 1 | I4: 0 | J4: 0 | K4: =(POWER(2,G4)-1)*H4+I4 -> 255 | L4: 0 | M4: / | N4: =LEN(K4) -> 3 | O4: Enum 0X1: Not Connected; 0X2: Full Discharge; 0X3: Discharge; 0X4: Charge; 0X5: Full Charge; 0X6: Standing; | P4: Rack状态,Rack Status[1,5] | Q4: 模型逻辑不需要更新，仅更新显示 | R4: ScEMCT_RBMS_ChaSt | S4: / | T4: BSWSRackChaSt | U4: /
C5: RBMS_SysOperSt | D5: Rack Operating Status Rack运行状态 | E5: =IF(INT((F5+G5-1)/8)+1=INT(F5/8)+1,INT(F5/8)+1,INT(F5/8)+1&"-"&INT((F5+G5-1)/8)+1) -> 3 | F5: =F4+G4 -> 16 | G5: 8 | H5: 1 | I5: 0 | J5: 0 | K5: =(POWER(2,G5)-1)*H5+I5 -> 255 | L5: 0 | M5: / | N5: =LEN(K5) -> 3 | O5: Enum 0X1: Not Connected; 0X2: Starting; 0X3: Connected; 0X4: Reserved; 0X5: SOC Protection; 0X63: Fault; | P5: Rack状态,Rack Status[1,6] | Q5: xuc 0826：RBMS_SysOperSt中SOC低直接用SOC低故障 @张龙b 其他模型逻辑不需要更新，仅更新显示 | R5: ScEMCT_RBMS_SysOperSt | S5: / | T5: BSWSRackSysOperSt | U5: /
C6: RBMS_ConSt | D6: Contactor Status 继电器/干接点状态 | E6: =IF(INT((F6+G6-1)/8)+1=INT(F6/8)+1,INT(F6/8)+1,INT(F6/8)+1&"-"&INT((F6+G6-1)/8)+1) -> 4-5 | F6: =F5+G5 -> 24 | G6: 16 | H6: 1 | I6: 0 | J6: 0 | K6: =(POWER(2,G6)-1)*H6+I6 -> 65535 | L6: 0 | M6: / | N6: =LEN(K6) -> 5 | O6: Bit0[1]: Main Negative Contactor Status;主负继电器状态; Signal; 0X0-Open; 0X1-Closed; Bit1[1]: Main Positive Contactor Status;主正继电器状态; Signal; 0X0-Open; 0X1-Closed; Bit2[1]: Precharge Contactor Status;预充继电器状态 Signal; 0X0-Open; 0X1-Closed; Bit3[0]: Reserved;保留 Signal; 0X0-Open; 0X1-Closed; Bit4[0]: Reserved;保留 Signal; 0X0-Open; 0X1-Closed; Bit5[0]: Reserved;保留 Signal; 0X0-Open; 0X1-Closed; Bit6[1]: QS Switch Status;隔离开关QS状态 Signal; 0X0-Closed; 0X1-Open; Bit7[1]: HV Interlock Status;高压互锁状态 Signal; 0X0-Closed; 0X1-Open; Bit8-Bit9[0]: HV Box Cooling Fan Status;高压箱冷却风扇状态 Signal; 0X0-Open; 0X1-Closed; Bit10[1]: EStop Status;急停状态 Signal; 0X0-Closed; 0X1-Open; Bit11[0]: Reserved;保留 Signal； 0X0-Open; 0X1-Closed; Bit12[0]: Reserved;保留 Signal; 0X0-Open; 0X1-Closed; Bit13[0]: Reserved;保留 Signal; 0X0-Open; 0X1-Closed; Bit14[1]: Isolation Finished Flag;绝缘完成标志 Signal; 0X0-No; 0X1-Yes; Bit15[1]: Door Open Status;电柜门状态 Signal; 0X0-Closed; 0X1-Open; | P6: Rack状态,Rack Status[1,8] | R6: ScEMCT_RBMS_ConSt | S6: / | T6: BSWSRackConSt | U6: /
C7: RBMS_ConFail | D7: HV Connect Fail Reason 高压连接失败原因 | E7: =IF(INT((F7+G7-1)/8)+1=INT(F7/8)+1,INT(F7/8)+1,INT(F7/8)+1&"-"&INT((F7+G7-1)/8)+1) -> 6-7 | F7: =F6+G6 -> 40 | G7: 16 | H7: 1 | I7: 0 | J7: 0 | K7: =(POWER(2,G7)-1)*H7+I7 -> 65535 | L7: 0 | M7: / | N7: =LEN(K7) -> 5 | O7: Enums Bit0: Insulation Unfinished Bit1: Debug Mode Bit2: Battery String Disabled Bit3: EMS Trip Bit4: Extreme Fault CRC Check Failed Bit5: Precharge Timeout Bit6: Hv Differential not Achieved During Precharge Phase Bit7: Precharge Fault Set Bit8: Relay Fault Set Bit9: RBMS has Level 1 Fault Bit10: Hv Control Mode Disconnected Bit11: Extreme Fault Set Bit12: Emergency Stop Signal Set | P7: Rack状态,Rack Status[1,7] | R7: ScEMCT_RBMS_ConFail | S7: / | T7: BSWSRackConFail | U7: /
C8: RBMS_V | D8: Battery String Voltage (V) 电池串电压 (V) | E8: =IF(INT((F8+G8-1)/8)+1=INT(F8/8)+1,INT(F8/8)+1,INT(F8/8)+1&"-"&INT((F8+G8-1)/8)+1) -> 8-9 | F8: =F7+G7 -> 56 | G8: 16 | H8: 0.5 | I8: 0 | J8: 0 | K8: =(POWER(2,G8)-1)*H8+I8 -> 32767.5 | L8: 0 | M8: V | N8: =LEN(K8) -> 7 | P8: Rack采样信息,Rack Sampling Information[3,11] | R8: ScEMCT_RBMS_V | S8: / | T8: BSWSRackV | U8: /
C9: RBMS_DCBusV | D9: DC Bus Voltage (V) 总线电压 (V) | E9: =IF(INT((F9+G9-1)/8)+1=INT(F9/8)+1,INT(F9/8)+1,INT(F9/8)+1&"-"&INT((F9+G9-1)/8)+1) -> 10-11 | F9: =F8+G8 -> 72 | G9: 16 | H9: 0.5 | I9: 0 | J9: 0 | K9: =(POWER(2,G9)-1)*H9+I9 -> 32767.5 | L9: 0 | M9: V | N9: =LEN(K9) -> 7 | P9: Rack采样信息,Rack Sampling Information[3,12] | R9: ScEMCT_RBMS_DCBusV | S9: / | T9: BSWSRackDCBusV | U9: /
C10: RBMS_A_HighAccu | D10: DC Bus Current (A) (High accu) 总线电流 (A) (高精度) | E10: =IF(INT((F10+G10-1)/8)+1=INT(F10/8)+1,INT(F10/8)+1,INT(F10/8)+1&"-"&INT((F10+G10-1)/8)+1) -> 12-15 | F10: =F9+G9 -> 88 | G10: 32 | H10: 0.001 | I10: -2000 | J10: -2000 | K10: =(POWER(2,G10)-1)*H10+I10 -> 4292967.3 | L10: 0 | M10: A | N10: =LEN(K10) -> 11 | Q10: songx0830：簇电流是否可以直接用single? xuc 0904: 已提高分辨率 | R10: ScSGPC_BatIA | S10: / | T10: / | U10: /
C11: RBMS_IsoR | D11: Insulation Resistance (kOhm) 绝缘阻值 (kOhm) | E11: =IF(INT((F11+G11-1)/8)+1=INT(F11/8)+1,INT(F11/8)+1,INT(F11/8)+1&"-"&INT((F11+G11-1)/8)+1) -> 16-17 | F11: =F10+G10 -> 120 | G11: 16 | H11: 1 | I11: 0 | J11: 0 | K11: =(POWER(2,G11)-1)*H11+I11 -> 65535 | L11: 0 | M11: kOhm | N11: =LEN(K11) -> 5 | P11: Rack采样信息,Rack Sampling Information[3,4] | R11: ScEMCT_RBMS_IsoR | S11: / | T11: BSWSRackIsoR | U11: /
C12: RBMS_HvBoxMaxTemp | D12: Max HV Box Temperature (℃) 最高高压箱温度 (℃) | E12: =IF(INT((F12+G12-1)/8)+1=INT(F12/8)+1,INT(F12/8)+1,INT(F12/8)+1&"-"&INT((F12+G12-1)/8)+1) -> 18-19 | F12: =F11+G11 -> 136 | G12: 16 | H12: 0.1 | I12: -40 | J12: -40 | K12: =(POWER(2,G12)-1)*H12+I12 -> 6513.5 | L12: 0 | M12: ℃ | N12: =LEN(K12) -> 6 | P12: Rack采样信息,Rack Sampling Information[3,30] | R12: ScCLTH_CtlBoxTMaxDegC | S12: / | T12: BSWSRackMaxHvBoxTDegC | U12: /
C13: RBMS_HvBoxMinTemp | D13: Min HV Box Temperature (℃) 最低高压箱温度 (℃) | E13: =IF(INT((F13+G13-1)/8)+1=INT(F13/8)+1,INT(F13/8)+1,INT(F13/8)+1&"-"&INT((F13+G13-1)/8)+1) -> 20-21 | F13: =F12+G12 -> 152 | G13: 16 | H13: 0.1 | I13: -40 | J13: -40 | K13: =(POWER(2,G13)-1)*H13+I13 -> 6513.5 | L13: 0 | M13: ℃ | N13: =LEN(K13) -> 6 | P13: Rack采样信息,Rack Sampling Information[3,31] | R13: ScCLTH_CtlBoxTMinDegC | S13: / | T13: BSWSRackMinHvBoxTDegC | U13: /
C14: Reserved3 | D14: Reserved3 预留占位3 | E14: =IF(INT((F14+G14-1)/8)+1=INT(F14/8)+1,INT(F14/8)+1,INT(F14/8)+1&"-"&INT((F14+G14-1)/8)+1) -> 22 | F14: =F13+G13 -> 168 | G14: 8 | H14: 1 | I14: 0 | J14: 0 | K14: =(POWER(2,G14)-1)*H14+I14 -> 255 | L14: 0 | M14: / | N14: 0 | R14: / | S14: / | T14: / | U14: /
C15: RBMS_LowPowSply | D15: Low Power Supply Voltage (mV) 低压供电电压 (mV) | E15: =IF(INT((F15+G15-1)/8)+1=INT(F15/8)+1,INT(F15/8)+1,INT(F15/8)+1&"-"&INT((F15+G15-1)/8)+1) -> 23-24 | F15: =F14+G14 -> 176 | G15: 16 | H15: 1 | I15: 0 | J15: 0 | K15: =(POWER(2,G15)-1)*H15+I15 -> 65535 | L15: 0 | M15: mV | N15: =LEN(K15) -> 5 | P15: Rack采样信息,Rack Sampling Information[3,9] | R15: ScEMCT_RBMS_LowPowSply | S15: / | T15: BSWSRackLowPowSply | U15: /
C16: RBMS_RlyCtrlSeqStState | D16: Relay Control Status 继电器控制状态 | E16: =IF(INT((F16+G16-1)/8)+1=INT(F16/8)+1,INT(F16/8)+1,INT(F16/8)+1&"-"&INT((F16+G16-1)/8)+1) -> 25 | F16: =F15+G15 -> 192 | G16: 4 | H16: 1 | I16: 0 | J16: 0 | K16: =(POWER(2,G16)-1)*H16+I16 -> 15 | L16: 0 | M16: / | N16: =LEN(K16) -> 2 | O16: Enum 0X0: Initial; 0X1: ClsMainNeg; 0X2: ClsPrech; 0X3: ClsMainPos; 0X4: Online; 0X5: WaitForCurrDwn; 0X6: OpenMainPos; 0X7: OpenMainNeg; 0X8: DlyForNxtPowup; 0X9: Service; 0XA: SftyOpenMainPos; 0XB: SftyOpenMainNeg; 0XC: SftyDlyForNxtPowup; | P16: Rack状态,Rack Status[1,9] | R16: SeCTSC_RlyCtrlSeqStState | S16: / | U16: /
C17: Reserved | D17: Reserved 预留占位 | E17: =IF(INT((F17+G17-1)/8)+1=INT(F17/8)+1,INT(F17/8)+1,INT(F17/8)+1&"-"&INT((F17+G17-1)/8)+1) -> 25 | F17: =F16+G16 -> 196 | G17: 4 | H17: 1 | I17: 0 | J17: 0 | K17: =(POWER(2,G17)-1)*H17+I17 -> 15 | L17: 0 | M17: / | N17: 0 | R17: / | S17: / | T17: / | U17: /
C18: Reserved1 | D18: Reserved1 预留占位1 | E18: =IF(INT((F18+G18-1)/8)+1=INT(F18/8)+1,INT(F18/8)+1,INT(F18/8)+1&"-"&INT((F18+G18-1)/8)+1) -> 26 | F18: =F17+G17 -> 200 | G18: 8 | H18: 1 | I18: 0 | J18: 0 | K18: =(POWER(2,G18)-1)*H18+I18 -> 255 | L18: 0 | M18: / | N18: 0 | R18: / | S18: / | T18: / | U18: /
C19: RBMS_HisSleepTiWrMin | D19: Rack History Sleep Time (min) 历史休眠时间 (min) | E19: =IF(INT((F19+G19-1)/8)+1=INT(F19/8)+1,INT(F19/8)+1,INT(F19/8)+1&"-"&INT((F19+G19-1)/8)+1) -> 27-30 | F19: =F18+G18 -> 208 | G19: 32 | H19: 1 | I19: 0 | J19: 0 | K19: =(POWER(2,G19)-1)*H19+I19 -> 4294967295 | L19: 0 | M19: Min | N19: =LEN(K19) -> 10 | P19: Rack历史信息,Rack History Information[4,1] | R19: ScEMCT_RBMS_HisSleepTiWrMin | S19: / | T19: BSWSRackHisSleepTiWrMin | U19: /
C20: RBMS_HisRunTiWrMin | D20: Rack History Run Time (min) 历史运行时间 (min) | E20: =IF(INT((F20+G20-1)/8)+1=INT(F20/8)+1,INT(F20/8)+1,INT(F20/8)+1&"-"&INT((F20+G20-1)/8)+1) -> 31-34 | F20: =F19+G19 -> 240 | G20: 32 | H20: 1 | I20: 0 | J20: 0 | K20: =(POWER(2,G20)-1)*H20+I20 -> 4294967295 | L20: 0 | M20: Min | N20: =LEN(K20) -> 10 | P20: Rack历史信息,Rack History Information[4,2] | R20: ScEMCT_RBMS_HisRunTiWrMin | S20: / | T20: BSWSRackHisRunTiWrMin | U20: /
C21: RBMS_LstSleepDurTiMin | D21: Last Power-down Sleep Time (min) 上次下电休眠时间 (min) | E21: =IF(INT((F21+G21-1)/8)+1=INT(F21/8)+1,INT(F21/8)+1,INT(F21/8)+1&"-"&INT((F21+G21-1)/8)+1) -> 35-38 | F21: =F20+G20 -> 272 | G21: 32 | H21: 1 | I21: 0 | J21: 0 | K21: =(POWER(2,G21)-1)*H21+I21 -> 4294967295 | L21: 0 | M21: Min | N21: =LEN(K21) -> 10 | R21: ScSGPC_LstSleepDurTiMin | S21: / | U21: /
C22: RBMS_IDLearnCodeSt | D22: Rack ID Learn Status Rack ID编码状态 | E22: =IF(INT((F22+G22-1)/8)+1=INT(F22/8)+1,INT(F22/8)+1,INT(F22/8)+1&"-"&INT((F22+G22-1)/8)+1) -> 39 | F22: =F21+G21 -> 304 | G22: 8 | H22: 1 | I22: 0 | J22: 0 | K22: =(POWER(2,G22)-1)*H22+I22 -> 255 | L22: 0 | M22: / | N22: =LEN(K22) -> 3 | O22: Enum 0X0: Initial; 0X1: Addressing; 0X2: Present RBMS Finished; 0X3: All RBMS Finished; 0X4: Failed; | P22: Rack状态,Rack Status[1,2] | R22: ScEMCT_RBMS_IDLearnCodeSt | S22: / | U22: /
C23: RBMS_IsoRPos | D23: Positive to GND Insulation Resistance (kOhm) 正对地绝缘阻值 (kOhm) | E23: =IF(INT((F23+G23-1)/8)+1=INT(F23/8)+1,INT(F23/8)+1,INT(F23/8)+1&"-"&INT((F23+G23-1)/8)+1) -> 40-41 | F23: =F22+G22 -> 312 | G23: 16 | H23: 1 | I23: 0 | J23: 0 | K23: =(POWER(2,G23)-1)*H23+I23 -> 65535 | L23: 0 | M23: kOhm | N23: =LEN(K23) -> 5 | R23: ScEMCT_RBMS_IsoRPos | S23: / | T23: BSWSRackIsoRPos | U23: /
C24: RBMS_IsoRNeg | D24: Negative to GND Insulation Resistance (kOhm) 负对地绝缘阻值 (kOhm) | E24: =IF(INT((F24+G24-1)/8)+1=INT(F24/8)+1,INT(F24/8)+1,INT(F24/8)+1&"-"&INT((F24+G24-1)/8)+1) -> 42-43 | F24: =F23+G23 -> 328 | G24: 16 | H24: 1 | I24: 0 | J24: 0 | K24: =(POWER(2,G24)-1)*H24+I24 -> 65535 | L24: 0 | M24: kOhm | N24: =LEN(K24) -> 5 | R24: ScEMCT_RBMS_IsoRNeg | S24: / | T24: BSWSRackIsoRNeg | U24: /
C25: RBMS_CmdInhibitFlg | D25: Insulation Disable Flag 绝缘禁止标志位 | E25: =IF(INT((F25+G25-1)/8)+1=INT(F25/8)+1,INT(F25/8)+1,INT(F25/8)+1&"-"&INT((F25+G25-1)/8)+1) -> 44 | F25: =F24+G24 -> 344 | G25: 8 | H25: 1 | I25: 0 | J25: 0 | K25: 1 | L25: 0 | M25: flg | N25: =LEN(K25) -> 1 | O25: Enum 0X0: Enable 0X1: Disable | R25: ScEMCT_RBMS_CmdInhibitFlg | S25: / | T25: BSWSRackCmdInhibitFlg | U25: /
C26: RBMS_IslnHvVldNbr | D26: Insulation High Voltage Validity Status 绝缘高压有效性状态 | E26: =IF(INT((F26+G26-1)/8)+1=INT(F26/8)+1,INT(F26/8)+1,INT(F26/8)+1&"-"&INT((F26+G26-1)/8)+1) -> 45 | F26: =F25+G25 -> 352 | G26: 8 | H26: 1 | I26: 0 | J26: 0 | K26: =(POWER(2,G26)-1)*H26+I26 -> 255 | L26: 0 | M26: / | N26: =LEN(K26) -> 3 | O26: Bit0[0]: Hv Battery Validity;高压有效性 Signal; 0X0-Invalid; 0X1-Valid; Bit1[0]: Postive Voltage Validity;正极电压有效性 Signal; 0X0-Invalid; 0X1-Valid; Bit2[0]: Negetive Voltage Validity;负极电压有效性 Signal; 0X0-Invalid; 0X1-Valid; | Q26: 统一按照bit 长度设置最大值 | R26: ScEMCT_RBMS_IslnHvVldNbr | S26: / | T26: BSWSRackIslnHvVldNbr | U26: /
C27: RBMS_IslnInhibitNbr | D27: Insulation Prohibition Reason 绝缘禁止原因 | E27: =IF(INT((F27+G27-1)/8)+1=INT(F27/8)+1,INT(F27/8)+1,INT(F27/8)+1&"-"&INT((F27+G27-1)/8)+1) -> 46 | F27: =F26+G26 -> 360 | G27: 8 | H27: 1 | I27: 0 | J27: 0 | K27: =(POWER(2,G27)-1)*H27+I27 -> 255 | L27: 0 | M27: / | N27: =LEN(K27) -> 3 | O27: Enum 0X0: Normal; 0X1: HMI Insulation Prohibition; 0X2: Insulation-related Voltage Invalid; 0X3: Hv Insulation Prohibition; 0X4: XCP Configuration Insulation Prohibition; | P27: Rack状态,Rack Status[1,10] | R27: ScEMCT_RBMS_IslnInhibitNbr | S27: / | T27: BSWSRackIslnInhibitNbr | U27: /
C28: RBMS_CellTMUXFaiIDNbr[RACK_TEMPERATURE_SENSOR_MUX_NUMBER] | D28: Temp Sampling MUX Fail Position 温度采样MUX失效位置 | E28: 47-110 | F28: =F27+G27 -> 368 | G28: 8 | H28: 1 | I28: 0 | J28: 0 | K28: =(POWER(2,G28)-1)*H28+I28 -> 255 | L28: 0 | M28: / | N28: =1*9+2*(64-9) -> 119 | P28: Rack采样信息,Rack Sampling Information[3,19] | Q28: 所有失效的MUX位置，MUX编号索引从1开始，末尾用0填充 | R28: SaEMCT_RBMS_CellTMUXFaiIDNbr | S28: / | T28: / | U28: /
C29: RBMS_SoC | D29: Rack SOC (%) Rack SOC（%） | E29: =IF(INT((F29+G29-1)/8)+1=INT(F29/8)+1,INT(F29/8)+1,INT(F29/8)+1&"-"&INT((F29+G29-1)/8)+1) -> 111 | F29: 880 | G29: 8 | H29: 0.5 | I29: 0 | J29: 0 | K29: =(POWER(2,G29)-1)*H29+I29 -> 127.5 | L29: 0 | M29: % | N29: =LEN(K29) -> 5 | P29: Rack SOX状态,Rack SOX Status[2,1] | Q29: 发送显示SOC | R29: ScEMCT_RBMS_SoC | S29: / | T29: BSWSRackSoC | U29: /
C30: RBMS_SoH | D30: Rack SOH (%) Rack SOH（%） | E30: =IF(INT((F30+G30-1)/8)+1=INT(F30/8)+1,INT(F30/8)+1,INT(F30/8)+1&"-"&INT((F30+G30-1)/8)+1) -> 112 | F30: =F29+G29 -> 888 | G30: 8 | H30: 1 | I30: 0 | J30: 0 | K30: =(POWER(2,G30)-1)*H30+I30 -> 255 | L30: 100 | M30: % | N30: =LEN(K30) -> 3 | P30: Rack SOX状态,Rack SOX Status[2,2] | Q30: 发送显示SOH | R30: ScEMCT_RBMS_SoH | S30: / | T30: BSWSRackSoH | U30: /
C31: RBMS_SoEC | D31: Rack SOE for Charge (kWh) Rack可充能量 (kWh) | E31: =IF(INT((F31+G31-1)/8)+1=INT(F31/8)+1,INT(F31/8)+1,INT(F31/8)+1&"-"&INT((F31+G31-1)/8)+1) -> 113-114 | F31: =F30+G30 -> 896 | G31: 16 | H31: 0.125 | I31: 0 | J31: 0 | K31: =(POWER(2,G31)-1)*H31+I31 -> 8191.875 | L31: 0 | M31: kWh | N31: =LEN(K31) -> 8 | P31: Rack SOX状态,Rack SOX Status[2,6] | R31: ScEMCT_RBMS_SoEC | S31: / | T31: BSWSRackSoEC | U31: /
C32: RBMS_SoED | D32: Rack SOE for Discharge (kWh) Rack可放能量 (kWh) | E32: =IF(INT((F32+G32-1)/8)+1=INT(F32/8)+1,INT(F32/8)+1,INT(F32/8)+1&"-"&INT((F32+G32-1)/8)+1) -> 115-116 | F32: =F31+G31 -> 912 | G32: 16 | H32: 0.125 | I32: 0 | J32: 0 | K32: =(POWER(2,G32)-1)*H32+I32 -> 8191.875 | L32: 0 | M32: kWh | N32: =LEN(K32) -> 8 | P32: Rack SOX状态,Rack SOX Status[2,7] | R32: ScEMCT_RBMS_SoED | S32: / | T32: BSWSRackSoED | U32: /
C33: RBMS_SoFPulseChrgCurr | D33: Pulse Charge Curr Limit (A) 脉冲充电电流限制 (A) | E33: =IF(INT((F33+G33-1)/8)+1=INT(F33/8)+1,INT(F33/8)+1,INT(F33/8)+1&"-"&INT((F33+G33-1)/8)+1) -> 117-118 | F33: =F32+G32 -> 928 | G33: 16 | H33: 0.125 | I33: 0 | J33: 0 | K33: =(POWER(2,G33)-1)*H33+I33 -> 8191.875 | L33: 0 | M33: A | N33: =LEN(K33) -> 8 | R33: ScEMCT_RBMS_SoFPulseChrgCurr | S33: / | T33: BSWSRackSoFPulseChrgCurr | U33: /
C34: RBMS_SoFPulseDisChrgCurr | D34: Pulse Discharge Curr Limit (A) 脉冲放电电流限制 (A) | E34: =IF(INT((F34+G34-1)/8)+1=INT(F34/8)+1,INT(F34/8)+1,INT(F34/8)+1&"-"&INT((F34+G34-1)/8)+1) -> 119-120 | F34: =F33+G33 -> 944 | G34: 16 | H34: 0.125 | I34: 0 | J34: 0 | K34: =(POWER(2,G34)-1)*H34+I34 -> 8191.875 | L34: 0 | M34: A | N34: =LEN(K34) -> 8 | R34: ScEMCT_RBMS_SoFPulseDisChrgCurr | S34: / | T34: BSWSRackSoFPulseDisChrgCurr | U34: /
C35: RBMS_SoFPulseChrgPwr | D35: Pulse Charge Power Limit (kW) 脉冲充电功率限制 (kW) | E35: =IF(INT((F35+G35-1)/8)+1=INT(F35/8)+1,INT(F35/8)+1,INT(F35/8)+1&"-"&INT((F35+G35-1)/8)+1) -> 121-122 | F35: =F34+G34 -> 960 | G35: 16 | H35: 0.125 | I35: 0 | J35: 0 | K35: =(POWER(2,G35)-1)*H35+I35 -> 8191.875 | L35: 0 | M35: kW | N35: =LEN(K35) -> 8 | R35: ScEMCT_RBMS_SoFPulseChrgPwr | S35: / | T35: BSWSRackSoFPulseChrgPwr | U35: /
C36: RBMS_SoFPulseDisChrgPwr | D36: Pulse Discharge Power Limit (kW) 脉冲放电功率限制 (kW) | E36: =IF(INT((F36+G36-1)/8)+1=INT(F36/8)+1,INT(F36/8)+1,INT(F36/8)+1&"-"&INT((F36+G36-1)/8)+1) -> 123-124 | F36: =F35+G35 -> 976 | G36: 16 | H36: 0.125 | I36: 0 | J36: 0 | K36: =(POWER(2,G36)-1)*H36+I36 -> 8191.875 | L36: 0 | M36: kW | N36: =LEN(K36) -> 8 | R36: ScEMCT_RBMS_SoFPulseDisChrgPwr | S36: / | T36: BSWSRackSoFPulseDisChrgPwr | U36: /
C37: RBMS_SoFContChrgCurr | D37: Const Charge Curr Limit (A) 持续充电电流限制 (A) | E37: =IF(INT((F37+G37-1)/8)+1=INT(F37/8)+1,INT(F37/8)+1,INT(F37/8)+1&"-"&INT((F37+G37-1)/8)+1) -> 125-126 | F37: =F36+G36 -> 992 | G37: 16 | H37: 0.125 | I37: 0 | J37: 0 | K37: =(POWER(2,G37)-1)*H37+I37 -> 8191.875 | L37: 0 | M37: A | N37: =LEN(K37) -> 8 | P37: Rack SOX状态,Rack SOX Status[2,8] | R37: ScEMCT_RBMS_SoFContChrgCurr | S37: / | T37: BSWSRackSoFContChrgCurr | U37: /
C38: RBMS_SoFContDisChrgCurr | D38: Const Discharge Curr Limit (A) 持续放电电流限制 (A) | E38: =IF(INT((F38+G38-1)/8)+1=INT(F38/8)+1,INT(F38/8)+1,INT(F38/8)+1&"-"&INT((F38+G38-1)/8)+1) -> 127-128 | F38: =F37+G37 -> 1008 | G38: 16 | H38: 0.125 | I38: 0 | J38: 0 | K38: =(POWER(2,G38)-1)*H38+I38 -> 8191.875 | L38: 0 | M38: A | N38: =LEN(K38) -> 8 | P38: Rack SOX状态,Rack SOX Status[2,9] | R38: ScEMCT_RBMS_SoFContDisChrgCurr | S38: / | T38: BSWSRackSoFContDisChrgCurr | U38: /
C39: RBMS_SoFContChrgPwr | D39: Const Charge Power Limit (kW) 持续充电功率限制 (kW) | E39: =IF(INT((F39+G39-1)/8)+1=INT(F39/8)+1,INT(F39/8)+1,INT(F39/8)+1&"-"&INT((F39+G39-1)/8)+1) -> 129-130 | F39: =F38+G38 -> 1024 | G39: 16 | H39: 0.125 | I39: 0 | J39: 0 | K39: =(POWER(2,G39)-1)*H39+I39 -> 8191.875 | L39: 0 | M39: kW | N39: =LEN(K39) -> 8 | R39: ScEMCT_RBMS_SoFContChrgPwr | S39: / | T39: BSWSRackSoFContChrgPwr | U39: /
C40: RBMS_SoFContDisChrgPwr | D40: Const Discharge Power Limit (kW) 持续放电功率限制 (kW) | E40: =IF(INT((F40+G40-1)/8)+1=INT(F40/8)+1,INT(F40/8)+1,INT(F40/8)+1&"-"&INT((F40+G40-1)/8)+1) -> 131-132 | F40: =F39+G39 -> 1040 | G40: 16 | H40: 0.125 | I40: 0 | J40: 0 | K40: =(POWER(2,G40)-1)*H40+I40 -> 8191.875 | L40: 0 | M40: kW | N40: =LEN(K40) -> 8 | R40: ScEMCT_RBMS_SoFContDisChrgPwr | S40: / | T40: BSWSRackSoFContDisChrgPwr | U40: /
...

Sheet Device ID
A1: 设备类型 | B1: 主节点号 | C1: 子节点号
A2: Broadcast | B2: 0x00 | C2: 0
A3: HMI & BBMS_A | B3: 0x01 | C3: 0
A4: HMI | B4: 0x01 | C4: 1
A5: BBMS_A | B5: 0x01 | C5: 2
A6: BBMS_M | B6: 0x03 | C6: 1
A7: RBMS | B7: 0x04 | C7: N（从1开始）
A8: Active_Balance | B8: 0x05 | C8: N

Sheet SSD Store Calculation
A1: ='Message ID'!A1 -> Message Name | B1: ='Message ID'!D1 -> Periodic Time (ms) | C1: ='Message ID'!O1 -> BBMS_A Store | D1: CSV Store Length(Byte) | E1: Rack Nbr | F1: Data RAM KB/Day | G1: Comma Nbr | H1: Comma RAM KB/Day | I1: LogTime RAM KB/Day
A2: ='Message ID'!A2 -> RBMS_SumInfo | B2: ='Message ID'!D2 -> 1000 | C2: ='Message ID'!O2 -> 1 | D2: =VLOOKUP(A2,'Comm Matrix'!A:N,14,FALSE) -> 805 | E2: =IF(OR(ISNUMBER(SEARCH("RBMS",A2)),ISNUMBER(SEARCH("Para",A2))),$F$52,1) -> 12 | F2: =IF(C2=1,D2*E2*60*60*24*C2/(B2/1000),0)/1024 -> 815062.5 | G2: {=MATCH(FALSE,INDEX(TRIM(INDIRECT("'Comm Matrix'!G"&(MATCH(A2,'Comm Matrix'!A:A,0)+1)&":G1000"))<>"",0),0)-1} -> 129 | H2: =IF(C2=1,G2*E2*60*60*24*C2/(B2/1000),0)/1024 -> 130612.5 | I2: =IF(C2=1,19*E2*60*60*24*C2/(B2/1000),0)/1024 -> 19237.5
A3: ='Message ID'!A3 -> RBMS_Volt | B3: ='Message ID'!D3 -> 1000 | C3: ='Message ID'!O3 -> 1 | D3: =VLOOKUP(A3,'Comm Matrix'!A:N,14,FALSE) -> 2400 | E3: =IF(OR(ISNUMBER(SEARCH("RBMS",A3)),ISNUMBER(SEARCH("Para",A3))),$F$52,1) -> 12 | F3: =IF(C3=1,D3*E3*60*60*24*C3/(B3/1000),0)/1024 -> 2430000 | G3: =416+416+32 -> 864 | H3: =IF(C3=1,G3*E3*60*60*24*C3/(B3/1000),0)/1024 -> 874800 | I3: =IF(C3=1,19*E3*60*60*24*C3/(B3/1000),0)/1024 -> 19237.5
A4: ='Message ID'!A4 -> RBMS_Temp | B4: ='Message ID'!D4 -> 1000 | C4: ='Message ID'!O4 -> 1 | D4: =VLOOKUP(A4,'Comm Matrix'!A:N,14,FALSE) -> 2672 | E4: =IF(OR(ISNUMBER(SEARCH("RBMS",A4)),ISNUMBER(SEARCH("Para",A4))),$F$52,1) -> 12 | F4: =IF(C4=1,D4*E4*60*60*24*C4/(B4/1000),0)/1024 -> 2705400 | G4: =416+64+16+32+32 -> 560 | H4: =IF(C4=1,G4*E4*60*60*24*C4/(B4/1000),0)/1024 -> 567000 | I4: =IF(C4=1,19*E4*60*60*24*C4/(B4/1000),0)/1024 -> 19237.5
A5: ='Message ID'!A5 -> RBMS_CellBalSt | B5: ='Message ID'!D5 -> 10000 | C5: ='Message ID'!O5 -> 1 | D5: =VLOOKUP(A5,'Comm Matrix'!A:N,14,FALSE) -> 416 | E5: =IF(OR(ISNUMBER(SEARCH("RBMS",A5)),ISNUMBER(SEARCH("Para",A5))),$F$52,1) -> 12 | F5: =IF(C5=1,D5*E5*60*60*24*C5/(B5/1000),0)/1024 -> 42120 | G5: =416 -> 416 | H5: =IF(C5=1,G5*E5*60*60*24*C5/(B5/1000),0)/1024 -> 42120 | I5: =IF(C5=1,19*E5*60*60*24*C5/(B5/1000),0)/1024 -> 1923.75
A6: ='Message ID'!A6 -> RBMS_CellSdr | B6: ='Message ID'!D6 -> 30000 | C6: ='Message ID'!O6 -> 0 | D6: =VLOOKUP(A6,'Comm Matrix'!A:N,14,FALSE) -> 2080 | E6: =IF(OR(ISNUMBER(SEARCH("RBMS",A6)),ISNUMBER(SEARCH("Para",A6))),$F$52,1) -> 12 | F6: =IF(C6=1,D6*E6*60*60*24*C6/(B6/1000),0)/1024 -> 0 | G6: =416 -> 416 | H6: =IF(C6=1,G6*E6*60*60*24*C6/(B6/1000),0)/1024 -> 0 | I6: =IF(C6=1,19*E6*60*60*24*C6/(B6/1000),0)/1024 -> 0
A7: ='Message ID'!A7 -> RBMS_Fault | B7: ='Message ID'!D7 -> 1000 | C7: ='Message ID'!O7 -> 1 | D7: =VLOOKUP(A7,'Comm Matrix'!A:N,14,FALSE) -> 200 | E7: =IF(OR(ISNUMBER(SEARCH("RBMS",A7)),ISNUMBER(SEARCH("Para",A7))),$F$52,1) -> 12 | F7: =IF(C7=1,D7*E7*60*60*24*C7/(B7/1000),0)/1024 -> 202500 | G7: =200 -> 200 | H7: =IF(C7=1,G7*E7*60*60*24*C7/(B7/1000),0)/1024 -> 202500 | I7: =IF(C7=1,19*E7*60*60*24*C7/(B7/1000),0)/1024 -> 19237.5
A8: ='Message ID'!A8 -> BBMS_SumInfo | B8: ='Message ID'!D8 -> 1000 | C8: ='Message ID'!O8 -> 1 | D8: =VLOOKUP(A8,'Comm Matrix'!A:N,14,FALSE) -> 366 | E8: =IF(OR(ISNUMBER(SEARCH("RBMS",A8)),ISNUMBER(SEARCH("Para",A8))),$F$52,1) -> 1 | F8: =IF(C8=1,D8*E8*60*60*24*C8/(B8/1000),0)/1024 -> 30881.25 | G8: {=MATCH(FALSE,INDEX(TRIM(INDIRECT("'Comm Matrix'!G"&(MATCH(A8,'Comm Matrix'!A:A,0)+1)&":G1000"))<>"",0),0)-1} -> 77 | H8: =IF(C8=1,G8*E8*60*60*24*C8/(B8/1000),0)/1024 -> 6496.875 | I8: =IF(C8=1,19*E8*60*60*24*C8/(B8/1000),0)/1024 -> 1603.125
A9: ='Message ID'!A9 -> BBMS_Fault | B9: ='Message ID'!D9 -> 1000 | C9: ='Message ID'!O9 -> 1 | D9: =VLOOKUP(A9,'Comm Matrix'!A:N,14,FALSE) -> 200 | E9: =IF(OR(ISNUMBER(SEARCH("RBMS",A9)),ISNUMBER(SEARCH("Para",A9))),$F$52,1) -> 1 | F9: =IF(C9=1,D9*E9*60*60*24*C9/(B9/1000),0)/1024 -> 16875 | G9: =200 -> 200 | H9: =IF(C9=1,G9*E9*60*60*24*C9/(B9/1000),0)/1024 -> 16875 | I9: =IF(C9=1,19*E9*60*60*24*C9/(B9/1000),0)/1024 -> 1603.125
A10: ='Message ID'!A10 -> BBMS_CtlWord | B10: ='Message ID'!D10 -> 1000 | C10: ='Message ID'!O10 -> 0 | D10: =VLOOKUP(A10,'Comm Matrix'!A:N,14,FALSE) -> 22 | E10: =IF(OR(ISNUMBER(SEARCH("RBMS",A10)),ISNUMBER(SEARCH("Para",A10))),$F$52,1) -> 1 | F10: =IF(C10=1,D10*E10*60*60*24*C10/(B10/1000),0)/1024 -> 0 | G10: {=MATCH(FALSE,INDEX(TRIM(INDIRECT("'Comm Matrix'!G"&(MATCH(A10,'Comm Matrix'!A:A,0)+1)&":G1000"))<>"",0),0)-1} -> 12 | H10: =IF(C10=1,G10*E10*60*60*24*C10/(B10/1000),0)/1024 -> 0 | I10: =IF(C10=1,19*E10*60*60*24*C10/(B10/1000),0)/1024 -> 0
A11: ='Message ID'!A11 -> BBMS_CtlWord | B11: ='Message ID'!D11 -> 1000 | C11: ='Message ID'!O11 -> 1 | D11: =VLOOKUP(A11,'Comm Matrix'!A:N,14,FALSE) -> 22 | E11: 12 | F11: =IF(C11=1,D11*E11*60*60*24*C11/(B11/1000),0)/1024 -> 22275 | G11: {=MATCH(FALSE,INDEX(TRIM(INDIRECT("'Comm Matrix'!G"&(MATCH(A11,'Comm Matrix'!A:A,0)+1)&":G1000"))<>"",0),0)-1} -> 12 | H11: =IF(C11=1,G11*E11*60*60*24*C11/(B11/1000),0)/1024 -> 12150 | I11: =IF(C11=1,19*E11*60*60*24*C11/(B11/1000),0)/1024 -> 19237.5
A12: ='Message ID'!A12 -> HMI_CtlWord | B12: ='Message ID'!D12 -> / | C12: ='Message ID'!O12 -> 0 | D12: =VLOOKUP(A12,'Comm Matrix'!A:N,14,FALSE) -> 20 | E12: =IF(OR(ISNUMBER(SEARCH("RBMS",A12)),ISNUMBER(SEARCH("Para",A12))),$F$52,1) -> 1 | F12: =IF(C12=1,D12*E12*60*60*24*C12/(B12/1000),0)/1024 -> 0 | G12: {=MATCH(FALSE,INDEX(TRIM(INDIRECT("'Comm Matrix'!G"&(MATCH(A12,'Comm Matrix'!A:A,0)+1)&":G1000"))<>"",0),0)-1} -> 13 | H12: =IF(C12=1,G12*E12*60*60*24*C12/(B12/1000),0)/1024 -> 0 | I12: =IF(C12=1,19*E12*60*60*24*C12/(B12/1000),0)/1024 -> 0
A13: ='Message ID'!A13 -> HMI_TMSCtrlWord | B13: ='Message ID'!D13 -> / | C13: ='Message ID'!O13 -> 0 | D13: =VLOOKUP(A13,'Comm Matrix'!A:N,14,FALSE) -> 7 | E13: =IF(OR(ISNUMBER(SEARCH("RBMS",A13)),ISNUMBER(SEARCH("Para",A13))),$F$52,1) -> 1 | F13: =IF(C13=1,D13*E13*60*60*24*C13/(B13/1000),0)/1024 -> 0 | G13: {=MATCH(FALSE,INDEX(TRIM(INDIRECT("'Comm Matrix'!G"&(MATCH(A13,'Comm Matrix'!A:A,0)+1)&":G1000"))<>"",0),0)-1} -> 4 | H13: =IF(C13=1,G13*E13*60*60*24*C13/(B13/1000),0)/1024 -> 0 | I13: =IF(C13=1,19*E13*60*60*24*C13/(B13/1000),0)/1024 -> 0
A14: ='Message ID'!A14 -> HMI_TMSCtrlWord | B14: ='Message ID'!D14 -> / | C14: ='Message ID'!O14 -> 0 | D14: =VLOOKUP(A14,'Comm Matrix'!A:N,14,FALSE) -> 7 | E14: 12 | F14: =IF(C14=1,D14*E14*60*60*24*C14/(B14/1000),0)/1024 -> 0 | G14: {=MATCH(FALSE,INDEX(TRIM(INDIRECT("'Comm Matrix'!G"&(MATCH(A14,'Comm Matrix'!A:A,0)+1)&":G1000"))<>"",0),0)-1} -> 4 | H14: =IF(C14=1,G14*E14*60*60*24*C14/(B14/1000),0)/1024 -> 0 | I14: =IF(C14=1,19*E14*60*60*24*C14/(B14/1000),0)/1024 -> 0
A15: ='Message ID'!A15 -> HMI_BankDOCtrl | B15: ='Message ID'!D15 -> / | C15: ='Message ID'!O15 -> 0 | D15: =VLOOKUP(A15,'Comm Matrix'!A:N,14,FALSE) -> 1 | E15: =IF(OR(ISNUMBER(SEARCH("RBMS",A15)),ISNUMBER(SEARCH("Para",A15))),$F$52,1) -> 1 | F15: =IF(C15=1,D15*E15*60*60*24*C15/(B15/1000),0)/1024 -> 0 | G15: {=MATCH(FALSE,INDEX(TRIM(INDIRECT("'Comm Matrix'!G"&(MATCH(A15,'Comm Matrix'!A:A,0)+1)&":G1000"))<>"",0),0)-1} -> 1 | H15: =IF(C15=1,G15*E15*60*60*24*C15/(B15/1000),0)/1024 -> 0 | I15: =IF(C15=1,19*E15*60*60*24*C15/(B15/1000),0)/1024 -> 0
A16: ='Message ID'!A16 -> HMI_RackCaliCtrl | B16: ='Message ID'!D16 -> / | C16: ='Message ID'!O16 -> 0 | D16: =VLOOKUP(A16,'Comm Matrix'!A:N,14,FALSE) -> 42 | E16: =IF(OR(ISNUMBER(SEARCH("RBMS",A16)),ISNUMBER(SEARCH("Para",A16))),$F$52,1) -> 1 | F16: =IF(C16=1,D16*E16*60*60*24*C16/(B16/1000),0)/1024 -> 0 | G16: {=MATCH(FALSE,INDEX(TRIM(INDIRECT("'Comm Matrix'!G"&(MATCH(A16,'Comm Matrix'!A:A,0)+1)&":G1000"))<>"",0),0)-1} -> 11 | H16: =IF(C16=1,G16*E16*60*60*24*C16/(B16/1000),0)/1024 -> 0 | I16: =IF(C16=1,19*E16*60*60*24*C16/(B16/1000),0)/1024 -> 0
A17: ='Message ID'!A17 -> HMI_RBMSRlyCtrl | B17: ='Message ID'!D17 -> / | C17: ='Message ID'!O17 -> 0 | D17: =VLOOKUP(A17,'Comm Matrix'!A:N,14,FALSE) -> 7 | E17: =IF(OR(ISNUMBER(SEARCH("RBMS",A17)),ISNUMBER(SEARCH("Para",A17))),$F$52,1) -> 12 | F17: =IF(C17=1,D17*E17*60*60*24*C17/(B17/1000),0)/1024 -> 0 | G17: {=MATCH(FALSE,INDEX(TRIM(INDIRECT("'Comm Matrix'!G"&(MATCH(A17,'Comm Matrix'!A:A,0)+1)&":G1000"))<>"",0),0)-1} -> 3 | H17: =IF(C17=1,G17*E17*60*60*24*C17/(B17/1000),0)/1024 -> 0 | I17: =IF(C17=1,19*E17*60*60*24*C17/(B17/1000),0)/1024 -> 0
A18: ='Message ID'!A18 -> TMS_SumInfo | B18: ='Message ID'!D18 -> 1000 | C18: ='Message ID'!O18 -> 1 | D18: =VLOOKUP(A18,'Comm Matrix'!A:N,14,FALSE) -> 34 | E18: =IF(OR(ISNUMBER(SEARCH("RBMS",A18)),ISNUMBER(SEARCH("Para",A18))),$F$52,1) -> 1 | F18: =IF(C18=1,D18*E18*60*60*24*C18/(B18/1000),0)/1024 -> 2868.75 | G18: {=MATCH(FALSE,INDEX(TRIM(INDIRECT("'Comm Matrix'!G"&(MATCH(A18,'Comm Matrix'!A:A,0)+1)&":G1000"))<>"",0),0)-1} -> 15 | H18: =IF(C18=1,G18*E18*60*60*24*C18/(B18/1000),0)/1024 -> 1265.625 | I18: =IF(C18=1,19*E18*60*60*24*C18/(B18/1000),0)/1024 -> 1603.125
A19: ='Message ID'!A19 -> TMS_SumInfo | B19: ='Message ID'!D19 -> 1000 | C19: ='Message ID'!O19 -> 1 | D19: =VLOOKUP(A19,'Comm Matrix'!A:N,14,FALSE) -> 34 | E19: 12 | F19: =IF(C19=1,D19*E19*60*60*24*C19/(B19/1000),0)/1024 -> 34425 | G19: {=MATCH(FALSE,INDEX(TRIM(INDIRECT("'Comm Matrix'!G"&(MATCH(A19,'Comm Matrix'!A:A,0)+1)&":G1000"))<>"",0),0)-1} -> 15 | H19: =IF(C19=1,G19*E19*60*60*24*C19/(B19/1000),0)/1024 -> 15187.5 | I19: =IF(C19=1,19*E19*60*60*24*C19/(B19/1000),0)/1024 -> 19237.5
A20: ='Message ID'!A20 -> ParaThr_CellV | B20: ='Message ID'!D20 -> / | C20: ='Message ID'!O20 -> 0 | D20: =VLOOKUP(A20,'Comm Matrix'!A:N,14,FALSE) -> 67 | E20: =IF(OR(ISNUMBER(SEARCH("RBMS",A20)),ISNUMBER(SEARCH("Para",A20))),$F$52,1) -> 12 | F20: =IF(C20=1,D20*E20*60*60*24*C20/(B20/1000),0)/1024 -> 0 | G20: {=MATCH(FALSE,INDEX(TRIM(INDIRECT("'Comm Matrix'!G"&(MATCH(A20,'Comm Matrix'!A:A,0)+1)&":G1000"))<>"",0),0)-1} -> 18 | H20: =IF(C20=1,G20*E20*60*60*24*C20/(B20/1000),0)/1024 -> 0 | I20: =IF(C20=1,19*E20*60*60*24*C20/(B20/1000),0)/1024 -> 0
A21: ='Message ID'!A21 -> ParaThr_CellV | B21: ='Message ID'!D21 -> / | C21: ='Message ID'!O21 -> 0 | D21: =VLOOKUP(A21,'Comm Matrix'!A:N,14,FALSE) -> 67 | E21: =IF(OR(ISNUMBER(SEARCH("RBMS",A21)),ISNUMBER(SEARCH("Para",A21))),$F$52,1) -> 12 | F21: =IF(C21=1,D21*E21*60*60*24*C21/(B21/1000),0)/1024 -> 0 | G21: {=MATCH(FALSE,INDEX(TRIM(INDIRECT("'Comm Matrix'!G"&(MATCH(A21,'Comm Matrix'!A:A,0)+1)&":G1000"))<>"",0),0)-1} -> 18 | H21: =IF(C21=1,G21*E21*60*60*24*C21/(B21/1000),0)/1024 -> 0 | I21: =IF(C21=1,19*E21*60*60*24*C21/(B21/1000),0)/1024 -> 0
A22: ='Message ID'!A22 -> ParaThr_RackV | B22: ='Message ID'!D22 -> / | C22: ='Message ID'!O22 -> 0 | D22: =VLOOKUP(A22,'Comm Matrix'!A:N,14,FALSE) -> 10 | E22: =IF(OR(ISNUMBER(SEARCH("RBMS",A22)),ISNUMBER(SEARCH("Para",A22))),$F$52,1) -> 12 | F22: =IF(C22=1,D22*E22*60*60*24*C22/(B22/1000),0)/1024 -> 0 | G22: {=MATCH(FALSE,INDEX(TRIM(INDIRECT("'Comm Matrix'!G"&(MATCH(A22,'Comm Matrix'!A:A,0)+1)&":G1000"))<>"",0),0)-1} -> 10 | H22: =IF(C22=1,G22*E22*60*60*24*C22/(B22/1000),0)/1024 -> 0 | I22: =IF(C22=1,19*E22*60*60*24*C22/(B22/1000),0)/1024 -> 0
A23: ='Message ID'!A23 -> ParaThr_RackV | B23: ='Message ID'!D23 -> / | C23: ='Message ID'!O23 -> 0 | D23: =VLOOKUP(A23,'Comm Matrix'!A:N,14,FALSE) -> 10 | E23: =IF(OR(ISNUMBER(SEARCH("RBMS",A23)),ISNUMBER(SEARCH("Para",A23))),$F$52,1) -> 12 | F23: =IF(C23=1,D23*E23*60*60*24*C23/(B23/1000),0)/1024 -> 0 | G23: {=MATCH(FALSE,INDEX(TRIM(INDIRECT("'Comm Matrix'!G"&(MATCH(A23,'Comm Matrix'!A:A,0)+1)&":G1000"))<>"",0),0)-1} -> 10 | H23: =IF(C23=1,G23*E23*60*60*24*C23/(B23/1000),0)/1024 -> 0 | I23: =IF(C23=1,19*E23*60*60*24*C23/(B23/1000),0)/1024 -> 0
A24: ='Message ID'!A24 -> ParaThr_RackI | B24: ='Message ID'!D24 -> / | C24: ='Message ID'!O24 -> 0 | D24: =VLOOKUP(A24,'Comm Matrix'!A:N,14,FALSE) -> 60 | E24: =IF(OR(ISNUMBER(SEARCH("RBMS",A24)),ISNUMBER(SEARCH("Para",A24))),$F$52,1) -> 12 | F24: =IF(C24=1,D24*E24*60*60*24*C24/(B24/1000),0)/1024 -> 0 | G24: {=MATCH(FALSE,INDEX(TRIM(INDIRECT("'Comm Matrix'!G"&(MATCH(A24,'Comm Matrix'!A:A,0)+1)&":G1000"))<>"",0),0)-1} -> 10 | H24: =IF(C24=1,G24*E24*60*60*24*C24/(B24/1000),0)/1024 -> 0 | I24: =IF(C24=1,19*E24*60*60*24*C24/(B24/1000),0)/1024 -> 0
A25: ='Message ID'!A25 -> ParaThr_RackI | B25: ='Message ID'!D25 -> / | C25: ='Message ID'!O25 -> 0 | D25: =VLOOKUP(A25,'Comm Matrix'!A:N,14,FALSE) -> 60 | E25: =IF(OR(ISNUMBER(SEARCH("RBMS",A25)),ISNUMBER(SEARCH("Para",A25))),$F$52,1) -> 12 | F25: =IF(C25=1,D25*E25*60*60*24*C25/(B25/1000),0)/1024 -> 0 | G25: {=MATCH(FALSE,INDEX(TRIM(INDIRECT("'Comm Matrix'!G"&(MATCH(A25,'Comm Matrix'!A:A,0)+1)&":G1000"))<>"",0),0)-1} -> 10 | H25: =IF(C25=1,G25*E25*60*60*24*C25/(B25/1000),0)/1024 -> 0 | I25: =IF(C25=1,19*E25*60*60*24*C25/(B25/1000),0)/1024 -> 0
A26: ='Message ID'!A26 -> ParaThr_ModuleT | B26: ='Message ID'!D26 -> / | C26: ='Message ID'!O26 -> 0 | D26: =VLOOKUP(A26,'Comm Matrix'!A:N,14,FALSE) -> 140 | E26: =IF(OR(ISNUMBER(SEARCH("RBMS",A26)),ISNUMBER(SEARCH("Para",A26))),$F$52,1) -> 12 | F26: =IF(C26=1,D26*E26*60*60*24*C26/(B26/1000),0)/1024 -> 0 | G26: {=MATCH(FALSE,INDEX(TRIM(INDIRECT("'Comm Matrix'!G"&(MATCH(A26,'Comm Matrix'!A:A,0)+1)&":G1000"))<>"",0),0)-1} -> 28 | H26: =IF(C26=1,G26*E26*60*60*24*C26/(B26/1000),0)/1024 -> 0 | I26: =IF(C26=1,19*E26*60*60*24*C26/(B26/1000),0)/1024 -> 0
A27: ='Message ID'!A27 -> ParaThr_ModuleT | B27: ='Message ID'!D27 -> / | C27: ='Message ID'!O27 -> 0 | D27: =VLOOKUP(A27,'Comm Matrix'!A:N,14,FALSE) -> 140 | E27: =IF(OR(ISNUMBER(SEARCH("RBMS",A27)),ISNUMBER(SEARCH("Para",A27))),$F$52,1) -> 12 | F27: =IF(C27=1,D27*E27*60*60*24*C27/(B27/1000),0)/1024 -> 0 | G27: {=MATCH(FALSE,INDEX(TRIM(INDIRECT("'Comm Matrix'!G"&(MATCH(A27,'Comm Matrix'!A:A,0)+1)&":G1000"))<>"",0),0)-1} -> 28 | H27: =IF(C27=1,G27*E27*60*60*24*C27/(B27/1000),0)/1024 -> 0 | I27: =IF(C27=1,19*E27*60*60*24*C27/(B27/1000),0)/1024 -> 0
A28: ='Message ID'!A28 -> ParaThr_SOX | B28: ='Message ID'!D28 -> / | C28: ='Message ID'!O28 -> 0 | D28: =VLOOKUP(A28,'Comm Matrix'!A:N,14,FALSE) -> 36 | E28: =IF(OR(ISNUMBER(SEARCH("RBMS",A28)),ISNUMBER(SEARCH("Para",A28))),$F$52,1) -> 12 | F28: =IF(C28=1,D28*E28*60*60*24*C28/(B28/1000),0)/1024 -> 0 | G28: {=MATCH(FALSE,INDEX(TRIM(INDIRECT("'Comm Matrix'!G"&(MATCH(A28,'Comm Matrix'!A:A,0)+1)&":G1000"))<>"",0),0)-1} -> 13 | H28: =IF(C28=1,G28*E28*60*60*24*C28/(B28/1000),0)/1024 -> 0 | I28: =IF(C28=1,19*E28*60*60*24*C28/(B28/1000),0)/1024 -> 0
A29: ='Message ID'!A29 -> ParaThr_SOX | B29: ='Message ID'!D29 -> / | C29: ='Message ID'!O29 -> 0 | D29: =VLOOKUP(A29,'Comm Matrix'!A:N,14,FALSE) -> 36 | E29: =IF(OR(ISNUMBER(SEARCH("RBMS",A29)),ISNUMBER(SEARCH("Para",A29))),$F$52,1) -> 12 | F29: =IF(C29=1,D29*E29*60*60*24*C29/(B29/1000),0)/1024 -> 0 | G29: {=MATCH(FALSE,INDEX(TRIM(INDIRECT("'Comm Matrix'!G"&(MATCH(A29,'Comm Matrix'!A:A,0)+1)&":G1000"))<>"",0),0)-1} -> 13 | H29: =IF(C29=1,G29*E29*60*60*24*C29/(B29/1000),0)/1024 -> 0 | I29: =IF(C29=1,19*E29*60*60*24*C29/(B29/1000),0)/1024 -> 0
A30: ='Message ID'!A30 -> ParaThr_AUX | B30: ='Message ID'!D30 -> / | C30: ='Message ID'!O30 -> 0 | D30: =VLOOKUP(A30,'Comm Matrix'!A:N,14,FALSE) -> 1 | E30: =IF(OR(ISNUMBER(SEARCH("RBMS",A30)),ISNUMBER(SEARCH("Para",A30))),$F$52,1) -> 12 | F30: =IF(C30=1,D30*E30*60*60*24*C30/(B30/1000),0)/1024 -> 0 | G30: {=MATCH(FALSE,INDEX(TRIM(INDIRECT("'Comm Matrix'!G"&(MATCH(A30,'Comm Matrix'!A:A,0)+1)&":G1000"))<>"",0),0)-1} -> 1 | H30: =IF(C30=1,G30*E30*60*60*24*C30/(B30/1000),0)/1024 -> 0 | I30: =IF(C30=1,19*E30*60*60*24*C30/(B30/1000),0)/1024 -> 0
A31: ='Message ID'!A31 -> ParaThr_AUX | B31: ='Message ID'!D31 -> / | C31: ='Message ID'!O31 -> 0 | D31: =VLOOKUP(A31,'Comm Matrix'!A:N,14,FALSE) -> 1 | E31: =IF(OR(ISNUMBER(SEARCH("RBMS",A31)),ISNUMBER(SEARCH("Para",A31))),$F$52,1) -> 12 | F31: =IF(C31=1,D31*E31*60*60*24*C31/(B31/1000),0)/1024 -> 0 | G31: {=MATCH(FALSE,INDEX(TRIM(INDIRECT("'Comm Matrix'!G"&(MATCH(A31,'Comm Matrix'!A:A,0)+1)&":G1000"))<>"",0),0)-1} -> 1 | H31: =IF(C31=1,G31*E31*60*60*24*C31/(B31/1000),0)/1024 -> 0 | I31: =IF(C31=1,19*E31*60*60*24*C31/(B31/1000),0)/1024 -> 0
A32: ='Message ID'!A32 -> ParaThr_TMS | B32: ='Message ID'!D32 -> / | C32: ='Message ID'!O32 -> 0 | D32: =VLOOKUP(A32,'Comm Matrix'!A:N,14,FALSE) -> 24 | E32: 1 | F32: =IF(C32=1,D32*E32*60*60*24*C32/(B32/1000),0)/1024 -> 0 | G32: {=MATCH(FALSE,INDEX(TRIM(INDIRECT("'Comm Matrix'!G"&(MATCH(A32,'Comm Matrix'!A:A,0)+1)&":G1000"))<>"",0),0)-1} -> 8 | H32: =IF(C32=1,G32*E32*60*60*24*C32/(B32/1000),0)/1024 -> 0 | I32: =IF(C32=1,19*E32*60*60*24*C32/(B32/1000),0)/1024 -> 0
A33: ='Message ID'!A33 -> ParaThr_TMS | B33: ='Message ID'!D33 -> / | C33: ='Message ID'!O33 -> 0 | D33: =VLOOKUP(A33,'Comm Matrix'!A:N,14,FALSE) -> 24 | E33: 1 | F33: =IF(C33=1,D33*E33*60*60*24*C33/(B33/1000),0)/1024 -> 0 | G33: {=MATCH(FALSE,INDEX(TRIM(INDIRECT("'Comm Matrix'!G"&(MATCH(A33,'Comm Matrix'!A:A,0)+1)&":G1000"))<>"",0),0)-1} -> 8 | H33: =IF(C33=1,G33*E33*60*60*24*C33/(B33/1000),0)/1024 -> 0 | I33: =IF(C33=1,19*E33*60*60*24*C33/(B33/1000),0)/1024 -> 0
A34: ='Message ID'!A34 -> ParaThr_TMS | B34: ='Message ID'!D34 -> / | C34: ='Message ID'!O34 -> 0 | D34: =VLOOKUP(A34,'Comm Matrix'!A:N,14,FALSE) -> 24 | E34: =IF(OR(ISNUMBER(SEARCH("RBMS",A34)),ISNUMBER(SEARCH("Para",A34))),$F$52,1) -> 12 | F34: =IF(C34=1,D34*E34*60*60*24*C34/(B34/1000),0)/1024 -> 0 | G34: {=MATCH(FALSE,INDEX(TRIM(INDIRECT("'Comm Matrix'!G"&(MATCH(A34,'Comm Matrix'!A:A,0)+1)&":G1000"))<>"",0),0)-1} -> 8 | H34: =IF(C34=1,G34*E34*60*60*24*C34/(B34/1000),0)/1024 -> 0 | I34: =IF(C34=1,19*E34*60*60*24*C34/(B34/1000),0)/1024 -> 0
A35: ='Message ID'!A35 -> ParaThr_TMS | B35: ='Message ID'!D35 -> / | C35: ='Message ID'!O35 -> 0 | D35: =VLOOKUP(A35,'Comm Matrix'!A:N,14,FALSE) -> 24 | E35: =IF(OR(ISNUMBER(SEARCH("RBMS",A35)),ISNUMBER(SEARCH("Para",A35))),$F$52,1) -> 12 | F35: =IF(C35=1,D35*E35*60*60*24*C35/(B35/1000),0)/1024 -> 0 | G35: {=MATCH(FALSE,INDEX(TRIM(INDIRECT("'Comm Matrix'!G"&(MATCH(A35,'Comm Matrix'!A:A,0)+1)&":G1000"))<>"",0),0)-1} -> 8 | H35: =IF(C35=1,G35*E35*60*60*24*C35/(B35/1000),0)/1024 -> 0 | I35: =IF(C35=1,19*E35*60*60*24*C35/(B35/1000),0)/1024 -> 0
A36: ='Message ID'!A36 -> HMI_RBMSDOCtrl | B36: ='Message ID'!D36 -> / | C36: ='Message ID'!O36 -> 0 | D36: =VLOOKUP(A36,'Comm Matrix'!A:N,14,FALSE) -> 12 | E36: =IF(OR(ISNUMBER(SEARCH("RBMS",A36)),ISNUMBER(SEARCH("Para",A36))),$F$52,1) -> 12 | F36: =IF(C36=1,D36*E36*60*60*24*C36/(B36/1000),0)/1024 -> 0 | G36: {=MATCH(FALSE,INDEX(TRIM(INDIRECT("'Comm Matrix'!G"&(MATCH(A36,'Comm Matrix'!A:A,0)+1)&":G1000"))<>"",0),0)-1} -> 12 | H36: =IF(C36=1,G36*E36*60*60*24*C36/(B36/1000),0)/1024 -> 0 | I36: =IF(C36=1,19*E36*60*60*24*C36/(B36/1000),0)/1024 -> 0
A37: ='Message ID'!A37 -> HMI_BBMSDOCtrl | B37: ='Message ID'!D37 -> / | C37: ='Message ID'!O37 -> 0 | D37: =VLOOKUP(A37,'Comm Matrix'!A:N,14,FALSE) -> 12 | E37: =IF(OR(ISNUMBER(SEARCH("RBMS",A37)),ISNUMBER(SEARCH("Para",A37))),$F$52,1) -> 1 | F37: =IF(C37=1,D37*E37*60*60*24*C37/(B37/1000),0)/1024 -> 0 | G37: {=MATCH(FALSE,INDEX(TRIM(INDIRECT("'Comm Matrix'!G"&(MATCH(A37,'Comm Matrix'!A:A,0)+1)&":G1000"))<>"",0),0)-1} -> 12 | H37: =IF(C37=1,G37*E37*60*60*24*C37/(B37/1000),0)/1024 -> 0 | I37: =IF(C37=1,19*E37*60*60*24*C37/(B37/1000),0)/1024 -> 0
A38: ='Message ID'!A38 -> RBMS_SOXdebugData1 | B38: ='Message ID'!D38 -> 1000 | C38: ='Message ID'!O38 -> 1 | D38: =VLOOKUP(A38,'Comm Matrix'!A:N,14,FALSE) -> 155 | E38: =IF(OR(ISNUMBER(SEARCH("RBMS",A38)),ISNUMBER(SEARCH("Para",A38))),$F$52,1) -> 12 | F38: =IF(C38=1,D38*E38*60*60*24*C38/(B38/1000),0)/1024 -> 156937.5 | G38: {=MATCH(FALSE,INDEX(TRIM(INDIRECT("'Comm Matrix'!G"&(MATCH(A38,'Comm Matrix'!A:A,0)+1)&":G1000"))<>"",0),0)-1} -> 32 | H38: =IF(C38=1,G38*E38*60*60*24*C38/(B38/1000),0)/1024 -> 32400 | I38: =IF(C38=1,19*E38*60*60*24*C38/(B38/1000),0)/1024 -> 19237.5
