Workbook

Sheet Cover
A1: BMS2.0控制器通信矩阵 项目名称： 编 制： 校 对： 审 核： 批 准： 2024年08月

Sheet Revision
A1: Version | B1: Date | C1: Revised by | D1: Reviewed by | E1: Description
A2: V1.0.0 | B2: 2024/8/12 | C2: yiwang | E2: 二、三级板数据协议首版
A3: V1.0.1 | B3: 2024/8/13 | C3: xuc01 | E3: 1.combine array, such as CellV/CellT/Fault 2.delete reserved signals 3.delete RBMS_FDUSt1-8/RBMS_FCUSt/RBMS_FireSt 4.signal order change 5.add review comment 6.add formula to caculate Byte/StartBit
A4: V1.0.2 | B4: 2024/8/14 | C4: zl | E4: 1.change cell and temp send periodic from 5000(ms) to 1000(ms); 2.change cell balancing state send periodic from 10000(ms) to 1000(ms); 3.change cell self-discharge send periodic from 30000(ms) to 1000(ms);
A5: V1.0.3 | B5: 2024/9/4 | C5: xuc01 | E5: 1.Sheet“Legend”更新字节序与位序 2.Sheet“StationID”地址问题 3.Sheet“Comm Matrix”删除列“SPN可疑参数编号”，删除详细数据报文发送周期列 4. start bit/byte 列重新计算 5. Unit列重新核对 6. 数据包整合 7. 信号中英文描述补充完整 8. 信号名称与上位机显示匹配 9. 补充信号值描述 10.补充cmdGroup，cmdid等信息 11.修改RBMS_ConFail的信号值描述 luof03 12.添加RBMS_CellTMUXFaiIDNbr的信号值描述 luof03
A6: V1.0.4 | B6: 2024/9/10 | C6: xuc01 | E6: BBMS_SumInfo中信号startbit修正
A7: V1.0.5 | B7: 2024/10/14 | C7: xuc01 | E7: 删除数据帧：RBMS_VendorVersionInfo 与 BBMS_VendorVersionInfo，这两帧信息在底层输出，不在通讯协议中体现
A8: V1.0.6 | B8: 2024/11/06 | C8: xuc01 | E8: add: TMS与参数阈值数据帧
A9: V1.0.7 | B9: 2024/11/12 | C9: zhangyf03 | E9: Sheet "Comm Matrix"： 1. 删除：数据帧BBMS_RTCInfo（底层已实现）、风扇控制信号HMI_CtrlBoxFanManualCtrl（MIC预制舱暂无风扇功能），列 Mapping Signal； 2. 新增列（用于自动化mapping）：Tx Mapping Signal(RBMS/BBMS)、Rx Mapping Signal(RBMS)、Rx Mapping Signal(BBMS)； 3. 新增数据帧（从已有数据帧中拆分得到）：HMI_TMSCtrlWord、HMI_BankDOCtrl、HMI_RackDOCtrl； 4. 修改错误名称 Falut -> Fault； Sheet "Message ID"： 1. 新增列：请求payload、BBMS-A； 2. BBMS_CtrlWord的HMI：Rx -> /；HMI_TMSCtrlWord/HMI_BankDOCtrl的RBMS：Rx -> /； 3. 根据新的BMS2.0协议重定义了cmdGroup、cmdid、请求payload、响应payload信息；
A10: V1.0.8 | B10: 2024/12/24 | C10: zhangyf03 | E10: Sheet "Comm Matrix": 1. 帧 TMS_Info：重命名为TMS_SumInfo，并与CANFD通信矩阵中TMS_SumInfo信号保持一致；补充mapping name； 2. 帧 ParaThr_TMS：修改信号 CcTHMC_EntCoolMaxTemUpLimtC 名称；修改数据类型为 fixdt(0, 16, 2^-6, -40)；删除目前未实现信号的mapping name； 3. 信号 RBMS_SumInfo/RBMS_DFCLPointTimeDay 的增益：0->1； 4. 分辨率修改： RBMS_LstChEkWh、RBMS_LstDchEkWh：0.0078125->0.1； BBMS_LstChEkWh、BBMS_LstDchEkWh：0.25->1； RBMS_IsoR、RBMS_IsoRPos、RBMS_IsoRNeg、BBMS_IsoRPos、BBMS_IsoRNeg：2->1； 5. mapping信号以及数据类型信号修改： RBMS_A: ScEMCT_RBMS_A -> ScSGPC_BatIA_dbug (fixdt(0, 32, 0.001, -2000)); RBMS_ModTmpMax: ScEMCT_RBMS_ModTmpMax -> ScCLTH_MaxCellTDegC (fixdt(0, 16, 2^-6, -40)); RBMS_ModTmpMin: ScEMCT_RBMS_ModTmpMin -> ScCLTH_MinCellTDegC (fixdt(0, 16, 2^-6, -40)); RBMS_ModTmpAvg: ScEMCT_RBMS_ModTmpAvg -> ScCLTH_AvgCellTDegC (fixdt(0, 16, 2^-6, -40)); RBMS_MaxPoleTDegC: ScEMCT_MaxPoleTDegC -> ScCLTH_MaxPoleTDegC (fixdt(0, 16, 2^-6, -40)); RBMS_MinPoleTDegC: ScEMCT_MinPoleTDegC -> ScCLTH_MinPoleTDegC (fixdt(0, 16, 2^-6, -40)); RBMS_AvgPoleTDegC: ScEMCT_AvgPoleTDegC -> ScCLTH_AvgPoleTDegC (fixdt(0, 16, 2^-6, -40)); RBMS_ModTmp: SaEMCT_RBMS_ModTmp -> SaCLTS_CellTDegC (fixdt(0, 16, 2^-6, -40)); RBMS_PoleTDegC: SaCLTS_CellTDegC (fixdt(0, 16, 2^-6, -40)); RBMS_MaxCellVMdulTDegC: ScCLTH_MaxCellVMdulTDegC (fixdt(0, 16, 2^-6, -40)); RBMS_MinCellVMdulTDegC: ScCLTH_MinCellVMdulTDegC (fixdt(0, 16, 2^-6, -40)); 6. 删除帧 BBMS_Forward，在底层实现； Sheet "Message ID"：TMS_Info -> TMS_SumInfo; 删除帧 BBMS_Forward；
A11: V1.0.9 | B11: 2024/12/27 | C11: zhangyf03 | E11: Sheet "Comm Matrix"：帧 ParaThr_CellV、ParaThr_RackI、ParaThr_ModuleT、ParaThr_SOX、ParaThr_AUX更新mapping信号名，并更新信号名与mapping信号名一致；； Sheet "Message ID"：更新各数据帧的接收/发送方； Sheet "Station ID"：修改IP Address；
A12: V1.0.10 | B12: 2025/01/06 | C12: zhangyf03 | E12: Sheet "Comm Matrix" & Sheet "Message ID"： 1. 新增帧 RBMS_PCBBdTemp，增加PCB板温及有效性数据； 2. 删除帧 ParaThd_TMS 中以 B/C 结尾的信号； 3. 帧 RBMS_Fault 只发给 BBMS_A，不再发给 BBMS_M；
A13: V1.0.11 | B13: 2025/01/13 | C13: zhangyf03 | E13: Sheet "Comm Matrix" & Sheet "Message ID"： 1. 帧 ParaThr_TMS：修改数据类型为 fixdt(0, 16, 2^-6, -40) -> fixdt(0, 8, 1, -40)； 2. 帧 RBMS_PCBBdTemp：接收方增加 HMI（但暂时无需HMI显示），便于与 BBMS_A 组播； 3. 帧 RBMS_SumInfo 中信号 RBMS_AccuDischrgAh、RBMS_AccuChrgAh：修改数据类型为 fixdt(0, 64, 0.001, 0) -> fixdt(0, 32, 1, 0)； 4. 上位机 DIDO 控制需求： a）本地/远程控制、使能控制、连接控制、故障清除、使能绝缘检测 已在原 HMI_CtlWord 帧实现；RBMS继电器强控 已在原 HMI_RackDOCtrl 中等效实现，重命名为 HMI_RBMSRlyCtrl； b）新增帧 HMI_RBMSDOCtrl、HMI_BBMSDOCtrl； c）DIDO状态显示已在底层实现；
... A16: V1.0.14 | B16: 2025/02/19 | C16: zhangyf03 | E16: Sheet "Comm Matrix"： 信号 RBMS_TMSFltLevel 的 Tx Mapping Signal：ScTMCR_TMSFltLevel→ScTMCR_TMSFltLevelState
A17: V1.0.15 | B17: 45713 | C17: zhangyf03 | E17: Sheet "Comm Matrix"： 帧 ParaThr_AUX 中删除信号 CcSOCA_FullChJudgeCellVmV、CcSOPC_FullDischCutVmV
A18: V1.0.16 | B18: 45727 | C18: zhangyf03 | E18: Sheet "Message ID": 1. 帧 RBMS_SumInfo 的 BBMS_M 列 "/" -> "Rx"； 2. 新增帧 RBMS_AFEVolt； Sheet "Comm Matrix"： 1. 根据 CANFD 通讯矩阵添加信号； 2. 新增帧 RBMS_AFEVolt； 3. 帧 RBMS_SumInfo： a）补充、修改"Rx Mapping Signal"列信号； b）对于涉及不同精度的电流、温度等信号，发给A核的信号名添加后缀"2"，对应的 Mapping 信号名称后添加后缀 "_A"；
A19: V1.0.17 | B19: 45737 | C19: zhangyf03 | E19: Sheet "Message ID": 1. 新增帧 HMI_RackFaultCali、HMI_BankFaultCali 相关命令，用于NVM批量标定故障次数； Sheet "Comm Matrix"： 1. 新增帧 HMI_RackFaultCali、HMI_BankFaultCali，用于NVM批量标定故障次数； 2. 帧 BBMS_SumInfo：信号 BBMS_ConFail 修改描述与 CANFD 中一致，删除信号 BBMS_CycleTimes； 3. 帧 RBMS_SumInfo：信号 RBMS_CellTMUXFaiIDNbr 变更，删除信号 RBMS_PoleTAllVldFlg； 4. SOX调试数据帧信号修改； 5. 帧 ParaThr_AUX：修改满充满放电压阈值信号；
A20: V1.0.18 | B20: 45744 | C20: zhangyf03 | E20: Sheet "Message ID": 1. 删除帧 HMI_RackFaultCali、HMI_BankFaultCali 的读取命令； Sheet "Comm Matrix"： 1. 帧 RBMS_SumInfo：删除信号 RBMS_CellOvTiNbr、RBMS_CellOvTempTiNbr、RBMS_FltProtnTiNbr；新增信号 RBMS_FltOvTiNbr，用于发送故障数组越限次数； 2. 帧 BBMS_SumInfo：新增信号 BBMS_FltOvTiNbr，用于发送故障数组越限次数；
A21: V1.0.19 | B21: 45748 | C21: zhangyf03 | E21: Sheet "Message ID": 新增帧 RBMS_PoleTemp； Sheet "Comm Matrix"：新增帧 RBMS_PoleTemp（从帧 RBMS_CellTemp 中将极柱温度单独拆分成一帧 ）；
A22: V1.0.20 | B22: 45754 | C22: zhangyf03 | E22: Sheet "Comm Matrix"：帧 RBMS_PCBBdTemp：修改有效性信号Byte数、温度信号offset为-40；
A23: V1.0.21 | B23: 45763 | C23: zhangyf03 | E23: Sheet "Comm Matrix"： 1. 帧 RBMS_SumInfo：添加Reserved信号避免解析错位；删除RBMS_CellVIdxMdulNbr、RBMS_TMdulIdxNbr；增加Rack最大、最小电压/温度电芯所在模组以及模组内位置信号；RBMS_ConSt信号bit10改为急停状态； 2. 帧 BBMS_SumInfo：修改Bank最大、最小电压/温度电芯所在Rack、模组、模组内位置Tx mapping信号（将BKPC信号替换原EMCT信号）； 3. 帧 RBMS_AFEVolt：补充Tx mapping信号；
A24: V1.0.22 | B24: 45776 | C24: zhangyf03 | E24: Sheet "Comm Matrix"： 帧 ParaThr_AUX：CbSGPC_BalFordCmdFlg->CbCBCC_BalFordCmdFlg；
A25: V1.0.23 | B25: 45789 | C25: zhangyf03 | E25: Sheet "Message ID": 新增帧 RBMS_PackPosNegConnTemp，Pack正负极连接件温度及其有效性； Sheet "Comm Matrix"： 1. 新增帧 RBMS_PackPosNegConnTemp； 2. 帧 RBMS_SumInfo：新增AFE菊花链主、副链节点数信号 RBMS_DaisyChain1LastNode、RBMS_DaisyChain2LastNode，；
A26: V1.0.24 | B26: 45791 | C26: zhangyf03 | E26: Sheet "Message ID"：删除帧 HMI_BroadcastSig； Sheet "Comm Matrix"： 1. 删除帧 HMI_BroadcastSig； 2. 帧 ParaThr_AUX：删除4个信号CcCSPC_FullDischSumV、FULL_DISCHARGE_CELLV、CcCSPC_FullChSumV、FULL_CHARGE_CELLV； 3. 帧 ParaThr_CellV：信号CcCLVH_MaxCellVOvLvl2FltVmV->FULL_CHARGE_CELLV、CcCLVH_MinCellVUvLvl2FltVmV->FULL_DISCHARGE_CELLV； 4. 修改信号描述：帧 BBMS_SumInfo/信号BBMS_ConFail、帧 ParaThr_CellV、帧 ParaThr_RackV；
A27: V1.0.25 | B27: 45798 | C27: zhangyf03 | E27: Sheet "Comm Matrix"：帧 RBMS_SumInfo：修改高压盒温度相关信号名称、描述、Mapping信号；
A28: V1.0.26 | B28: 45807 | C28: zhangyf03 | E28: Sheet "Message ID"： 1. 增加帧 HMI_FltOvTiNbr，用于标定RBMS/BBMS_M故障越限次数； 2. 增加列 Rx_cmdType，以区分接收命令类型； 3. 增加列 BBMS_A Store，以识别A核需要保存的数据； 4. 合并电压、温度数据帧： a. 帧 RBMS_CellV、RBMS_AFEVolt 合并至同一帧 RBMS_Volt； b. 帧 RBMS_CellTemp、RBMS_PoleTemp、RBMS_PackPosNegConnTemp、RBMS_PCBBdTemp 合并至同一帧 RBMS_Temp； Sheet "Comm Matrix"： 1. 帧 RBMS_SumInfo/RBMS_FltOvTiNbr[200] 与 帧BBMS_SumInfo/BBMS_FltOvTiNbr[200] 移至帧 HMI_FltOvTiNbr； 2. 将5s/10s/30s发送的EMCT模型输出更新为前置模块的输出变量； 3. 帧 RBMS_SumInfo 中删除部分无逻辑信号，与CAN保持一致； 4. 涉及维度信号优化： a. 删除有效性信号 RBMS_ModTmpVldFlg、RBMS_PoleTVldFlg、RBMS_PackPosNegConnTVldFlg（温度为-40时即为无效）； b. 电压、温度合并后数据帧 RBMS_Volt、RBMS_Temp：固定结构体维度，可变维度定义在Map信号中； 新增 Sheet "Device ID"：记录设备类型以及节点号；
... A59: V1.0.57 | B59: 46267 | C59: zhangyf03 | E59: Sheet "Comm Matrix"： 1、RBMS_SumInfo 帧：修改 RBMS_St 信号值描述；新增当日累积充放电容量、能量（Byte 59-74） 2、BBMS_SumInfo 帧：新增当日累积充放电容量、能量（Byte 131-146）

Sheet Legend
A1: Legend 矩阵说明 | D1: Requset 通信要求
A2: Property 属性 | B2: Description 描述 | D2: Property 属性 | E2: Description 描述
A3: Message Name 报文名称 | B3: 例：RBMS_CellV表示RBMS发送的CellV报文 | D3: Byte/Bit Order 排列格式 | E3: Intel Little Endian/LSB
A4: Message Send Type 报文发送类型 | B4: Periodic:固定周期发送; Event:事件未触发时不发送，事件触发时按快速周期发送N次，快速发送周期默认50ms，发送次数默认3次; IfActive:1.未触发时固定周期发送，触发后以较快周期发送；2.未触发时不发送，触发后以固定周期发送; PE:事件未触发时按固定周期发送，事件触发时按快速周期发送N次，快速发送周期默认50ms，发送次数默认3次; On Request:接收到请求后触发; | D4: Data Type 数据类型 | E4: Unsigned integer
A5: Message Periodic Time (ms) 报文周期时间 | B5: 单位：毫秒（ms） | D5: 说明： Big Endian 大端：一个数值的最高有效字节存放在最低的内存地址上 LSB (Least Significant Bit): 最低有效位, 最右边的一位, 从右到左发送
A6: Signal Name 信号名称 | B6: 例：RBMS_Life表示RACK BMS发送的生命值信号
A7: Signal Description 信号描述
A8: Byte 字节 | B8: 1-1500Byte
A9: Bit 位 | B9: 8-1Bit
A10: Signal Send Type 信号发送类型 | B10: Periodic OnChange OnChangeWithRepetition IfActive
A11: Bit Length (Bit) 信号长度
A12: Resolution 精度 | B12: Used to Transform the Hex Value to Physical Value or in Reverse Direction. [Physical Value] = ( [Hex Value] * [Resolution] ) + [Offset] 用于十六进制和物理值间的相互转换。 [物理值] = ( [十六进制值] * [精度] ) + [偏移量]
A13: Offset 偏移量 | B13: Offset Value of the Signal. 信号的偏移量。
A14: Signal Min. Value (phys) 物理最小值 | B14: Physical Minimum Value of the Signal in Physical Value 信号的物理最小值
A15: Signal Max. Value(phys) 物理最大值 | B15: Physical maximum Value of the signal in physical Value 信号的物理最大值
A16: Signal Max. Value(Raw) 原始最大值 | B16: Raw maximum Value of the signal in physical Value 信号的原始最大值
A17: Initial Value(Hex) 初始值 | B17: Predefined Value If no valid signal is Available after Network Startup. 网络启动后没有可用的有效值而预定义的值
A18: Unit 单位 | B18: Unit of the signal physical Value 信号物理值的单位
A19: Signal Value Description 信号值描述 | B19: Hex-Physics Representation of the Signal Value 信号十六进制值所代表的物理值
A20: Message Periodic Time Fast(ms) 报文的快速发送周期(ms) | B20: The Fast Periodic Time of Message if the Send Type is not Periodic. 若报文非周期发送而定义的快速发送周期。
A21: Message Nr. Of Reption 报文的快速发送次数 | B21: The Repetition Number of Message if the Send Type is not Periodic 若报文非周期发送而定义的快速发送次数。
A22: Message Delay Time(ms) 报文延时时间(ms) | B22: The Min Time between the Same Message if the Send Type is not Periodic 若报文非周期发送，相同报文间的最小时间间隔。

Sheet Station ID
B2: BMS No. | C2: IP Address
B3: Bank BMS | C3: 192.168.1.136
B4: Rack BMS #1 | C4: 192.168.1.137
B5: Rack BMS #2 | C5: 192.168.1.138
B6: Rack BMS #3 | C6: 192.168.1.139
B7: Rack BMS #4 | C7: 192.168.1.140
B8: Rack BMS #5 | C8: 192.168.1.141
B9: Rack BMS #6 | C9: 192.168.1.142
B10: Rack BMS #7 | C10: 192.168.1.143
B11: Rack BMS #8 | C11: 192.168.1.144
B12: Rack BMS #9 | C12: 192.168.1.145
B13: Rack BMS #10 | C13: 192.168.1.146
... B16: HMI | C16: 192.168.1.149

Sheet Message ID
A1: Message Name | B1: Description | C1: Send Type | D1: Periodic Time (ms) | E1: cmdGroup | F1: cmdid | G1: 命令类型 0x01:不需要回应的报文； 0x02:需要回应的报文； 0x03:回应的报文 | H1: transportType | I1: 请求payload | J1: 响应payload | K1: struct Name | L1: HMI | M1: BBMS_A | N1: BBMS_M | O1: RBMS | P1: Rx_cmdType (RBMS/BBMS_M/BBMS_A) | Q1: BBMS_A Store | R1: HMI Store | S1: SSD File Type | T1: cmdNUm | U1: N2M Modify | V1: Platform | W1: Special Dim | X1: Disp Jason
A2: RBMS_SumInfo | B2: Rack 概要数据(系统状态、高压状态、接插件温度、消防干接点、TMS、FCU、温湿度、水浸传感器；SOX、持续和瞬时功率、电压温度概要、故障和心跳信号；可充/放容量电量) | C2: Periodic | D2: 1000 | E2: 0x03 | F2: 1 | G2: 0x01 | H2: {=_xlfn.SWITCH(G2,"0x01","YCP_TRANSPORT_UNNEED_ACK","0x02","YCP_TRANSPORT_NEED_ACK","")} -> YCP_TRANSPORT_UNNEED_ACK | I2: struct RBMS_SumInfo | J2: / | K2: =IFERROR(MID(I2, FIND("struct ",I2)+7, LEN(I2)),IFERROR(MID(J2, FIND("struct ",J2)+7, LEN(J2)), "")) -> RBMS_SumInfo | L2: Rx | M2: Rx | N2: Rx | O2: Tx | P2: Set | Q2: 1 | R2: 1 | S2: TYPE_SUMINFO | T2: =COUNTIF(A:A, A2) -> 2 | U2: 1 | V2: BMS20/BMS21/BMS23 | W2: RACK_NUMBER_FOR_EVERY_BANK | X2: 1
A3: RBMS_SumInfo | B3: 写入-N拖M架构A核将获取到的主从机间通信簇数据转发给M核 | C3: OnChange | D3: / | E3: 0x01 | F3: 36 | G3: 0x01 | H3: YCP_TRANSPORT_UNNEED_ACK | I3: struct RBMS_SumInfo_OtherBank | J3: / | K3: =IFERROR(MID(I3, FIND("struct ",I3)+7, LEN(I3)),IFERROR(MID(J3, FIND("struct ",J3)+7, LEN(J3)), "")) -> RBMS_SumInfo_OtherBank | L3: / | M3: / | N3: Rx | O3: / | P3: Set | Q3: 0 | R3: 0 | S3: / | T3: =COUNTIF(A:A, A3) -> 2 | U3: 0 | V3: BMS20/BMS21/BMS23 | W3: / | X3: 0
A4: RBMS_Volt | B4: 电芯电压及其有效性、各AFE总压 | C4: Periodic | D4: 1000 | E4: 0x03 | F4: 2 | G4: 0x01 | H4: {=_xlfn.SWITCH(G4,"0x01","YCP_TRANSPORT_UNNEED_ACK","0x02","YCP_TRANSPORT_NEED_ACK","")} -> YCP_TRANSPORT_UNNEED_ACK | I4: struct RBMS_Volt | J4: / | K4: =IFERROR(MID(I4, FIND("struct ",I4)+7, LEN(I4)),IFERROR(MID(J4, FIND("struct ",J4)+7, LEN(J4)), "")) -> RBMS_Volt | L4: Rx | M4: Rx | N4: / | O4: Tx | P4: Set | Q4: 1 | R4: 1 | S4: TYPE_DETAIL | T4: =COUNTIF(A:A, A4) -> 1 | U4: 0 | V4: BMS20/BMS21/BMS23 | W4: RACK_NUMBER_FOR_EVERY_BANK | X4: 0
A5: RBMS_Temp | B5: 电芯温度、极柱温度、Pack正负极连接件温度、PCB板温及其有效性 | C5: Periodic | D5: 1000 | E5: 0x03 | F5: 3 | G5: 0x01 | H5: {=_xlfn.SWITCH(G5,"0x01","YCP_TRANSPORT_UNNEED_ACK","0x02","YCP_TRANSPORT_NEED_ACK","")} -> YCP_TRANSPORT_UNNEED_ACK | I5: struct RBMS_Temp | J5: / | K5: =IFERROR(MID(I5, FIND("struct ",I5)+7, LEN(I5)),IFERROR(MID(J5, FIND("struct ",J5)+7, LEN(J5)), "")) -> RBMS_Temp | L5: Rx | M5: Rx | N5: / | O5: Tx | P5: Set | Q5: 1 | R5: 1 | S5: TYPE_DETAIL | T5: =COUNTIF(A:A, A5) -> 1 | U5: 0 | V5: BMS20/BMS21/BMS23 | W5: RACK_NUMBER_FOR_EVERY_BANK | X5: 0
A6: RBMS_CellBalSt | B6: Cell Balancing State 电芯均衡状态 | C6: Periodic | D6: 10000 | E6: 0x03 | F6: 4 | G6: 0x01 | H6: {=_xlfn.SWITCH(G6,"0x01","YCP_TRANSPORT_UNNEED_ACK","0x02","YCP_TRANSPORT_NEED_ACK","")} -> YCP_TRANSPORT_UNNEED_ACK | I6: struct RBMS_CellBalSt | J6: / | K6: =IFERROR(MID(I6, FIND("struct ",I6)+7, LEN(I6)),IFERROR(MID(J6, FIND("struct ",J6)+7, LEN(J6)), "")) -> RBMS_CellBalSt | L6: Rx | M6: Rx | N6: / | O6: Tx | P6: Set | Q6: 1 | R6: 1 | S6: TYPE_DETAIL | T6: =COUNTIF(A:A, A6) -> 1 | U6: 0 | V6: BMS20/BMS21/BMS23 | W6: RACK_NUMBER_FOR_EVERY_BANK | X6: 0
A7: RBMS_CellSdr | B7: 单体电芯自放电率 | C7: Periodic | D7: 30000 | E7: 0x03 | F7: 5 | G7: 0x01 | H7: {=_xlfn.SWITCH(G7,"0x01","YCP_TRANSPORT_UNNEED_ACK","0x02","YCP_TRANSPORT_NEED_ACK","")} -> YCP_TRANSPORT_UNNEED_ACK | I7: struct RBMS_CellSdr | J7: / | K7: =IFERROR(MID(I7, FIND("struct ",I7)+7, LEN(I7)),IFERROR(MID(J7, FIND("struct ",J7)+7, LEN(J7)), "")) -> RBMS_CellSdr | L7: Rx | M7: Rx | N7: / | O7: Tx | P7: Set | Q7: 0 | R7: 0 | S7: / | T7: =COUNTIF(A:A, A7) -> 1 | U7: 0 | V7: BMS20/BMS21/BMS23 | W7: RACK_NUMBER_FOR_EVERY_BANK | X7: 0
A8: RBMS_Fault | B8: RBMS故障列表 | C8: Periodic | D8: 1000 | E8: 0x03 | F8: 41 | G8: 0x01 | H8: {=_xlfn.SWITCH(G8,"0x01","YCP_TRANSPORT_UNNEED_ACK","0x02","YCP_TRANSPORT_NEED_ACK","")} -> YCP_TRANSPORT_UNNEED_ACK | I8: struct RBMS_Fault | J8: / | K8: =IFERROR(MID(I8, FIND("struct ",I8)+7, LEN(I8)),IFERROR(MID(J8, FIND("struct ",J8)+7, LEN(J8)), "")) -> RBMS_Fault | L8: Rx | M8: Rx | N8: / | O8: Tx | P8: Set | Q8: 1 | R8: 1 | S8: TYPE_FAULT | T8: =COUNTIF(A:A, A8) -> 1 | U8: 0 | V8: BMS20/BMS21/BMS23 | W8: RACK_NUMBER_FOR_EVERY_BANK | X8: 0
A9: BBMS_SumInfo | B9: Bank 概要数据 | C9: Periodic | D9: 1000 | E9: 0x02 | F9: 1 | G9: 0x01 | H9: {=_xlfn.SWITCH(G9,"0x01","YCP_TRANSPORT_UNNEED_ACK","0x02","YCP_TRANSPORT_NEED_ACK","")} -> YCP_TRANSPORT_UNNEED_ACK | I9: struct BBMS_SumInfo | J9: / | K9: =IFERROR(MID(I9, FIND("struct ",I9)+7, LEN(I9)),IFERROR(MID(J9, FIND("struct ",J9)+7, LEN(J9)), "")) -> BBMS_SumInfo | L9: Rx | M9: Rx | N9: Tx | O9: / | P9: Set | Q9: 1 | R9: 1 | S9: TYPE_SUMINFO | T9: =COUNTIF(A:A, A9) -> 2 | U9: 1 | V9: BMS20/BMS21/BMS23 | W9: / | X9: 1
A10: BBMS_SumInfo | B10: 写入-N拖M架构A核将获取到的主从机间通信堆数据转发给M核 | C10: OnChange | D10: / | E10: 0x01 | F10: 37 | G10: 0x01 | H10: {=_xlfn.SWITCH(G10,"0x01","YCP_TRANSPORT_UNNEED_ACK","0x02","YCP_TRANSPORT_NEED_ACK","")} -> YCP_TRANSPORT_UNNEED_ACK | I10: struct BBMS_SumInfo_OtherBank | J10: / | K10: =IFERROR(MID(I10, FIND("struct ",I10)+7, LEN(I10)),IFERROR(MID(J10, FIND("struct ",J10)+7, LEN(J10)), "")) -> BBMS_SumInfo_OtherBank | L10: / | M10: / | N10: Rx | O10: / | P10: Set | Q10: 0 | R10: 0 | S10: / | T10: =COUNTIF(A:A, A10) -> 2 | U10: 0 | V10: BMS20/BMS21/BMS23 | W10: / | X10: 0
A11: BBMS_Fault | B11: BMS故障列表 | C11: Periodic | D11: 1000 | E11: 0x02 | F11: 19 | G11: 0x01 | H11: {=_xlfn.SWITCH(G11,"0x01","YCP_TRANSPORT_UNNEED_ACK","0x02","YCP_TRANSPORT_NEED_ACK","")} -> YCP_TRANSPORT_UNNEED_ACK | I11: struct BBMS_Fault | J11: / | K11: =IFERROR(MID(I11, FIND("struct ",I11)+7, LEN(I11)),IFERROR(MID(J11, FIND("struct ",J11)+7, LEN(J11)), "")) -> BBMS_Fault | L11: Rx | M11: Rx | N11: Tx | O11: / | P11: Set | Q11: 1 | R11: 1 | S11: TYPE_FAULT | T11: =COUNTIF(A:A, A11) -> 1 | U11: 1 | V11: BMS20/BMS21/BMS23 | W11: / | X11: 0
A12: BBMS_CtlWord | B12: BBMS Control BBMS控制指令 | C12: Periodic | D12: 1000 | E12: 0x03 | F12: 7 | G12: 0x02 | H12: {=_xlfn.SWITCH(G12,"0x01","YCP_TRANSPORT_UNNEED_ACK","0x02","YCP_TRANSPORT_NEED_ACK","")} -> YCP_TRANSPORT_NEED_ACK | I12: struct BBMS_CtlWord | J12: struct state{ uint8_t state; //00：写入成功，01：写入失败 } | K12: =IFERROR(MID(I12, FIND("struct ",I12)+7, LEN(I12)),IFERROR(MID(J12, FIND("struct ",J12)+7, LEN(J12)), "")) -> BBMS_CtlWord | L12: / | M12: / | N12: Tx | O12: Rx | P12: Set | Q12: 0 | R12: 0 | S12: / | T12: =COUNTIF(A:A, A12) -> 2 | U12: 1 | V12: BMS20/BMS21/BMS23 | W12: RACK_NUMBER_FOR_EVERY_BANK | X12: 0
A13: BBMS_CtlWord | B13: 存储所有Rack的BBMS控制命令 | C13: Periodic | D13: 1000 | E13: 0x02 | F13: 12 | G13: 0x01 | H13: {=_xlfn.SWITCH(G13,"0x01","YCP_TRANSPORT_UNNEED_ACK","0x02","YCP_TRANSPORT_NEED_ACK","")} -> YCP_TRANSPORT_UNNEED_ACK | I13: struct BBMS_CtlWordAllRack | J13: / | K13: =IFERROR(MID(I13, FIND("struct ",I13)+7, LEN(I13)),IFERROR(MID(J13, FIND("struct ",J13)+7, LEN(J13)), "")) -> BBMS_CtlWordAllRack | L13: Rx | M13: Rx | N13: Tx | O13: / | P13: Set | Q13: 1 | R13: 1 | S13: TYPE_SUMINFO | T13: =COUNTIF(A:A, A13) -> 2 | U13: 1 | V13: BMS20/BMS21/BMS23 | W13: RACK_NUMBER_FOR_EVERY_BANK | X13: 0
A14: HMI_CtlWord | B14: HMI Control HMI 控制指令 | C14: OnChange | D14: / | E14: 0x04 | F14: 4 | G14: 0x02 | H14: {=_xlfn.SWITCH(G14,"0x01","YCP_TRANSPORT_UNNEED_ACK","0x02","YCP_TRANSPORT_NEED_ACK","")} -> YCP_TRANSPORT_NEED_ACK | I14: struct HMI_CtlWord | J14: struct state{ uint8_t state; //00：写入成功，01：写入失败 } | K14: =IFERROR(MID(I14, FIND("struct ",I14)+7, LEN(I14)),IFERROR(MID(J14, FIND("struct ",J14)+7, LEN(J14)), "")) -> HMI_CtlWord | L14: Tx | M14: Rx | N14: Rx | O14: Rx | P14: Set | Q14: 0 | R14: 0 | S14: / | T14: =COUNTIF(A:A, A14) -> 1 | U14: 1 | V14: BMS20/BMS21/BMS23 | W14: / | X14: 0
A15: HMI_TMSCtrlWord | B15: HMI TMS控制指令(BBMS) | C15: OnChange | D15: / | E15: 0x02 | F15: 3 | G15: 0x02 | H15: {=_xlfn.SWITCH(G15,"0x01","YCP_TRANSPORT_UNNEED_ACK","0x02","YCP_TRANSPORT_NEED_ACK","")} -> YCP_TRANSPORT_NEED_ACK | I15: struct HMI_TMSCtrlWord | J15: struct state{ uint8_t state; //00：写入成功，01：写入失败 } | K15: =IFERROR(MID(I15, FIND("struct ",I15)+7, LEN(I15)),IFERROR(MID(J15, FIND("struct ",J15)+7, LEN(J15)), "")) -> HMI_TMSCtrlWord | L15: Tx | M15: / | N15: Rx | O15: / | P15: Set | Q15: 0 | R15: 0 | S15: / | T15: =COUNTIF(A:A, A15) -> 2 | U15: 0 | V15: BMS20/BMS21 | W15: TMS_NUM | X15: 0
A16: HMI_TMSCtrlWord | B16: HMI TMS控制指令(RBMS) | C16: OnChange | D16: / | E16: 0x03 | F16: 37 | G16: 0x02 | H16: {=_xlfn.SWITCH(G16,"0x01","YCP_TRANSPORT_UNNEED_ACK","0x02","YCP_TRANSPORT_NEED_ACK","")} -> YCP_TRANSPORT_NEED_ACK | I16: struct HMI_TMSCtrlWord | J16: struct state{ uint8_t state; //00：写入成功，01：写入失败 } | K16: =IFERROR(MID(I16, FIND("struct ",I16)+7, LEN(I16)),IFERROR(MID(J16, FIND("struct ",J16)+7, LEN(J16)), "")) -> HMI_TMSCtrlWord | L16: Tx | M16: / | N16: / | O16: Rx | P16: Set | Q16: 0 | R16: 0 | S16: / | T16: =COUNTIF(A:A, A16) -> 2 | U16: 0 | V16: BMS23 | W16: / | X16: 0
A17: HMI_BankDOCtrl | B17: HMI三级板DO控制指令（灯） | C17: OnChange | D17: / | E17: 0x02 | F17: 4 | G17: 0x02 | H17: {=_xlfn.SWITCH(G17,"0x01","YCP_TRANSPORT_UNNEED_ACK","0x02","YCP_TRANSPORT_NEED_ACK","")} -> YCP_TRANSPORT_NEED_ACK | I17: struct HMI_BankDOCtrl | J17: struct state{ uint8_t state; //00：写入成功，01：写入失败 } | K17: =IFERROR(MID(I17, FIND("struct ",I17)+7, LEN(I17)),IFERROR(MID(J17, FIND("struct ",J17)+7, LEN(J17)), "")) -> HMI_BankDOCtrl | L17: Tx | M17: / | N17: Rx | O17: / | P17: Set | Q17: 0 | R17: 0 | S17: / | T17: =COUNTIF(A:A, A17) -> 1 | U17: 0 | V17: BMS20/BMS21/BMS23 | W17: / | X17: 0
A18: HMI_RackCaliCtrl | B18: Rack标定与控制 | C18: OnChange | D18: / | E18: 0x03 | F18: 8 | G18: 0x02 | H18: {=_xlfn.SWITCH(G18,"0x01","YCP_TRANSPORT_UNNEED_ACK","0x02","YCP_TRANSPORT_NEED_ACK","")} -> YCP_TRANSPORT_NEED_ACK | I18: struct HMI_RackCaliCtrl | J18: struct state{ uint8_t state; //00：写入成功，01：写入失败 } | K18: =IFERROR(MID(I18, FIND("struct ",I18)+7, LEN(I18)),IFERROR(MID(J18, FIND("struct ",J18)+7, LEN(J18)), "")) -> HMI_RackCaliCtrl | L18: Tx | M18: / | N18: / | O18: Rx | P18: Set | Q18: 0 | R18: 0 | S18: / | T18: =COUNTIF(A:A, A18) -> 1 | U18: 0 | V18: BMS20/BMS21/BMS23 | W18: / | X18: 0
A19: HMI_RBMSRlyCtrl | B19: HMI二级板继电器强控指令 | C19: OnChange | D19: / | E19: 0x03 | F19: 9 | G19: 0x02 | H19: {=_xlfn.SWITCH(G19,"0x01","YCP_TRANSPORT_UNNEED_ACK","0x02","YCP_TRANSPORT_NEED_ACK","")} -> YCP_TRANSPORT_NEED_ACK | I19: struct HMI_RBMSRlyCtrl | J19: struct state{ uint8_t state; //00：写入成功，01：写入失败 } | K19: =IFERROR(MID(I19, FIND("struct ",I19)+7, LEN(I19)),IFERROR(MID(J19, FIND("struct ",J19)+7, LEN(J19)), "")) -> HMI_RBMSRlyCtrl | L19: Tx | M19: / | N19: / | O19: Rx | P19: Set | Q19: 0 | R19: 0 | S19: / | T19: =COUNTIF(A:A, A19) -> 1 | U19: 0 | V19: BMS20/BMS21/BMS23 | W19: / | X19: 0
A20: TMS_SumInfo | B20: 热管理信息(BBMS) | C20: Periodic | D20: 1000 | E20: 0x02 | F20: 2 | G20: 0x01 | H20: {=_xlfn.SWITCH(G20,"0x01","YCP_TRANSPORT_UNNEED_ACK","0x02","YCP_TRANSPORT_NEED_ACK","")} -> YCP_TRANSPORT_UNNEED_ACK | I20: struct TMS_SumInfo | J20: / | K20: =IFERROR(MID(I20, FIND("struct ",I20)+7, LEN(I20)),IFERROR(MID(J20, FIND("struct ",J20)+7, LEN(J20)), "")) -> TMS_SumInfo | L20: Rx | M20: Rx | N20: Tx | O20: / | P20: Set | Q20: 1 | R20: 1 | S20: TYPE_SUMINFO | T20: =COUNTIF(A:A, A20) -> 2 | U20: 0 | V20: BMS20/BMS21 | W20: TMS_NUM | X20: 1
A21: TMS_SumInfo | B21: 热管理信息(RBMS) | C21: Periodic | D21: 1000 | E21: 0x03 | F21: 38 | G21: 0x01 | H21: {=_xlfn.SWITCH(G21,"0x01","YCP_TRANSPORT_UNNEED_ACK","0x02","YCP_TRANSPORT_NEED_ACK","")} -> YCP_TRANSPORT_UNNEED_ACK | I21: struct TMS_SumInfo | J21: / | K21: =IFERROR(MID(I21, FIND("struct ",I21)+7, LEN(I21)),IFERROR(MID(J21, FIND("struct ",J21)+7, LEN(J21)), "")) -> TMS_SumInfo | L21: Rx | M21: Rx | N21: / | O21: Tx | P21: Set | Q21: 1 | R21: 1 | S21: TYPE_SUMINFO | T21: =COUNTIF(A:A, A21) -> 2 | U21: 0 | V21: BMS23 | W21: RACK_NUMBER_FOR_EVERY_BANK | X21: 1
A22: ParaThr_CellV | B22: 读取-电压阈值参数 | C22: OnChange | D22: / | E22: 0x03 | F22: 10 | G22: 0x02 | H22: {=_xlfn.SWITCH(G22,"0x01","YCP_TRANSPORT_UNNEED_ACK","0x02","YCP_TRANSPORT_NEED_ACK","")} -> YCP_TRANSPORT_NEED_ACK | I22: / | J22: struct ParaThr_CellV | K22: =IFERROR(MID(I22, FIND("struct ",I22)+7, LEN(I22)),IFERROR(MID(J22, FIND("struct ",J22)+7, LEN(J22)), "")) -> ParaThr_CellV | L22: Tx | M22: / | N22: / | O22: Rx | P22: Get | Q22: 0 | R22: 0 | S22: / | T22: =COUNTIF(A:A, A22) -> 2 | U22: 0 | V22: BMS20/BMS21/BMS23 | W22: / | X22: 0
A23: ParaThr_CellV | B23: 写入-电压阈值参数 | C23: OnChange | D23: / | E23: 0x03 | F23: 11 | G23: 0x02 | H23: {=_xlfn.SWITCH(G23,"0x01","YCP_TRANSPORT_UNNEED_ACK","0x02","YCP_TRANSPORT_NEED_ACK","")} -> YCP_TRANSPORT_NEED_ACK | I23: struct ParaThr_CellV | J23: struct state{ uint8_t state; //00：写入成功，01：写入失败 } | K23: =IFERROR(MID(I23, FIND("struct ",I23)+7, LEN(I23)),IFERROR(MID(J23, FIND("struct ",J23)+7, LEN(J23)), "")) -> ParaThr_CellV | L23: Tx | M23: / | N23: / | O23: Rx | P23: Set | Q23: 0 | R23: 0 | S23: / | T23: =COUNTIF(A:A, A23) -> 2 | U23: 0 | V23: BMS20/BMS21/BMS23 | W23: / | X23: 0
A24: ParaThr_RackV | B24: 读取-簇电压阈值参数 | C24: OnChange | D24: / | E24: 0x03 | F24: 12 | G24: 0x02 | H24: {=_xlfn.SWITCH(G24,"0x01","YCP_TRANSPORT_UNNEED_ACK","0x02","YCP_TRANSPORT_NEED_ACK","")} -> YCP_TRANSPORT_NEED_ACK | I24: / | J24: struct ParaThr_RackV | K24: =IFERROR(MID(I24, FIND("struct ",I24)+7, LEN(I24)),IFERROR(MID(J24, FIND("struct ",J24)+7, LEN(J24)), "")) -> ParaThr_RackV | L24: Tx | M24: / | N24: / | O24: Rx | P24: Get | Q24: 0 | R24: 0 | S24: / | T24: =COUNTIF(A:A, A24) -> 2 | U24: 0 | V24: BMS20/BMS21/BMS23 | W24: / | X24: 0
A25: ParaThr_RackV | B25: 写入-簇电压阈值参数 | C25: OnChange | D25: / | E25: 0x03 | F25: 13 | G25: 0x02 | H25: {=_xlfn.SWITCH(G25,"0x01","YCP_TRANSPORT_UNNEED_ACK","0x02","YCP_TRANSPORT_NEED_ACK","")} -> YCP_TRANSPORT_NEED_ACK | I25: struct ParaThr_RackV | J25: struct state{ uint8_t state; //00：写入成功，01：写入失败 } | K25: =IFERROR(MID(I25, FIND("struct ",I25)+7, LEN(I25)),IFERROR(MID(J25, FIND("struct ",J25)+7, LEN(J25)), "")) -> ParaThr_RackV | L25: Tx | M25: / | N25: / | O25: Rx | P25: Set | Q25: 0 | R25: 0 | S25: / | T25: =COUNTIF(A:A, A25) -> 2 | U25: 0 | V25: BMS20/BMS21/BMS23 | W25: / | X25: 0
A26: ParaThr_RackI | B26: 读取-簇电流阈值参数 | C26: OnChange | D26: / | E26: 0x03 | F26: 14 | G26: 0x02 | H26: {=_xlfn.SWITCH(G26,"0x01","YCP_TRANSPORT_UNNEED_ACK","0x02","YCP_TRANSPORT_NEED_ACK","")} -> YCP_TRANSPORT_NEED_ACK | I26: / | J26: struct ParaThr_RackI | K26: =IFERROR(MID(I26, FIND("struct ",I26)+7, LEN(I26)),IFERROR(MID(J26, FIND("struct ",J26)+7, LEN(J26)), "")) -> ParaThr_RackI | L26: Tx | M26: / | N26: / | O26: Rx | P26: Get | Q26: 0 | R26: 0 | S26: / | T26: =COUNTIF(A:A, A26) -> 2 | U26: 0 | V26: BMS20/BMS21/BMS23 | W26: / | X26: 0
A27: ParaThr_RackI | B27: 写入-簇电流阈值参数 | C27: OnChange | D27: / | E27: 0x03 | F27: 15 | G27: 0x02 | H27: {=_xlfn.SWITCH(G27,"0x01","YCP_TRANSPORT_UNNEED_ACK","0x02","YCP_TRANSPORT_NEED_ACK","")} -> YCP_TRANSPORT_NEED_ACK | I27: struct ParaThr_RackI | J27: struct state{ uint8_t state; //00：写入成功，01：写入失败 } | K27: =IFERROR(MID(I27, FIND("struct ",I27)+7, LEN(I27)),IFERROR(MID(J27, FIND("struct ",J27)+7, LEN(J27)), "")) -> ParaThr_RackI | L27: Tx | M27: / | N27: / | O27: Rx | P27: Set | Q27: 0 | R27: 0 | S27: / | T27: =COUNTIF(A:A, A27) -> 2 | U27: 0 | V27: BMS20/BMS21/BMS23 | W27: / | X27: 0
A28: ParaThr_ModuleT | B28: 读取-温度阈值参数 | C28: OnChange | D28: / | E28: 0x03 | F28: 16 | G28: 0x02 | H28: {=_xlfn.SWITCH(G28,"0x01","YCP_TRANSPORT_UNNEED_ACK","0x02","YCP_TRANSPORT_NEED_ACK","")} -> YCP_TRANSPORT_NEED_ACK | I28: / | J28: struct ParaThr_ModuleT | K28: =IFERROR(MID(I28, FIND("struct ",I28)+7, LEN(I28)),IFERROR(MID(J28, FIND("struct ",J28)+7, LEN(J28)), "")) -> ParaThr_ModuleT | L28: Tx | M28: / | N28: / | O28: Rx | P28: Get | Q28: 0 | R28: 0 | S28: / | T28: =COUNTIF(A:A, A28) -> 2 | U28: 0 | V28: BMS20/BMS21/BMS23 | W28: / | X28: 0
A29: ParaThr_ModuleT | B29: 写入-温度阈值参数 | C29: OnChange | D29: / | E29: 0x03 | F29: 17 | G29: 0x02 | H29: {=_xlfn.SWITCH(G29,"0x01","YCP_TRANSPORT_UNNEED_ACK","0x02","YCP_TRANSPORT_NEED_ACK","")} -> YCP_TRANSPORT_NEED_ACK | I29: struct ParaThr_ModuleT | J29: struct state{ uint8_t state; //00：写入成功，01：写入失败 } | K29: =IFERROR(MID(I29, FIND("struct ",I29)+7, LEN(I29)),IFERROR(MID(J29, FIND("struct ",J29)+7, LEN(J29)), "")) -> ParaThr_ModuleT | L29: Tx | M29: / | N29: / | O29: Rx | P29: Set | Q29: 0 | R29: 0 | S29: / | T29: =COUNTIF(A:A, A29) -> 2 | U29: 0 | V29: BMS20/BMS21/BMS23 | W29: / | X29: 0
A30: ParaThr_SOX | B30: 读取-SOX阈值参数 | C30: OnChange | D30: / | E30: 0x03 | F30: 18 | G30: 0x02 | H30: {=_xlfn.SWITCH(G30,"0x01","YCP_TRANSPORT_UNNEED_ACK","0x02","YCP_TRANSPORT_NEED_ACK","")} -> YCP_TRANSPORT_NEED_ACK | I30: / | J30: struct ParaThr_SOX | K30: =IFERROR(MID(I30, FIND("struct ",I30)+7, LEN(I30)),IFERROR(MID(J30, FIND("struct ",J30)+7, LEN(J30)), "")) -> ParaThr_SOX | L30: Tx | M30: / | N30: / | O30: Rx | P30: Get | Q30: 0 | R30: 0 | S30: / | T30: =COUNTIF(A:A, A30) -> 2 | U30: 0 | V30: BMS20/BMS21/BMS23 | W30: / | X30: 0
A31: ParaThr_SOX | B31: 写入-SOX阈值参数 | C31: OnChange | D31: / | E31: 0x03 | F31: 19 | G31: 0x02 | H31: {=_xlfn.SWITCH(G31,"0x01","YCP_TRANSPORT_UNNEED_ACK","0x02","YCP_TRANSPORT_NEED_ACK","")} -> YCP_TRANSPORT_NEED_ACK | I31: struct ParaThr_SOX | J31: struct state{ uint8_t state; //00：写入成功，01：写入失败 } | K31: =IFERROR(MID(I31, FIND("struct ",I31)+7, LEN(I31)),IFERROR(MID(J31, FIND("struct ",J31)+7, LEN(J31)), "")) -> ParaThr_SOX | L31: Tx | M31: / | N31: / | O31: Rx | P31: Set | Q31: 0 | R31: 0 | S31: / | T31: =COUNTIF(A:A, A31) -> 2 | U31: 0 | V31: BMS20/BMS21/BMS23 | W31: / | X31: 0
A32: ParaThr_AUX | B32: 读取-AUX阈值参数 | C32: OnChange | D32: / | E32: 0x03 | F32: 20 | G32: 0x02 | H32: {=_xlfn.SWITCH(G32,"0x01","YCP_TRANSPORT_UNNEED_ACK","0x02","YCP_TRANSPORT_NEED_ACK","")} -> YCP_TRANSPORT_NEED_ACK | I32: / | J32: struct ParaThr_AUX | K32: =IFERROR(MID(I32, FIND("struct ",I32)+7, LEN(I32)),IFERROR(MID(J32, FIND("struct ",J32)+7, LEN(J32)), "")) -> ParaThr_AUX | L32: Tx | M32: / | N32: / | O32: Rx | P32: Get | Q32: 0 | R32: 0 | S32: / | T32: =COUNTIF(A:A, A32) -> 2 | U32: 0 | V32: BMS20/BMS21/BMS23 | W32: / | X32: 0
A33: ParaThr_AUX | B33: 写入-AUX阈值参数 | C33: OnChange | D33: / | E33: 0x03 | F33: 21 | G33: 0x02 | H33: {=_xlfn.SWITCH(G33,"0x01","YCP_TRANSPORT_UNNEED_ACK","0x02","YCP_TRANSPORT_NEED_ACK","")} -> YCP_TRANSPORT_NEED_ACK | I33: struct ParaThr_AUX | J33: struct state{ uint8_t state; //00：写入成功，01：写入失败 } | K33: =IFERROR(MID(I33, FIND("struct ",I33)+7, LEN(I33)),IFERROR(MID(J33, FIND("struct ",J33)+7, LEN(J33)), "")) -> ParaThr_AUX | L33: Tx | M33: / | N33: / | O33: Rx | P33: Set | Q33: 0 | R33: 0 | S33: / | T33: =COUNTIF(A:A, A33) -> 2 | U33: 0 | V33: BMS20/BMS21/BMS23 | W33: / | X33: 0
... A39: HMI_BBMSDOCtrl | B39: HMI三级板DO控制命令 | C39: OnChange | D39: / | E39: 0x02 | F39: 10 | G39: 0x02 | H39: {=_xlfn.SWITCH(G39,"0x01","YCP_TRANSPORT_UNNEED_ACK","0x02","YCP_TRANSPORT_NEED_ACK","")} -> YCP_TRANSPORT_NEED_ACK | I39: struct HMI_BBMSDOCtrl | J39: struct state{ uint8_t state; //00：写入成功，01：写入失败 } | K39: =IFERROR(MID(I39, FIND("struct ",I39)+7, LEN(I39)),IFERROR(MID(J39, FIND("struct ",J39)+7, LEN(J39)), "")) -> HMI_BBMSDOCtrl | L39: Tx | M39: / | N39: Rx | O39: / | P39: Set | Q39: 0 | R39: 0 | S39: / | T39: =COUNTIF(A:A, A39) -> 1 | U39: 0 | V39: BMS20/BMS21/BMS23 | W39: / | X39: 0
A40: RBMS_SOXdebugData1 | B40: SOX算法调试的输入数据，包含电流、电压、温度等 | C40: Periodic | D40: 1000 | E40: 0x03 | F40: 25 | G40: 0x01 | H40: {=_xlfn.SWITCH(G40,"0x01","YCP_TRANSPORT_UNNEED_ACK","0x02","YCP_TRANSPORT_NEED_ACK","")} -> YCP_TRANSPORT_UNNEED_ACK | I40: struct RBMS_SOXdebugData1 | J40: / | K40: =IFERROR(MID(I40, FIND("struct ",I40)+7, LEN(I40)),IFERROR(MID(J40, FIND("struct ",J40)+7, LEN(J40)), "")) -> RBMS_SOXdebugData1 | L40: Rx | M40: Rx | N40: / | O40: Tx | P40: Set | Q40: 1 | R40: 1 | S40: TYPE_DEBUG | T40: =COUNTIF(A:A, A40) -> 1 | U40: 0 | V40: BMS20/BMS21/BMS23 | W40: RACK_NUMBER_FOR_EVERY_BANK | X40: 0
A41: RBMS_SOXdebugData2 | B41: SOX算法调试的输出数据，包含SOC、SOHC、容量等 | C41: Periodic | D41: 1000 | E41: 0x03 | F41: 26 | G41: 0x01 | H41: {=_xlfn.SWITCH(G41,"0x01","YCP_TRANSPORT_UNNEED_ACK","0x02","YCP_TRANSPORT_NEED_ACK","")} -> YCP_TRANSPORT_UNNEED_ACK | I41: struct RBMS_SOXdebugData2 | J41: / | K41: =IFERROR(MID(I41, FIND("struct ",I41)+7, LEN(I41)),IFERROR(MID(J41, FIND("struct ",J41)+7, LEN(J41)), "")) -> RBMS_SOXdebugData2 | L41: Rx | M41: Rx | N41: / | O41: Tx | P41: Set | Q41: 1 | R41: 1 | S41: TYPE_DEBUG | T41: =COUNTIF(A:A, A41) -> 1 | U41: 0 | V41: BMS20/BMS21/BMS23 | W41: RACK_NUMBER_FOR_EVERY_BANK | X41: 0
A42: HMI_RackFaultCali | B42: 写入-Rack故障累积次数标定 | C42: OnChange | D42: / | E42: 0x03 | F42: 28 | G42: 0x02 | H42: {=_xlfn.SWITCH(G42,"0x01","YCP_TRANSPORT_UNNEED_ACK","0x02","YCP_TRANSPORT_NEED_ACK","")} -> YCP_TRANSPORT_NEED_ACK | I42: struct HMI_RackFaultCali | J42: struct state{ uint8_t state; //00：写入成功，01：写入失败 } | K42: =IFERROR(MID(I42, FIND("struct ",I42)+7, LEN(I42)),IFERROR(MID(J42, FIND("struct ",J42)+7, LEN(J42)), "")) -> HMI_RackFaultCali | L42: Tx | M42: / | N42: / | O42: Rx | P42: Set | Q42: 0 | R42: 0 | S42: / | T42: =COUNTIF(A:A, A42) -> 1 | U42: 0 | V42: BMS20/BMS21/BMS23 | W42: / | X42: 0
A43: HMI_BankFaultCali | B43: 写入-Bank故障累积次数标定 | C43: OnChange | D43: / | E43: 0x02 | F43: 11 | G43: 0x02 | H43: {=_xlfn.SWITCH(G43,"0x01","YCP_TRANSPORT_UNNEED_ACK","0x02","YCP_TRANSPORT_NEED_ACK","")} -> YCP_TRANSPORT_NEED_ACK | I43: struct HMI_BankFaultCali | J43: struct state{ uint8_t state; //00：写入成功，01：写入失败 } | K43: =IFERROR(MID(I43, FIND("struct ",I43)+7, LEN(I43)),IFERROR(MID(J43, FIND("struct ",J43)+7, LEN(J43)), "")) -> HMI_BankFaultCali | L43: Tx | M43: / | N43: Rx | O43: / | P43: Set | Q43: 0 | R43: 0 | S43: / | T43: =COUNTIF(A:A, A43) -> 1 | U43: 1 | V43: BMS20/BMS21/BMS23 | W43: / | X43: 0
A44: HMI_FltOvTiNbr | B44: 读取-RBMS/BBMS故障越限次数 | C44: OnChange | D44: / | E44: 0x04 | F44: 5 | G44: 0x02 | H44: {=_xlfn.SWITCH(G44,"0x01","YCP_TRANSPORT_UNNEED_ACK","0x02","YCP_TRANSPORT_NEED_ACK","")} -> YCP_TRANSPORT_NEED_ACK | I44: / | J44: struct HMI_FltOvTiNbr | K44: =IFERROR(MID(I44, FIND("struct ",I44)+7, LEN(I44)),IFERROR(MID(J44, FIND("struct ",J44)+7, LEN(J44)), "")) -> HMI_FltOvTiNbr | L44: Tx | M44: / | N44: Rx | O44: Rx | P44: Get | Q44: 0 | R44: 0 | S44: / | T44: =COUNTIF(A:A, A44) -> 1 | U44: 1 | V44: BMS20/BMS21/BMS23 | W44: / | X44: 0
A45: RBMS_Debug | B45: 模型调试信息 | C45: Periodic | D45: 1000 | E45: 0x03 | F45: 23 | G45: 0x01 | H45: {=_xlfn.SWITCH(G45,"0x01","YCP_TRANSPORT_UNNEED_ACK","0x02","YCP_TRANSPORT_NEED_ACK","")} -> YCP_TRANSPORT_UNNEED_ACK | I45: struct RBMS_Debug | J45: / | K45: =IFERROR(MID(I45, FIND("struct ",I45)+7, LEN(I45)),IFERROR(MID(J45, FIND("struct ",J45)+7, LEN(J45)), "")) -> RBMS_Debug | L45: Rx | M45: Rx | N45: / | O45: Tx | P45: Set | Q45: 1 | R45: 1 | S45: TYPE_DEBUG | T45: =COUNTIF(A:A, A45) -> 1 | U45: 0 | V45: BMS20/BMS21/BMS23 | W45: RACK_NUMBER_FOR_EVERY_BANK | X45: 0
...

Sheet Comm Matrix
A1: Message Name | B1: Description | C1: Signal Name | D1: Signal Description | E1: Byte | F1: Start Bit | G1: Bit Length (Bit) | H1: Resolution | I1: offset | J1: Signal Min. Value (Valid) | K1: Signal Max. Value (Valid) | L1: Initial Value | M1: Unit | N1: CSV Store Length(Byte) | O1: Signal Value Description | P1: SSD Store Display | Q1: Upper Computer Display | R1: remark | S1: Tx Mapping Signal (RBMS/BBMS_M/BBMS_A) | T1: Rx Mapping Signal (BBMS_A) | U1: Rx Mapping Signal (BBMS_M) | V1: Rx Mapping Signal (RBMS) | W1: Signal ArrType | Y1: Signal Description V2
A2: RBMS_SumInfo | B2: =VLOOKUP(A2,'Message ID'!A:O,2,FALSE) -> Rack 概要数据(系统状态、高压状态、接插件温度、消防干接点、TMS、FCU、温湿度、水浸传感器；SOX、持续和瞬时功率、电压温度概要、故障和心跳信号；可充/放容量电量) | E2: 310 | N2: =SUM(N3:N139) -> 765
C3: RBMS_St | D3: Battery String Status 电池串工作状态 | E3: =IF(INT((F3 + G3-1) / 8) + 1 = INT(F3 / 8) + 1, INT(F3 / 8) + 1, INT(F3 / 8) + 1 & "-" & INT((F3 + G3 - 1) / 8) + 1) -> 1 | F3: 0 | G3: 8 | H3: 1 | I3: 0 | J3: 0 | K3: =(POWER(2,G3)-1)*H3+I3 -> 255 | L3: 0 | M3: / | N3: =LEN(K3) -> 3 | O3: Bit0[1]: Rack Enable Status;Rack使能状态 Signal; 0X0-Disabled; 0X1-Enabled; Bit1[1]: Rack Online Status;Rack在线状态 Signal; 0X0-Offline; 0X1-Online; Bit2-Bit3[1]: Rack Control Mode Status;Rack控制模式 Signal; 0X1-Debug; 0X2-BMS Control; 0X3-EMS Control; Bit4[1]: Overall Balancing Status;均衡状态 Signal; 0X0-Stop; 0X1-Ongoing; Bit5[1]: Green Light Status;绿灯状态 Signal; 0X0-Off; 0X1-On; Bit6[1]: Yellow Light Status;黄灯状态 Signal; 0X0-Off; 0X1-On; Bit7[1]: Red Light Status;红灯状态 Signal; 0X0-Off; 0X1-On; | P3: Rack状态,Rack Status;系统信息[1,1,6] | Q3: Y | S3: ScEMCT_RBMS_St | T3: BSWSRackSt | U3: BSWSRackSt | V3: / | Y3: Working Status 工作状态
C4: RBMS_ChaSt | D4: Rack Charging Status Rack充放电状态 | E4: =IF(INT((F4 + G4-1) / 8) + 1 = INT(F4 / 8) + 1, INT(F4 / 8) + 1, INT(F4 / 8) + 1 & "-" & INT((F4 + G4 - 1) / 8) + 1) -> 2 | F4: =F3+G3 -> 8 | G4: 8 | H4: 1 | I4: 0 | J4: 0 | K4: =(POWER(2,G4)-1)*H4+I4 -> 255 | L4: 0 | M4: / | N4: =LEN(K4) -> 3 | O4: Enum 0X1: Not Connected; 0X2: Full Discharge; 0X3: Discharge; 0X4: Charge; 0X5: Full Charge; 0X6: Standing; | P4: Rack状态,Rack Status;系统信息[1,1,8] | Q4: Y | R4: 模型逻辑不需要更新，仅更新显示 | S4: ScEMCT_RBMS_ChaSt | T4: / | U4: BSWSRackChaSt | V4: / | Y4: Charging Status 充放电状态
C5: RBMS_SysOperSt | D5: Rack Operating Status Rack运行状态 | E5: =IF(INT((F5 + G5-1) / 8) + 1 = INT(F5 / 8) + 1, INT(F5 / 8) + 1, INT(F5 / 8) + 1 & "-" & INT((F5 + G5 - 1) / 8) + 1) -> 3 | F5: =F4+G4 -> 16 | G5: 8 | H5: 1 | I5: 0 | J5: 0 | K5: =(POWER(2,G5)-1)*H5+I5 -> 255 | L5: 0 | M5: / | N5: =LEN(K5) -> 3 | O5: Enum 0X1: Not Connected; 0X2: Starting; 0X3: Connected; 0X4: Reserved; 0X5: SOC Protection; 0X63: Fault; | P5: Rack状态,Rack Status;系统信息[1,1,7] | Q5: Y | R5: xuc 0826：RBMS_SysOperSt中SOC低直接用SOC低故障 @张龙b 其他模型逻辑不需要更新，仅更新显示 | S5: ScEMCT_RBMS_SysOperSt | T5: / | U5: BSWSRackSysOperSt | V5: / | Y5: Operating Status 运行状态
C6: RBMS_ConSt | D6: Contactor Status 继电器/干接点状态 | E6: =IF(INT((F6 + G6-1) / 8) + 1 = INT(F6 / 8) + 1, INT(F6 / 8) + 1, INT(F6 / 8) + 1 & "-" & INT((F6 + G6 - 1) / 8) + 1) -> 4-5 | F6: =F5+G5 -> 24 | G6: 16 | H6: 1 | I6: 0 | J6: 0 | K6: =(POWER(2,G6)-1)*H6+I6 -> 65535 | L6: 0 | M6: / | N6: =LEN(K6) -> 5 | O6: Bit0[1]: Main Negative Contactor Status;主负继电器状态; Signal; 0X0-Open; 0X1-Closed; Bit1[1]: Main Positive Contactor Status;主正继电器状态; Signal; 0X0-Open; 0X1-Closed; Bit2[1]: Precharge Contactor Status;预充继电器状态 Signal; 0X0-Open; 0X1-Closed; Bit3[0]: Reserved;保留 Signal; 0X0-Open; 0X1-Closed; Bit4[0]: Reserved;保留 Signal; 0X0-Open; 0X1-Closed; Bit5[0]: Reserved;保留 Signal; 0X0-Open; 0X1-Closed; Bit6[1]: QS Switch Status;隔离开关QS状态 Signal; 0X0-Closed; 0X1-Open; Bit7[1]: HV Interlock Status;高压互锁状态 Signal; 0X0-Closed; 0X1-Open; Bit8-Bit9[0]: HV Box Cooling Fan Status;高压箱冷却风扇状态 Signal; 0X0-Open; 0X1-Closed; Bit10[1]: EStop Status;急停状态 Signal; 0X0-Closed; 0X1-Open; Bit11[0]: Reserved;保留 Signal； 0X0-Open; 0X1-Closed; Bit12[0]: Reserved;保留 Signal; 0X0-Open; 0X1-Closed; Bit13[0]: Reserved;保留 Signal; 0X0-Open; 0X1-Closed; Bit14[1]: Isolation Finished Flag;绝缘完成标志 Signal; 0X0-No; 0X1-Yes; Bit15[1]: Door Open Status;电柜门状态 Signal; 0X0-Closed; 0X1-Open; | P6: Rack状态,Rack Status;继电器信息[1,2,2] | Q6: Y | S6: ScEMCT_RBMS_ConSt | T6: / | U6: BSWSRackConSt | V6: / | Y6: Contactor Status 接触器状态
C7: RBMS_ConFail | D7: HV Connect Fail Reason 高压连接失败原因 | E7: =IF(INT((F7 + G7-1) / 8) + 1 = INT(F7 / 8) + 1, INT(F7 / 8) + 1, INT(F7 / 8) + 1 & "-" & INT((F7 + G7 - 1) / 8) + 1) -> 6-7 | F7: =F6+G6 -> 40 | G7: 16 | H7: 1 | I7: 0 | J7: 0 | K7: =(POWER(2,G7)-1)*H7+I7 -> 65535 | L7: 0 | M7: / | N7: =LEN(K7) -> 5 | O7: Enums Bit0: Insulation Unfinished Bit1: Debug Mode Bit2: Battery String Disabled Bit3: EMS Trip Bit4: Extreme Fault CRC Check Failed Bit5: Precharge Timeout Bit6: Hv Differential not Achieved During Precharge Phase Bit7: Precharge Fault Set Bit8: Relay Fault Set Bit9: RBMS has Level 1 Fault Bit10: Hv Control Mode Disconnected Bit11: Extreme Fault Set Bit12: Emergency Stop Signal Set Bit13: Recharging Plug Interlock Signal Set | P7: Rack状态,Rack Status;继电器信息[1,2,1] | Q7: Y | S7: ScEMCT_RBMS_ConFail | T7: / | U7: BSWSRackConFail | V7: / | Y7: HV Connect Fail Reason 高压连接失败原因
C8: RBMS_V | D8: Battery String Voltage (V) 电池串电压 (V) | E8: =IF(INT((F8 + G8-1) / 8) + 1 = INT(F8 / 8) + 1, INT(F8 / 8) + 1, INT(F8 / 8) + 1 & "-" & INT((F8 + G8 - 1) / 8) + 1) -> 8-9 | F8: =F7+G7 -> 56 | G8: 16 | H8: 0.5 | I8: 0 | J8: 0 | K8: =(POWER(2,G8)-1)*H8+I8 -> 32767.5 | L8: 0 | M8: V | N8: =LEN(K8) -> 7 | P8: Rack采样信息,Rack Sampling Information;其他电压[3,3,1] | Q8: Y | S8: ScEMCT_RBMS_V | T8: / | U8: BSWSRackV | V8: / | Y8: Battery String Voltage (V) 电池串电压 (V)
C9: RBMS_DCBusV | D9: DC Bus Voltage (V) 总线电压 (V) | E9: =IF(INT((F9 + G9-1) / 8) + 1 = INT(F9 / 8) + 1, INT(F9 / 8) + 1, INT(F9 / 8) + 1 & "-" & INT((F9 + G9 - 1) / 8) + 1) -> 10-11 | F9: =F8+G8 -> 72 | G9: 16 | H9: 0.5 | I9: 0 | J9: 0 | K9: =(POWER(2,G9)-1)*H9+I9 -> 32767.5 | L9: 0 | M9: V | N9: =LEN(K9) -> 7 | P9: Rack采样信息,Rack Sampling Information;其他电压[3,3,2] | Q9: Y | S9: ScEMCT_RBMS_DCBusV | T9: / | U9: BSWSRackDCBusV | V9: / | Y9: DC Bus Voltage (V) 总线电压 (V)
C10: RBMS_A_HighAccu | D10: DC Bus Current (A) (High accu) 总线电流 (A) (高精度) | E10: =IF(INT((F10 + G10-1) / 8) + 1 = INT(F10 / 8) + 1, INT(F10 / 8) + 1, INT(F10 / 8) + 1 & "-" & INT((F10 + G10 - 1) / 8) + 1) -> 12-15 | F10: =F9+G9 -> 88 | G10: 32 | H10: 0.001 | I10: -2000 | J10: -2000 | K10: =(POWER(2,G10)-1)*H10+I10 -> 4292967.3 | L10: 0 | M10: A | N10: =LEN(K10) -> 11 | P10: Rack采样信息,Rack Sampling Information;电流[3,2,1] | R10: songx0830：簇电流是否可以直接用single? xuc 0904: 已提高分辨率 | S10: ScSGPC_BatIA | T10: / | U10: / | V10: / | Y10: DC Bus Current (A) (High accu) 总线电流 (A) (高精度)
C11: RBMS_IsoR | D11: Insulation Resistance (kOhm) 绝缘阻值 (kOhm) | E11: =IF(INT((F11 + G11-1) / 8) + 1 = INT(F11 / 8) + 1, INT(F11 / 8) + 1, INT(F11 / 8) + 1 & "-" & INT((F11 + G11 - 1) / 8) + 1) -> 16-17 | F11: =F10+G10 -> 120 | G11: 16 | H11: 1 | I11: 0 | J11: 0 | K11: =(POWER(2,G11)-1)*H11+I11 -> 65535 | L11: 0 | M11: kOhm | N11: =LEN(K11) -> 5 | P11: Rack状态,Rack Status;绝缘信息[1,3,8] | Q11: Y | S11: ScEMCT_RBMS_IsoR | T11: / | U11: BSWSRackIsoR | V11: / | Y11: Insulation Resistance (kOhm) 绝缘阻值 (kOhm)
C12: RBMS_HvBoxMaxTemp | D12: Max HV Box Temperature (℃) 最高高压箱温度 (℃) | E12: =IF(INT((F12 + G12-1) / 8) + 1 = INT(F12 / 8) + 1, INT(F12 / 8) + 1, INT(F12 / 8) + 1 & "-" & INT((F12 + G12 - 1) / 8) + 1) -> 18-19 | F12: =F11+G11 -> 136 | G12: 16 | H12: 0.1 | I12: -40 | J12: -40 | K12: =(POWER(2,G12)-1)*H12+I12 -> 6513.5 | L12: 0 | M12: ℃ | N12: =LEN(K12) -> 6 | P12: Rack采样信息,Rack Sampling Information;高压箱温度[3,8,1] | Q12: Y | S12: ScCLTH_CtlBoxTMaxDegC | T12: / | U12: BSWSRackMaxHvBoxTDegC | V12: / | Y12: Max HV Box Temperature (℃) 最高高压箱温度 (℃)
C13: RBMS_HvBoxMinTemp | D13: Min HV Box Temperature (℃) 最低高压箱温度 (℃) | E13: =IF(INT((F13 + G13-1) / 8) + 1 = INT(F13 / 8) + 1, INT(F13 / 8) + 1, INT(F13 / 8) + 1 & "-" & INT((F13 + G13 - 1) / 8) + 1) -> 20-21 | F13: =F12+G12 -> 152 | G13: 16 | H13: 0.1 | I13: -40 | J13: -40 | K13: =(POWER(2,G13)-1)*H13+I13 -> 6513.5 | L13: 0 | M13: ℃ | N13: =LEN(K13) -> 6 | P13: Rack采样信息,Rack Sampling Information;高压箱温度[3,8,2] | Q13: Y | S13: ScCLTH_CtlBoxTMinDegC | T13: / | U13: BSWSRackMinHvBoxTDegC | V13: / | Y13: Min HV Box Temperature (℃) 最低高压箱温度 (℃)
C14: Reserved3 | D14: Reserved3 预留占位3 | E14: =IF(INT((F14 + G14-1) / 8) + 1 = INT(F14 / 8) + 1, INT(F14 / 8) + 1, INT(F14 / 8) + 1 & "-" & INT((F14 + G14 - 1) / 8) + 1) -> 22 | F14: =F13+G13 -> 168 | G14: 8 | H14: 1 | I14: 0 | J14: 0 | K14: =(POWER(2,G14)-1)*H14+I14 -> 255 | L14: 0 | M14: / | N14: 0 | S14: / | T14: / | U14: / | V14: / | Y14: Reserved3 预留占位3
C15: RBMS_LowPowSply | D15: Low Power Supply Voltage (mV) 低压供电电压 (mV) | E15: =IF(INT((F15 + G15-1) / 8) + 1 = INT(F15 / 8) + 1, INT(F15 / 8) + 1, INT(F15 / 8) + 1 & "-" & INT((F15 + G15 - 1) / 8) + 1) -> 23-24 | F15: =F14+G14 -> 176 | G15: 16 | H15: 1 | I15: 0 | J15: 0 | K15: =(POWER(2,G15)-1)*H15+I15 -> 65535 | L15: 0 | M15: mV | N15: =LEN(K15) -> 5 | P15: Rack采样信息,Rack Sampling Information;其他电压[3,3,3] | Q15: Y | S15: ScEMCT_RBMS_LowPowSply | T15: / | U15: BSWSRackLowPowSply | V15: / | Y15: Low Power Supply Voltage (mV) 低压供电电压 (mV)
C16: RBMS_RlyCtrlSeqStState | D16: Relay Control Status 继电器控制状态 | E16: =IF(INT((F16 + G16-1) / 8) + 1 = INT(F16 / 8) + 1, INT(F16 / 8) + 1, INT(F16 / 8) + 1 & "-" & INT((F16 + G16 - 1) / 8) + 1) -> 25 | F16: =F15+G15 -> 192 | G16: 4 | H16: 1 | I16: 0 | J16: 0 | K16: =(POWER(2,G16)-1)*H16+I16 -> 15 | L16: 0 | M16: / | N16: =LEN(K16) -> 2 | O16: Enum 0X0: Initial; 0X1: ClsMainNeg; 0X2: ClsPrech; 0X3: ClsMainPos; 0X4: Online; 0X5: WaitForCurrDwn; 0X6: OpenMainPos; 0X7: OpenMainNeg; 0X8: DlyForNxtPowup; 0X9: Service; 0XA: SftyOpenMainPos; 0XB: SftyOpenMainNeg; 0XC: SftyDlyForNxtPowup; | P16: Rack状态,Rack Status;继电器信息[1,2,4] | Q16: Y | S16: SeCTSC_RlyCtrlSeqStState | T16: / | U16: BSWSRlyCtrlSeqStState | V16: / | Y16: Relay Control Status 继电器控制状态
C17: RBMS_HvCnctCoverPrechFlg | D17: Rack Prech-included Hv Main Circiut Status Flg 簇包含预充的高压主回路状态标志位 | E17: =IF(INT((F17 + G17-1) / 8) + 1 = INT(F17 / 8) + 1, INT(F17 / 8) + 1, INT(F17 / 8) + 1 & "-" & INT((F17 + G17 - 1) / 8) + 1) -> 25 | F17: =F16+G16 -> 196 | G17: 1 | H17: 1 | I17: 0 | J17: 0 | K17: =(POWER(2,G17)-1)*H17+I17 -> 1 | L17: 1 | M17: flg | N17: =LEN(K17) -> 1 | O17: Enum 0x0: Open 0x1: Close | P17: Rack状态,Rack Status;继电器信息[1,2,7] | S17: SbCTSC_HvCnctStCoverPrechFlg | T17: / | U17: BSWSHvCnctStCoverPrechFlg | V17: / | Y17: Rack Prech-included Hv Main Circiut Status Flg 簇包含预充的高压主回路状态标志位
C18: Reserved | D18: Reserved 预留占位 | E18: =IF(INT((F18 + G18-1) / 8) + 1 = INT(F18 / 8) + 1, INT(F18 / 8) + 1, INT(F18 / 8) + 1 & "-" & INT((F18 + G18 - 1) / 8) + 1) -> 25 | F18: =F17+G17 -> 197 | G18: 3 | H18: 1 | I18: 0 | J18: 0 | K18: =(POWER(2,G18)-1)*H18+I18 -> 7 | L18: 0 | M18: / | N18: 0 | S18: / | T18: / | U18: / | V18: / | Y18: Reserved 预留占位
C19: RBMS_ReChrgStatus | D19: Recharge Status 补电状态 | E19: =IF(INT((F19 + G19-1) / 8) + 1 = INT(F19 / 8) + 1, INT(F19 / 8) + 1, INT(F19 / 8) + 1 & "-" & INT((F19 + G19 - 1) / 8) + 1) -> 26 | F19: =F18+G18 -> 200 | G19: 8 | H19: 1 | I19: 0 | J19: 0 | K19: =(POWER(2,G19)-1)*H19+I19 -> 255 | L19: 0 | M19: Nbr | N19: =LEN(K19) -> 3 | O19: Enum 0X0: Not Recharge; 0X1: Recharging; 0X2: Recharge Finished; | P19: Rack状态,Rack Status;继电器信息[1,2,5] | Q19: Y | S19: ScCTSC_ReChrgStateNbr | T19: / | U19: / | V19: / | Y19: Recharge Status 补电状态
C20: RBMS_HisSleepTiWrMin | D20: Rack History Sleep Time (min) 历史休眠时间 (min) | E20: =IF(INT((F20 + G20-1) / 8) + 1 = INT(F20 / 8) + 1, INT(F20 / 8) + 1, INT(F20 / 8) + 1 & "-" & INT((F20 + G20 - 1) / 8) + 1) -> 27-30 | F20: =F19+G19 -> 208 | G20: 32 | H20: 1 | I20: 0 | J20: 0 | K20: =(POWER(2,G20)-1)*H20+I20 -> 4294967295 | L20: 0 | M20: Min | N20: =LEN(K20) -> 10 | P20: Rack历史信息,Rack History Information;时间[4,1,1] | Q20: Y | S20: ScEMCT_RBMS_HisSleepTiWrMin | T20: / | U20: BSWSRackHisSleepTiWrMin | V20: / | Y20: History Sleep Time (min) 历史休眠时间 (min)
C21: RBMS_HisRunTiWrMin | D21: Rack History Run Time (min) 历史运行时间 (min) | E21: =IF(INT((F21 + G21-1) / 8) + 1 = INT(F21 / 8) + 1, INT(F21 / 8) + 1, INT(F21 / 8) + 1 & "-" & INT((F21 + G21 - 1) / 8) + 1) -> 31-34 | F21: =F20+G20 -> 240 | G21: 32 | H21: 1 | I21: 0 | J21: 0 | K21: =(POWER(2,G21)-1)*H21+I21 -> 4294967295 | L21: 0 | M21: Min | N21: =LEN(K21) -> 10 | P21: Rack历史信息,Rack History Information;时间[4,1,2] | Q21: Y | S21: ScEMCT_RBMS_HisRunTiWrMin | T21: / | U21: BSWSRackHisRunTiWrMin | V21: / | Y21: History Run Time (min) 历史运行时间 (min)
C22: RBMS_LstSleepDurTiMin | D22: Last Power-down Sleep Time (min) 上次下电休眠时间 (min) | E22: =IF(INT((F22 + G22-1) / 8) + 1 = INT(F22 / 8) + 1, INT(F22 / 8) + 1, INT(F22 / 8) + 1 & "-" & INT((F22 + G22 - 1) / 8) + 1) -> 35-38 | F22: =F21+G21 -> 272 | G22: 32 | H22: 1 | I22: 0 | J22: 0 | K22: =(POWER(2,G22)-1)*H22+I22 -> 4294967295 | L22: 0 | M22: Min | N22: =LEN(K22) -> 10 | P22: Rack历史信息,Rack History Information;时间[4,1,3] | S22: ScSGPC_LstSleepDurTiMin | T22: / | V22: / | Y22: Last Power-down Sleep Time (min) 上次下电休眠时间 (min)
C23: RBMS_IDLearnCodeSt | D23: Rack ID Learn Status Rack ID编码状态 | E23: =IF(INT((F23 + G23-1) / 8) + 1 = INT(F23 / 8) + 1, INT(F23 / 8) + 1, INT(F23 / 8) + 1 & "-" & INT((F23 + G23 - 1) / 8) + 1) -> 39 | F23: =F22+G22 -> 304 | G23: 8 | H23: 1 | I23: 0 | J23: 0 | K23: =(POWER(2,G23)-1)*H23+I23 -> 255 | L23: 0 | M23: / | N23: =LEN(K23) -> 3 | O23: Enum 0X0: Initial; 0X1: Addressing; 0X2: Present RBMS Finished; 0X3: All RBMS Finished; 0X4: Failed; | P23: Rack状态,Rack Status;系统信息[1,1,3] | Q23: Y | S23: ScEMCT_RBMS_IDLearnCodeSt | T23: / | V23: / | Y23: ID Learn Status ID编码状态
C24: RBMS_IsoRPos | D24: Positive to GND Insulation Resistance (kOhm) 正对地绝缘阻值 (kOhm) | E24: =IF(INT((F24 + G24-1) / 8) + 1 = INT(F24 / 8) + 1, INT(F24 / 8) + 1, INT(F24 / 8) + 1 & "-" & INT((F24 + G24 - 1) / 8) + 1) -> 40-41 | F24: =F23+G23 -> 312 | G24: 16 | H24: 1 | I24: 0 | J24: 0 | K24: =(POWER(2,G24)-1)*H24+I24 -> 65535 | L24: 0 | M24: kOhm | N24: =LEN(K24) -> 5 | P24: Rack状态,Rack Status;绝缘信息[1,3,9] | S24: ScEMCT_RBMS_IsoRPos | T24: / | U24: BSWSRackIsoRPos | V24: / | Y24: Insulation Positive to GND Resistance (kOhm) 绝缘正对地阻值 (kOhm)
C25: RBMS_IsoRNeg | D25: Negative to GND Insulation Resistance (kOhm) 负对地绝缘阻值 (kOhm) | E25: =IF(INT((F25 + G25-1) / 8) + 1 = INT(F25 / 8) + 1, INT(F25 / 8) + 1, INT(F25 / 8) + 1 & "-" & INT((F25 + G25 - 1) / 8) + 1) -> 42-43 | F25: =F24+G24 -> 328 | G25: 16 | H25: 1 | I25: 0 | J25: 0 | K25: =(POWER(2,G25)-1)*H25+I25 -> 65535 | L25: 0 | M25: kOhm | N25: =LEN(K25) -> 5 | P25: Rack状态,Rack Status;绝缘信息[1,3,10] | S25: ScEMCT_RBMS_IsoRNeg | T25: / | U25: BSWSRackIsoRNeg | V25: / | Y25: Insulation Negative to GND Resistance (kOhm) 绝缘负对地阻值 (kOhm)
C26: RBMS_CmdInhibitFlg | D26: Insulation Disable Flag 绝缘禁止标志位 | E26: =IF(INT((F26 + G26-1) / 8) + 1 = INT(F26 / 8) + 1, INT(F26 / 8) + 1, INT(F26 / 8) + 1 & "-" & INT((F26 + G26 - 1) / 8) + 1) -> 44 | F26: =F25+G25 -> 344 | G26: 8 | H26: 1 | I26: 0 | J26: 0 | K26: 1 | L26: 0 | M26: flg | N26: =LEN(K26) -> 1 | O26: Enum 0X0: Enable 0X1: Disable | P26: Rack状态,Rack Status;绝缘信息[1,3,2] | S26: ScEMCT_RBMS_CmdInhibitFlg | T26: / | U26: BSWSRackCmdInhibitFlg | V26: / | Y26: Insulation Inhibit Flag 绝缘禁止标志位
C27: RBMS_IslnHvVldNbr | D27: Insulation High Voltage Validity Status 绝缘高压有效性状态 | E27: =IF(INT((F27 + G27-1) / 8) + 1 = INT(F27 / 8) + 1, INT(F27 / 8) + 1, INT(F27 / 8) + 1 & "-" & INT((F27 + G27 - 1) / 8) + 1) -> 45 | F27: =F26+G26 -> 352 | G27: 8 | H27: 1 | I27: 0 | J27: 0 | K27: =(POWER(2,G27)-1)*H27+I27 -> 255 | L27: 0 | M27: / | N27: =LEN(K27) -> 3 | O27: Bit0[0]: Hv Battery Validity;高压有效性 Signal; 0X0-Invalid; 0X1-Valid; Bit1[0]: Postive Voltage Validity;正极电压有效性 Signal; 0X0-Invalid; 0X1-Valid; Bit2[0]: Negetive Voltage Validity;负极电压有效性 Signal; 0X0-Invalid; 0X1-Valid; | P27: Rack状态,Rack Status;绝缘信息[1,3,4] | R27: 统一按照bit 长度设置最大值 | S27: ScEMCT_RBMS_IslnHvVldNbr | T27: / | U27: BSWSRackIslnHvVldNbr | V27: / | Y27: Insulation Voltage Validity 绝缘电压有效性
C28: RBMS_IslnInhibitNbr | D28: Insulation Prohibition Reason 绝缘禁止原因 | E28: =IF(INT((F28 + G28-1) / 8) + 1 = INT(F28 / 8) + 1, INT(F28 / 8) + 1, INT(F28 / 8) + 1 & "-" & INT((F28 + G28 - 1) / 8) + 1) -> 46 | F28: =F27+G27 -> 360 | G28: 8 | H28: 1 | I28: 0 | J28: 0 | K28: =(POWER(2,G28)-1)*H28+I28 -> 255 | L28: 0 | M28: / | N28: =LEN(K28) -> 3 | O28: Enum 0X0: Normal; 0X1: HMI Insulation Prohibition; 0X2: Insulation-related Voltage Invalid; 0X3: Hv Insulation Prohibition; 0X4: XCP Configuration Insulation Prohibition; | P28: Rack状态,Rack Status;绝缘信息[1,3,3] | Q28: Y | S28: ScEMCT_RBMS_IslnInhibitNbr | T28: / | U28: BSWSRackIslnInhibitNbr | V28: / | Y28: Insulation Inhibit Reason 绝缘禁止原因
C29: RBMS_CellTMUXFaiIDNbr | D29: Temp Sampling MUX Fail Position 温度采样MUX失效位置 | E29: =IF(INT((F29 + G29-1) / 8) + 1 = INT(F29 / 8) + 1, INT(F29 / 8) + 1, INT(F29 / 8) + 1 & "-" & INT((F29 + G29 - 1) / 8) + 1) -> 47-54 | F29: =F28+G28 -> 368 | G29: 64 | H29: 1 | I29: 0 | J29: 0 | K29: =(POWER(2,G29)-1)*H29+I29 -> 1.8446744e+19 | L29: 0 | M29: / | N29: =LEN(K29) -> 20 | P29: Rack采样信息,Rack Sampling Information;电芯温度[3,6,1] | Q29: Y | R29: 所有失效的MUX位置（1-失效，0-未失效） bitN: 第N+1个MUX | S29: ScEMCT_RBMS_CellTMUXFaiIDNbr | T29: / | U29: / | V29: / | Y29: Temp Sampling MUX Fail Position 温度采样MUX失效位置
C30: RBMS_MaxPackFuseTDegC | D30: Max Pack Fuse Temp (℃) 最高Pack熔断器温度 (℃) | E30: =IF(INT((F30 + G30-1) / 8) + 1 = INT(F30 / 8) + 1, INT(F30 / 8) + 1, INT(F30 / 8) + 1 & "-" & INT((F30 + G30 - 1) / 8) + 1) -> 55-56 | F30: =F29+G29 -> 432 | G30: 16 | H30: 0.1 | I30: -40 | J30: 0 | K30: =(POWER(2,G30)-1)*H30+I30 -> 6513.5 | L30: 0 | M30: ℃ | N30: =LEN(K30) -> 6 | P30: Rack采样信息,Rack Sampling Information;其他温度[3,5,10] | S30: ScCLTH_MaxPackFuseTDegC | T30: / | U30: / | V30: / | Y30: Max Pack Fuse Temp (℃) 最高Pack熔断器温度 (℃)
C31: RBMS_MinPackFuseTDegC | D31: Min Pack Fuse Temp (℃) 最低Pack熔断器温度 (℃) | E31: =IF(INT((F31 + G31-1) / 8) + 1 = INT(F31 / 8) + 1, INT(F31 / 8) + 1, INT(F31 / 8) + 1 & "-" & INT((F31 + G31 - 1) / 8) + 1) -> 57-58 | F31: =F30+G30 -> 448 | G31: 16 | H31: 0.1 | I31: -40 | J31: 0 | K31: =(POWER(2,G31)-1)*H31+I31 -> 6513.5 | L31: 0 | M31: ℃ | N31: =LEN(K31) -> 6 | P31: Rack采样信息,Rack Sampling Information;其他温度[3,5,11] | S31: ScCLTH_MinPackFuseTDegC | T31: / | U31: / | V31: / | Y31: Min Pack Fuse Temp (℃) 最低Pack熔断器温度 (℃)
C32: RBMS_DayAccuChCapAh | D32: Daily Accu Charge Cap (Ah) 当日累计充电容量 (Ah) | E32: =IF(INT((F32 + G32-1) / 8) + 1 = INT(F32 / 8) + 1, INT(F32 / 8) + 1, INT(F32 / 8) + 1 & "-" & INT((F32 + G32 - 1) / 8) + 1) -> 59-62 | F32: =F31+G31 -> 464 | G32: 32 | H32: 1 | I32: 0 | J32: 0 | K32: =(POWER(2,G32)-1)*H32+I32 -> 4294967295 | L32: 0 | M32: Ah | N32: =LEN(K32) -> 10 | P32: Rack历史信息,Rack History Information;累计[4,2,10] | S32: ScEMCT_DayAccuChCapAh | T32: / | U32: BSWSRackDayAccuChrgAh | V32: / | Y32: Daily Accu Charge Cap (Ah) 当日累计充电容量 (Ah)
C33: RBMS_DayAccuDchCapAh | D33: Daily Accu Discharge Cap (Ah) 当日累计放电容量 (Ah) | E33: =IF(INT((F33 + G33-1) / 8) + 1 = INT(F33 / 8) + 1, INT(F33 / 8) + 1, INT(F33 / 8) + 1 & "-" & INT((F33 + G33 - 1) / 8) + 1) -> 63-66 | F33: =F32+G32 -> 496 | G33: 32 | H33: 1 | I33: 0 | J33: 0 | K33: =(POWER(2,G33)-1)*H33+I33 -> 4294967295 | L33: 0 | M33: Ah | N33: =LEN(K33) -> 10 | P33: Rack历史信息,Rack History Information;累计[4,2,11] | S33: ScEMCT_DayAccuDischCapAh | T33: / | U33: BSWSRackDayAccuDisChrgAh | V33: / | Y33: Daily Accu Discharge Cap (Ah) 当日累计放电容量 (Ah)
C34: RBMS_DayAccuChEngkWh | D34: Daily Accu Charge Eng (kWh) 当日累计充电能量 (kWh) | E34: =IF(INT((F34 + G34-1) / 8) + 1 = INT(F34 / 8) + 1, INT(F34 / 8) + 1, INT(F34 / 8) + 1 & "-" & INT((F34 + G34 - 1) / 8) + 1) -> 67-70 | F34: =F33+G33 -> 528 | G34: 32 | H34: 1 | I34: 0 | J34: 0 | K34: =(POWER(2,G34)-1)*H34+I34 -> 4294967295 | L34: 0 | M34: kWh | N34: =LEN(K34) -> 10 | P34: Rack历史信息,Rack History Information;累计[4,2,12] | S34: ScEMCT_DayAccuChEngKwh | T34: / | U34: BSWSRackDayAccuChrgkWh | V34: / | Y34: Daily Accu Charge Eng (kWh) 当日累计充电能量 (kWh)
C35: RBMS_DayAccuDchEngkWh | D35: Daily Accu Discharge Eng (kWh) 当日累计放电能量 (kWh) | E35: =IF(INT((F35 + G35-1) / 8) + 1 = INT(F35 / 8) + 1, INT(F35 / 8) + 1, INT(F35 / 8) + 1 & "-" & INT((F35 + G35 - 1) / 8) + 1) -> 71-74 | F35: =F34+G34 -> 560 | G35: 32 | H35: 1 | I35: 0 | J35: 0 | K35: =(POWER(2,G35)-1)*H35+I35 -> 4294967295 | L35: 0 | M35: kWh | N35: =LEN(K35) -> 10 | P35: Rack历史信息,Rack History Information;累计[4,2,13] | S35: ScEMCT_DayAccuDischEngKwh | T35: / | U35: BSWSRackDayAccuDisChrgkWh | V35: / | Y35: Daily Accu Discharge Eng (kWh) 当日累计放电能量 (kWh)
C36: Reserved5[36] | D36: Reserved5 预留占位5 | E36: 75-110 | F36: =F29+G29 -> 432 | G36: 8 | H36: 1 | I36: 0 | J36: 0 | K36: =(POWER(2,G36)-1)*H36+I36 -> 255 | L36: 0 | M36: / | N36: 0 | S36: / | T36: / | U36: / | V36: /
C37: RBMS_SoC | D37: Rack SOC (%) Rack SOC（%） | E37: =IF(INT((F37 + G37-1) / 8) + 1 = INT(F37 / 8) + 1, INT(F37 / 8) + 1, INT(F37 / 8) + 1 & "-" & INT((F37 + G37 - 1) / 8) + 1) -> 111 | F37: 880 | G37: 8 | H37: 0.5 | I37: 0 | J37: 0 | K37: =(POWER(2,G37)-1)*H37+I37 -> 127.5 | L37: 0 | M37: % | N37: =LEN(K37) -> 5 | P37: Rack SOX状态,Rack SOX Status;SOC[2,1,1] | Q37: Y | R37: 发送显示SOC | S37: ScEMCT_RBMS_SoC | T37: / | U37: BSWSRackSoC | V37: / | Y37: SOC (%) SOC（%）
C38: RBMS_SoH | D38: Rack SOH (%) Rack SOH（%） | E38: =IF(INT((F38 + G38-1) / 8) + 1 = INT(F38 / 8) + 1, INT(F38 / 8) + 1, INT(F38 / 8) + 1 & "-" & INT((F38 + G38 - 1) / 8) + 1) -> 112 | F38: =F37+G37 -> 888 | G38: 8 | H38: 1 | I38: 0 | J38: 0 | K38: =(POWER(2,G38)-1)*H38+I38 -> 255 | L38: 100 | M38: % | N38: =LEN(K38) -> 3 | P38: Rack SOX状态,Rack SOX Status;SOH[2,2,1] | Q38: Y | R38: 发送显示SOH | S38: ScEMCT_RBMS_SoH | T38: / | U38: BSWSRackSoH | V38: / | Y38: SOH (%) SOH（%）
C39: RBMS_SoEC | D39: Rack SOE for Charge (kWh) Rack可充能量 (kWh) | E39: =IF(INT((F39 + G39-1) / 8) + 1 = INT(F39 / 8) + 1, INT(F39 / 8) + 1, INT(F39 / 8) + 1 & "-" & INT((F39 + G39 - 1) / 8) + 1) -> 113-114 | F39: =F38+G38 -> 896 | G39: 16 | H39: 0.125 | I39: 0 | J39: 0 | K39: =(POWER(2,G39)-1)*H39+I39 -> 8191.875 | L39: 0 | M39: kWh | N39: =LEN(K39) -> 8 | P39: Rack SOX状态,Rack SOX Status;SOE[2,3,3] | Q39: Y | S39: ScEMCT_RBMS_SoEC | T39: / | U39: BSWSRackSoEC | V39: / | Y39: SOE for Charge (kWh) 可充能量 (kWh)
C40: RBMS_SoED | D40: Rack SOE for Discharge (kWh) Rack可放能量 (kWh) | E40: =IF(INT((F40 + G40-1) / 8) + 1 = INT(F40 / 8) + 1, INT(F40 / 8) + 1, INT(F40 / 8) + 1 & "-" & INT((F40 + G40 - 1) / 8) + 1) -> 115-116 | F40: =F39+G39 -> 912 | G40: 16 | H40: 0.125 | I40: 0 | J40: 0 | K40: =(POWER(2,G40)-1)*H40+I40 -> 8191.875 | L40: 0 | M40: kWh | N40: =LEN(K40) -> 8 | P40: Rack SOX状态,Rack SOX Status;SOE[2,3,4] | Q40: Y | S40: ScEMCT_RBMS_SoED | T40: / | U40: BSWSRackSoED | V40: / | Y40: SOE for Discharge (kWh) 可放能量 (kWh)
...

Sheet Device ID
A1: 设备类型 | B1: 主节点号 | C1: 子节点号
A2: Broadcast | B2: 0x00 | C2: 0
A3: HMI & BBMS_A | B3: 0x01 | C3: 0
A4: HMI | B4: 0x01 | C4: 1
A5: BBMS_A | B5: 0x01 | C5: 2
A6: BBMS_M | B6: 0x03 | C6: 1
A7: RBMS | B7: 0x04 | C7: N
A8: Active_Balance | B8: 0x05 | C8: N

Sheet SSD Store Calculation
A1: ='Message ID'!A1 -> Message Name | B1: ='Message ID'!D1 -> Periodic Time (ms) | C1: ='Message ID'!Q1 -> BBMS_A Store | D1: CSV Store Length(Byte) | E1: Rack Nbr | F1: Data RAM KB/Day | G1: Comma Nbr | H1: Comma RAM KB/Day | I1: LogTime RAM KB/Day
A2: ='Message ID'!A2 -> RBMS_SumInfo | B2: ='Message ID'!D2 -> 1000 | C2: ='Message ID'!Q2 -> 1 | D2: =VLOOKUP(A2,'Comm Matrix'!A:N,14,FALSE) -> 765 | E2: =IF(OR(ISNUMBER(SEARCH("RBMS", A2)), ISNUMBER(SEARCH("Para", A2))), $F$54, 1) -> 12 | F2: =IF(C2=1,D2*E2*60*60*24*C2/(B2/1000),0)/1024 -> 774562.5 | G2: {=MATCH(FALSE, INDEX(TRIM(INDIRECT("'Comm Matrix'!G" & (MATCH(A2,'Comm Matrix'!A:A,0)+1) & ":G1000"))<>"", 0), 0)-1} -> 137 | H2: =IF(C2=1,G2*E2*60*60*24*C2/(B2/1000),0)/1024 -> 138712.5 | I2: =IF(C2=1,19*E2*60*60*24*C2/(B2/1000),0)/1024 -> 19237.5
A3: ='Message ID'!A4 -> RBMS_Volt | B3: ='Message ID'!D4 -> 1000 | C3: ='Message ID'!Q4 -> 1 | D3: =VLOOKUP(A3,'Comm Matrix'!A:N,14,FALSE) -> 2400 | E3: =IF(OR(ISNUMBER(SEARCH("RBMS", A3)), ISNUMBER(SEARCH("Para", A3))), $F$54, 1) -> 12 | F3: =IF(C3=1,D3*E3*60*60*24*C3/(B3/1000),0)/1024 -> 2430000 | G3: =416+416+32 -> 864 | H3: =IF(C3=1,G3*E3*60*60*24*C3/(B3/1000),0)/1024 -> 874800 | I3: =IF(C3=1,19*E3*60*60*24*C3/(B3/1000),0)/1024 -> 19237.5
A4: ='Message ID'!A5 -> RBMS_Temp | B4: ='Message ID'!D5 -> 1000 | C4: ='Message ID'!Q5 -> 1 | D4: =VLOOKUP(A4,'Comm Matrix'!A:N,14,FALSE) -> 2672 | E4: =IF(OR(ISNUMBER(SEARCH("RBMS", A4)), ISNUMBER(SEARCH("Para", A4))), $F$54, 1) -> 12 | F4: =IF(C4=1,D4*E4*60*60*24*C4/(B4/1000),0)/1024 -> 2705400 | G4: =416+64+16+32+32 -> 560 | H4: =IF(C4=1,G4*E4*60*60*24*C4/(B4/1000),0)/1024 -> 567000 | I4: =IF(C4=1,19*E4*60*60*24*C4/(B4/1000),0)/1024 -> 19237.5
A5: ='Message ID'!A6 -> RBMS_CellBalSt | B5: ='Message ID'!D6 -> 10000 | C5: ='Message ID'!Q6 -> 1 | D5: =VLOOKUP(A5,'Comm Matrix'!A:N,14,FALSE) -> 416 | E5: =IF(OR(ISNUMBER(SEARCH("RBMS", A5)), ISNUMBER(SEARCH("Para", A5))), $F$54, 1) -> 12 | F5: =IF(C5=1,D5*E5*60*60*24*C5/(B5/1000),0)/1024 -> 42120 | G5: =416 -> 416 | H5: =IF(C5=1,G5*E5*60*60*24*C5/(B5/1000),0)/1024 -> 42120 | I5: =IF(C5=1,19*E5*60*60*24*C5/(B5/1000),0)/1024 -> 1923.75
A6: ='Message ID'!A7 -> RBMS_CellSdr | B6: ='Message ID'!D7 -> 30000 | C6: ='Message ID'!Q7 -> 0 | D6: =VLOOKUP(A6,'Comm Matrix'!A:N,14,FALSE) -> 2080 | E6: =IF(OR(ISNUMBER(SEARCH("RBMS", A6)), ISNUMBER(SEARCH("Para", A6))), $F$54, 1) -> 12 | F6: =IF(C6=1,D6*E6*60*60*24*C6/(B6/1000),0)/1024 -> 0 | G6: =416 -> 416 | H6: =IF(C6=1,G6*E6*60*60*24*C6/(B6/1000),0)/1024 -> 0 | I6: =IF(C6=1,19*E6*60*60*24*C6/(B6/1000),0)/1024 -> 0
A7: ='Message ID'!A8 -> RBMS_Fault | B7: ='Message ID'!D8 -> 1000 | C7: ='Message ID'!Q8 -> 1 | D7: =VLOOKUP(A7,'Comm Matrix'!A:N,14,FALSE) -> 200 | E7: =IF(OR(ISNUMBER(SEARCH("RBMS", A7)), ISNUMBER(SEARCH("Para", A7))), $F$54, 1) -> 12 | F7: =IF(C7=1,D7*E7*60*60*24*C7/(B7/1000),0)/1024 -> 202500 | G7: =200 -> 200 | H7: =IF(C7=1,G7*E7*60*60*24*C7/(B7/1000),0)/1024 -> 202500 | I7: =IF(C7=1,19*E7*60*60*24*C7/(B7/1000),0)/1024 -> 19237.5
